Workbook

Sheet Summary
A1: Community | B1: RM Code | C1: Sewer YTD | D1: WWTP YTD | E1: Sewer + WWTP | F1: Trash YTD | G1: Lot-months | H1: Avg occ lots | I1: Sewer /lot/mo | J1: WWTP /lot/mo | K1: Trash /lot/mo | L1: All-in /lot/mo | M1: Note
A2: American | B2: AMER | C2: ='Sewer Monthly'!K2 -> 0 | D2: ='WWTP Monthly'!K2 -> 0 | E2: =C2+D2 -> 0 | F2: ='Trash Monthly'!K2 -> 4740 | G2: ='Occupied Lots'!K2 -> 316 | H2: =IFERROR(G2/8,0) -> 39.5 | I2: =IFERROR(C2/$G2,0) -> 0 | J2: =IFERROR(D2/$G2,0) -> 0 | K2: =IFERROR(F2/$G2,0) -> 15 | L2: =IFERROR((C2+D2+F2)/$G2,0) -> 15 | M2: no sewer expense booked
A3: Applegate MHC | B3: APPLE | C3: ='Sewer Monthly'!K3 -> 0 | D3: ='WWTP Monthly'!K3 -> 24963.4 | E3: =C3+D3 -> 24963.4 | F3: ='Trash Monthly'!K3 -> 18566.18 | G3: ='Occupied Lots'!K3 -> 590 | H3: =IFERROR(G3/8,0) -> 73.75 | I3: =IFERROR(C3/$G3,0) -> 0 | J3: =IFERROR(D3/$G3,0) -> 42.310847 | K3: =IFERROR(F3/$G3,0) -> 31.468102 | L3: =IFERROR((C3+D3+F3)/$G3,0) -> 73.778949 | M3: sewer via own WWTP
A4: Auburn Ridge | B4: ARD | C4: ='Sewer Monthly'!K4 -> 0 | D4: ='WWTP Monthly'!K4 -> 0 | E4: =C4+D4 -> 0 | F4: ='Trash Monthly'!K4 -> 3068.83 | G4: ='Occupied Lots'!K4 -> 1170 | H4: =IFERROR(G4/8,0) -> 146.25 | I4: =IFERROR(C4/$G4,0) -> 0 | J4: =IFERROR(D4/$G4,0) -> 0 | K4: =IFERROR(F4/$G4,0) -> 2.6229316 | L4: =IFERROR((C4+D4+F4)/$G4,0) -> 2.6229316 | M4: no sewer expense booked
A5: Bay Oaks Village II | B5: BOVIIPO | C5: ='Sewer Monthly'!K5 -> 0 | D5: ='WWTP Monthly'!K5 -> 0 | E5: =C5+D5 -> 0 | F5: ='Trash Monthly'!K5 -> 5731.23 | G5: ='Occupied Lots'!K5 -> 151 | H5: =IFERROR(G5/8,0) -> 18.875 | I5: =IFERROR(C5/$G5,0) -> 0 | J5: =IFERROR(D5/$G5,0) -> 0 | K5: =IFERROR(F5/$G5,0) -> 37.955166 | L5: =IFERROR((C5+D5+F5)/$G5,0) -> 37.955166 | M5: no sewer expense booked
A6: Belle Haven | B6: BELL | C6: ='Sewer Monthly'!K6 -> 21706.77 | D6: ='WWTP Monthly'!K6 -> 0 | E6: =C6+D6 -> 21706.77 | F6: ='Trash Monthly'!K6 -> 8814.65 | G6: ='Occupied Lots'!K6 -> 439 | H6: =IFERROR(G6/8,0) -> 54.875 | I6: =IFERROR(C6/$G6,0) -> 49.445945 | J6: =IFERROR(D6/$G6,0) -> 0 | K6: =IFERROR(F6/$G6,0) -> 20.078929 | L6: =IFERROR((C6+D6+F6)/$G6,0) -> 69.524875
A7: Brunswick Estates | B7: BRUN | C7: ='Sewer Monthly'!K7 -> 2200.71 | D7: ='WWTP Monthly'!K7 -> 0 | E7: =C7+D7 -> 2200.71 | F7: ='Trash Monthly'!K7 -> 2886.58 | G7: ='Occupied Lots'!K7 -> 398 | H7: =IFERROR(G7/8,0) -> 49.75 | I7: =IFERROR(C7/$G7,0) -> 5.5294221 | J7: =IFERROR(D7/$G7,0) -> 0 | K7: =IFERROR(F7/$G7,0) -> 7.2527136 | L7: =IFERROR((C7+D7+F7)/$G7,0) -> 12.782136
A8: Carley's Mobile Home Park | B8: CARL | C8: ='Sewer Monthly'!K8 -> 3375 | D8: ='WWTP Monthly'!K8 -> 73 | E8: =C8+D8 -> 3448 | F8: ='Trash Monthly'!K8 -> 50731.52 | G8: ='Occupied Lots'!K8 -> 605 | H8: =IFERROR(G8/8,0) -> 75.625 | I8: =IFERROR(C8/$G8,0) -> 5.5785124 | J8: =IFERROR(D8/$G8,0) -> 0.12066116 | K8: =IFERROR(F8/$G8,0) -> 83.853752 | L8: =IFERROR((C8+D8+F8)/$G8,0) -> 89.552926
A9: Central Mobile Home Park | B9: CENT | C9: ='Sewer Monthly'!K9 -> 21374.47 | D9: ='WWTP Monthly'!K9 -> 658.31 | E9: =C9+D9 -> 22032.78 | F9: ='Trash Monthly'!K9 -> 39073.05 | G9: ='Occupied Lots'!K9 -> 459 | H9: =IFERROR(G9/8,0) -> 57.375 | I9: =IFERROR(C9/$G9,0) -> 46.567473 | J9: =IFERROR(D9/$G9,0) -> 1.4342266 | K9: =IFERROR(F9/$G9,0) -> 85.126471 | L9: =IFERROR((C9+D9+F9)/$G9,0) -> 133.12817
A10: Congress Mobile Home Park | B10: CONG | C10: ='Sewer Monthly'!K10 -> 7145.39 | D10: ='WWTP Monthly'!K10 -> 1399 | E10: =C10+D10 -> 8544.39 | F10: ='Trash Monthly'!K10 -> 0 | G10: ='Occupied Lots'!K10 -> 248 | H10: =IFERROR(G10/8,0) -> 31 | I10: =IFERROR(C10/$G10,0) -> 28.812056 | J10: =IFERROR(D10/$G10,0) -> 5.641129 | K10: =IFERROR(F10/$G10,0) -> 0 | L10: =IFERROR((C10+D10+F10)/$G10,0) -> 34.453185 | M10: sold Jul-2026; no trash expense booked
A11: Crystal Acres | B11: CA | C11: ='Sewer Monthly'!K11 -> 0 | D11: ='WWTP Monthly'!K11 -> 0 | E11: =C11+D11 -> 0 | F11: ='Trash Monthly'!K11 -> 7287.48 | G11: ='Occupied Lots'!K11 -> 187 | H11: =IFERROR(G11/8,0) -> 23.375 | I11: =IFERROR(C11/$G11,0) -> 0 | J11: =IFERROR(D11/$G11,0) -> 0 | K11: =IFERROR(F11/$G11,0) -> 38.970481 | L11: =IFERROR((C11+D11+F11)/$G11,0) -> 38.970481 | M11: no sewer expense booked
A12: Druid Oaks MHC | B12: DO | C12: ='Sewer Monthly'!K12 -> 0 | D12: ='WWTP Monthly'!K12 -> 0 | E12: =C12+D12 -> 0 | F12: ='Trash Monthly'!K12 -> 1233.99 | G12: ='Occupied Lots'!K12 -> 783 | H12: =IFERROR(G12/8,0) -> 97.875 | I12: =IFERROR(C12/$G12,0) -> 0 | J12: =IFERROR(D12/$G12,0) -> 0 | K12: =IFERROR(F12/$G12,0) -> 1.575977 | L12: =IFERROR((C12+D12+F12)/$G12,0) -> 1.575977 | M12: no sewer expense booked
A13: Fox Creek | B13: FOX | C13: ='Sewer Monthly'!K13 -> 2228.41 | D13: ='WWTP Monthly'!K13 -> 0 | E13: =C13+D13 -> 2228.41 | F13: ='Trash Monthly'!K13 -> 20387.24 | G13: ='Occupied Lots'!K13 -> 812 | H13: =IFERROR(G13/8,0) -> 101.5 | I13: =IFERROR(C13/$G13,0) -> 2.7443473 | J13: =IFERROR(D13/$G13,0) -> 0 | K13: =IFERROR(F13/$G13,0) -> 25.107438 | L13: =IFERROR((C13+D13+F13)/$G13,0) -> 27.851786
A14: Geiger Key RV Resort | B14: GEIGRV | C14: ='Sewer Monthly'!K14 -> 7314.66 | D14: ='WWTP Monthly'!K14 -> 0 | E14: =C14+D14 -> 7314.66 | F14: ='Trash Monthly'!K14 -> 20696.27 | G14: ='Occupied Lots'!K14 -> 330 | H14: =IFERROR(G14/8,0) -> 41.25 | I14: =IFERROR(C14/$G14,0) -> 22.165636 | J14: =IFERROR(D14/$G14,0) -> 0 | K14: =IFERROR(F14/$G14,0) -> 62.71597 | L14: =IFERROR((C14+D14+F14)/$G14,0) -> 84.881606
A15: Great Oak RV Resort | B15: GO | C15: ='Sewer Monthly'!K15 -> 0 | D15: ='WWTP Monthly'!K15 -> 29863.48 | E15: =C15+D15 -> 29863.48 | F15: ='Trash Monthly'!K15 -> 20214.48 | G15: ='Occupied Lots'!K15 -> 1088 | H15: =IFERROR(G15/8,0) -> 136 | I15: =IFERROR(C15/$G15,0) -> 0 | J15: =IFERROR(D15/$G15,0) -> 27.448051 | K15: =IFERROR(F15/$G15,0) -> 18.579485 | L15: =IFERROR((C15+D15+F15)/$G15,0) -> 46.027537 | M15: sewer via own WWTP
A16: Greene Pointe | B16: GPT | C16: ='Sewer Monthly'!K16 -> 132 | D16: ='WWTP Monthly'!K16 -> 0 | E16: =C16+D16 -> 132 | F16: ='Trash Monthly'!K16 -> 10024.2 | G16: ='Occupied Lots'!K16 -> 719 | H16: =IFERROR(G16/8,0) -> 89.875 | I16: =IFERROR(C16/$G16,0) -> 0.18358832 | J16: =IFERROR(D16/$G16,0) -> 0 | K16: =IFERROR(F16/$G16,0) -> 13.941864 | L16: =IFERROR((C16+D16+F16)/$G16,0) -> 14.125452
A17: Gulf Breeze MHC | B17: GULFPO | C17: ='Sewer Monthly'!K17 -> 2140.48 | D17: ='WWTP Monthly'!K17 -> 0 | E17: =C17+D17 -> 2140.48 | F17: ='Trash Monthly'!K17 -> 1750 | G17: ='Occupied Lots'!K17 -> 212 | H17: =IFERROR(G17/8,0) -> 26.5 | I17: =IFERROR(C17/$G17,0) -> 10.096604 | J17: =IFERROR(D17/$G17,0) -> 0 | K17: =IFERROR(F17/$G17,0) -> 8.254717 | L17: =IFERROR((C17+D17+F17)/$G17,0) -> 18.351321
A18: Harbour Mobile Home Park | B18: HARB | C18: ='Sewer Monthly'!K18 -> 9259.3 | D18: ='WWTP Monthly'!K18 -> 0 | E18: =C18+D18 -> 9259.3 | F18: ='Trash Monthly'!K18 -> 19976.97 | G18: ='Occupied Lots'!K18 -> 284 | H18: =IFERROR(G18/8,0) -> 35.5 | I18: =IFERROR(C18/$G18,0) -> 32.603169 | J18: =IFERROR(D18/$G18,0) -> 0 | K18: =IFERROR(F18/$G18,0) -> 70.341444 | L18: =IFERROR((C18+D18+F18)/$G18,0) -> 102.94461
A19: Hershey Park | B19: HP | C19: ='Sewer Monthly'!K19 -> 463.05 | D19: ='WWTP Monthly'!K19 -> 0 | E19: =C19+D19 -> 463.05 | F19: ='Trash Monthly'!K19 -> 27898.49 | G19: ='Occupied Lots'!K19 -> 600 | H19: =IFERROR(G19/8,0) -> 75 | I19: =IFERROR(C19/$G19,0) -> 0.77175 | J19: =IFERROR(D19/$G19,0) -> 0 | K19: =IFERROR(F19/$G19,0) -> 46.497483 | L19: =IFERROR((C19+D19+F19)/$G19,0) -> 47.269233
A20: Hunter Springs MHP | B20: HSMHC | C20: ='Sewer Monthly'!K20 -> 704.77 | D20: ='WWTP Monthly'!K20 -> 0 | E20: =C20+D20 -> 704.77 | F20: ='Trash Monthly'!K20 -> 1399.64 | G20: ='Occupied Lots'!K20 -> 105 | H20: =IFERROR(G20/8,0) -> 13.125 | I20: =IFERROR(C20/$G20,0) -> 6.7120952 | J20: =IFERROR(D20/$G20,0) -> 0 | K20: =IFERROR(F20/$G20,0) -> 13.329905 | L20: =IFERROR((C20+D20+F20)/$G20,0) -> 20.042
A21: J Bar J Estates | B21: JBJ | C21: ='Sewer Monthly'!K21 -> 6547.5 | D21: ='WWTP Monthly'!K21 -> 0 | E21: =C21+D21 -> 6547.5 | F21: ='Trash Monthly'!K21 -> 44397.85 | G21: ='Occupied Lots'!K21 -> 799 | H21: =IFERROR(G21/8,0) -> 99.875 | I21: =IFERROR(C21/$G21,0) -> 8.1946183 | J21: =IFERROR(D21/$G21,0) -> 0 | K21: =IFERROR(F21/$G21,0) -> 55.566771 | L21: =IFERROR((C21+D21+F21)/$G21,0) -> 63.761389
A22: Lake Saunders | B22: LS | C22: ='Sewer Monthly'!K22 -> 0 | D22: ='WWTP Monthly'!K22 -> 1147.5 | E22: =C22+D22 -> 1147.5 | F22: ='Trash Monthly'!K22 -> 7776.65 | G22: ='Occupied Lots'!K22 -> 346 | H22: =IFERROR(G22/8,0) -> 43.25 | I22: =IFERROR(C22/$G22,0) -> 0 | J22: =IFERROR(D22/$G22,0) -> 3.316474 | K22: =IFERROR(F22/$G22,0) -> 22.475867 | L22: =IFERROR((C22+D22+F22)/$G22,0) -> 25.792341 | M22: sewer via own WWTP
A23: Lake Wales MHC | B23: LWPO | C23: ='Sewer Monthly'!K23 -> 10514.21 | D23: ='WWTP Monthly'!K23 -> 0 | E23: =C23+D23 -> 10514.21 | F23: ='Trash Monthly'!K23 -> 7427.66 | G23: ='Occupied Lots'!K23 -> 198 | H23: =IFERROR(G23/8,0) -> 24.75 | I23: =IFERROR(C23/$G23,0) -> 53.102071 | J23: =IFERROR(D23/$G23,0) -> 0 | K23: =IFERROR(F23/$G23,0) -> 37.513434 | L23: =IFERROR((C23+D23+F23)/$G23,0) -> 90.615505
A24: Lamberton Lake MHC | B24: LLMHC | C24: ='Sewer Monthly'!K24 -> 17140.99 | D24: ='WWTP Monthly'!K24 -> 0 | E24: =C24+D24 -> 17140.99 | F24: ='Trash Monthly'!K24 -> 6748.42 | G24: ='Occupied Lots'!K24 -> 280 | H24: =IFERROR(G24/8,0) -> 35 | I24: =IFERROR(C24/$G24,0) -> 61.217821 | J24: =IFERROR(D24/$G24,0) -> 0 | K24: =IFERROR(F24/$G24,0) -> 24.1015 | L24: =IFERROR((C24+D24+F24)/$G24,0) -> 85.319321
A25: Lucky Clover | B25: LUCK | C25: ='Sewer Monthly'!K25 -> 0 | D25: ='WWTP Monthly'!K25 -> 0 | E25: =C25+D25 -> 0 | F25: ='Trash Monthly'!K25 -> 14726.38 | G25: ='Occupied Lots'!K25 -> 728 | H25: =IFERROR(G25/8,0) -> 91 | I25: =IFERROR(C25/$G25,0) -> 0 | J25: =IFERROR(D25/$G25,0) -> 0 | K25: =IFERROR(F25/$G25,0) -> 20.228544 | L25: =IFERROR((C25+D25+F25)/$G25,0) -> 20.228544 | M25: no sewer expense booked
A26: Mayflower Hills | B26: MAY | C26: ='Sewer Monthly'!K26 -> 0 | D26: ='WWTP Monthly'!K26 -> 0 | E26: =C26+D26 -> 0 | F26: ='Trash Monthly'!K26 -> 22257.65 | G26: ='Occupied Lots'!K26 -> 392 | H26: =IFERROR(G26/8,0) -> 49 | I26: =IFERROR(C26/$G26,0) -> 0 | J26: =IFERROR(D26/$G26,0) -> 0 | K26: =IFERROR(F26/$G26,0) -> 56.779719 | L26: =IFERROR((C26+D26+F26)/$G26,0) -> 56.779719 | M26: no sewer expense booked
A27: McGregor Downs | B27: MCG | C27: ='Sewer Monthly'!K27 -> 0 | D27: ='WWTP Monthly'!K27 -> 0 | E27: =C27+D27 -> 0 | F27: ='Trash Monthly'!K27 -> 10005.83 | G27: ='Occupied Lots'!K27 -> 1013 | H27: =IFERROR(G27/5,0) -> 202.6 | I27: =IFERROR(C27/$G27,0) -> 0 | J27: =IFERROR(D27/$G27,0) -> 0 | K27: =IFERROR(F27/$G27,0) -> 9.8774235 | L27: =IFERROR((C27+D27+F27)/$G27,0) -> 9.8774235 | M27: occupancy only 5 of 8 months; no sewer expense booked
A28: Meadow Woods Mobile Home Park | B28: MWMHP | C28: ='Sewer Monthly'!K28 -> 13829.48 | D28: ='WWTP Monthly'!K28 -> 0 | E28: =C28+D28 -> 13829.48 | F28: ='Trash Monthly'!K28 -> 17988.26 | G28: ='Occupied Lots'!K28 -> 528 | H28: =IFERROR(G28/8,0) -> 66 | I28: =IFERROR(C28/$G28,0) -> 26.192197 | J28: =IFERROR(D28/$G28,0) -> 0 | K28: =IFERROR(F28/$G28,0) -> 34.068674 | L28: =IFERROR((C28+D28+F28)/$G28,0) -> 60.260871
A29: Monson | B29: MON | C29: ='Sewer Monthly'!K29 -> 25156.19 | D29: ='WWTP Monthly'!K29 -> 0 | E29: =C29+D29 -> 25156.19 | F29: ='Trash Monthly'!K29 -> 11595.88 | G29: ='Occupied Lots'!K29 -> 472 | H29: =IFERROR(G29/8,0) -> 59 | I29: =IFERROR(C29/$G29,0) -> 53.297013 | J29: =IFERROR(D29/$G29,0) -> 0 | K29: =IFERROR(F29/$G29,0) -> 24.567542 | L29: =IFERROR((C29+D29+F29)/$G29,0) -> 77.864555
A30: Northgate MH | B30: NGMH | C30: ='Sewer Monthly'!K30 -> 0 | D30: ='WWTP Monthly'!K30 -> 2093.69 | E30: =C30+D30 -> 2093.69 | F30: ='Trash Monthly'!K30 -> 2447.73 | G30: ='Occupied Lots'!K30 -> 1496 | H30: =IFERROR(G30/8,0) -> 187 | I30: =IFERROR(C30/$G30,0) -> 0 | J30: =IFERROR(D30/$G30,0) -> 1.3995254 | K30: =IFERROR(F30/$G30,0) -> 1.6361832 | L30: =IFERROR((C30+D30+F30)/$G30,0) -> 3.0357086 | M30: sewer via own WWTP
A31: Northgate Utility | B31: NGU | C31: ='Sewer Monthly'!K31 -> 0 | D31: ='WWTP Monthly'!K31 -> 18278 | E31: =C31+D31 -> 18278 | F31: ='Trash Monthly'!K31 -> 0 | G31: ='Occupied Lots'!K31 -> 560 | H31: =IFERROR(G31/8,0) -> 70 | I31: =IFERROR(C31/$G31,0) -> 0 | J31: =IFERROR(D31/$G31,0) -> 32.639286 | K31: =IFERROR(F31/$G31,0) -> 0 | L31: =IFERROR((C31+D31+F31)/$G31,0) -> 32.639286 | M31: sewer via own WWTP; no trash expense booked
A32: Oakside MHP | B32: OAK | C32: ='Sewer Monthly'!K32 -> 33447.3 | D32: ='WWTP Monthly'!K32 -> 575 | E32: =C32+D32 -> 34022.3 | F32: ='Trash Monthly'!K32 -> 10851.3 | G32: ='Occupied Lots'!K32 -> 707 | H32: =IFERROR(G32/8,0) -> 88.375 | I32: =IFERROR(C32/$G32,0) -> 47.308769 | J32: =IFERROR(D32/$G32,0) -> 0.81329562 | K32: =IFERROR(F32/$G32,0) -> 15.348373 | L32: =IFERROR((C32+D32+F32)/$G32,0) -> 63.470438
A33: Oceanaire MHC | B33: OCEANPO | C33: ='Sewer Monthly'!K33 -> 7446.7 | D33: ='WWTP Monthly'!K33 -> 0 | E33: =C33+D33 -> 7446.7 | F33: ='Trash Monthly'!K33 -> 0 | G33: ='Occupied Lots'!K33 -> 363 | H33: =IFERROR(G33/8,0) -> 45.375 | I33: =IFERROR(C33/$G33,0) -> 20.514325 | J33: =IFERROR(D33/$G33,0) -> 0 | K33: =IFERROR(F33/$G33,0) -> 0 | L33: =IFERROR((C33+D33+F33)/$G33,0) -> 20.514325 | M33: no trash expense booked
A34: Ormond Beach Oasis | B34: OBOPO | C34: ='Sewer Monthly'!K34 -> 13990.28 | D34: ='WWTP Monthly'!K34 -> 0 | E34: =C34+D34 -> 13990.28 | F34: ='Trash Monthly'!K34 -> 17468.17 | G34: ='Occupied Lots'!K34 -> 318 | H34: =IFERROR(G34/8,0) -> 39.75 | I34: =IFERROR(C34/$G34,0) -> 43.994591 | J34: =IFERROR(D34/$G34,0) -> 0 | K34: =IFERROR(F34/$G34,0) -> 54.931352 | L34: =IFERROR((C34+D34+F34)/$G34,0) -> 98.925943
A35: Palm Haven Estates | B35: PPH | C35: ='Sewer Monthly'!K35 -> 1814.62 | D35: ='WWTP Monthly'!K35 -> 0 | E35: =C35+D35 -> 1814.62 | F35: ='Trash Monthly'!K35 -> 6990.74 | G35: ='Occupied Lots'!K35 -> 290 | H35: =IFERROR(G35/8,0) -> 36.25 | I35: =IFERROR(C35/$G35,0) -> 6.2573103 | J35: =IFERROR(D35/$G35,0) -> 0 | K35: =IFERROR(F35/$G35,0) -> 24.106 | L35: =IFERROR((C35+D35+F35)/$G35,0) -> 30.36331
A36: Palm Spring Estates | B36: PSEPO | C36: ='Sewer Monthly'!K36 -> 17525.98 | D36: ='WWTP Monthly'!K36 -> 209.21 | E36: =C36+D36 -> 17735.19 | F36: ='Trash Monthly'!K36 -> 10992.48 | G36: ='Occupied Lots'!K36 -> 265 | H36: =IFERROR(G36/8,0) -> 33.125 | I36: =IFERROR(C36/$G36,0) -> 66.135774 | J36: =IFERROR(D36/$G36,0) -> 0.7894717 | K36: =IFERROR(F36/$G36,0) -> 41.481057 | L36: =IFERROR((C36+D36+F36)/$G36,0) -> 108.4063
A37: Paradise Lakes | B37: PL | C37: ='Sewer Monthly'!K37 -> 0 | D37: ='WWTP Monthly'!K37 -> 23257.11 | E37: =C37+D37 -> 23257.11 | F37: ='Trash Monthly'!K37 -> 8305.3 | G37: ='Occupied Lots'!K37 -> 1255 | H37: =IFERROR(G37/8,0) -> 156.875 | I37: =IFERROR(C37/$G37,0) -> 0 | J37: =IFERROR(D37/$G37,0) -> 18.531562 | K37: =IFERROR(F37/$G37,0) -> 6.6177689 | L37: =IFERROR((C37+D37+F37)/$G37,0) -> 25.149331 | M37: sewer via own WWTP
A38: Paradise Palms | B38: PP | C38: ='Sewer Monthly'!K38 -> 0 | D38: ='WWTP Monthly'!K38 -> 0 | E38: =C38+D38 -> 0 | F38: ='Trash Monthly'!K38 -> 5092.77 | G38: ='Occupied Lots'!K38 -> 315 | H38: =IFERROR(G38/8,0) -> 39.375 | I38: =IFERROR(C38/$G38,0) -> 0 | J38: =IFERROR(D38/$G38,0) -> 0 | K38: =IFERROR(F38/$G38,0) -> 16.167524 | L38: =IFERROR((C38+D38+F38)/$G38,0) -> 16.167524 | M38: no sewer expense booked
A39: Parkwood Mobile Home Park | B39: PARK | C39: ='Sewer Monthly'!K39 -> 40447.8 | D39: ='WWTP Monthly'!K39 -> 511.29 | E39: =C39+D39 -> 40959.09 | F39: ='Trash Monthly'!K39 -> 23688.9 | G39: ='Occupied Lots'!K39 -> 508 | H39: =IFERROR(G39/8,0) -> 63.5 | I39: =IFERROR(C39/$G39,0) -> 79.621654 | J39: =IFERROR(D39/$G39,0) -> 1.0064764 | K39: =IFERROR(F39/$G39,0) -> 46.631693 | L39: =IFERROR((C39+D39+F39)/$G39,0) -> 127.25982
A40: Redlands | B40: RED | C40: ='Sewer Monthly'!K40 -> 1050 | D40: ='WWTP Monthly'!K40 -> 14819.38 | E40: =C40+D40 -> 15869.38 | F40: ='Trash Monthly'!K40 -> 17858.28 | G40: ='Occupied Lots'!K40 -> 648 | H40: =IFERROR(G40/8,0) -> 81 | I40: =IFERROR(C40/$G40,0) -> 1.6203704 | J40: =IFERROR(D40/$G40,0) -> 22.869414 | K40: =IFERROR(F40/$G40,0) -> 27.559074 | L40: =IFERROR((C40+D40+F40)/$G40,0) -> 52.048858
...

Sheet Occupied Lots
A1: Community | B1: RM Code | C1: Jan | D1: Feb | E1: Mar | F1: Apr | G1: May | H1: Jun | I1: Jul | J1: Aug | K1: Lot-months
A2: American | B2: AMER | C2: 39 | D2: 39 | E2: 39 | F2: 39 | G2: 40 | H2: 40 | I2: 40 | J2: 40 | K2: =SUM(C2:J2) -> 316
A3: Applegate MHC | B3: APPLE | C3: 74 | D3: 74 | E3: 74 | F3: 74 | G3: 74 | H3: 74 | I3: 74 | J3: 72 | K3: =SUM(C3:J3) -> 590
A4: Auburn Ridge | B4: ARD | C4: 147 | D4: 147 | E4: 145 | F4: 146 | G4: 148 | H4: 146 | I4: 146 | J4: 145 | K4: =SUM(C4:J4) -> 1170
A5: Bay Oaks Village II | B5: BOVIIPO | C5: 20 | D5: 19 | E5: 19 | F5: 19 | G5: 19 | H5: 19 | I5: 18 | J5: 18 | K5: =SUM(C5:J5) -> 151
A6: Belle Haven | B6: BELL | C6: 56 | D6: 56 | E6: 56 | F6: 56 | G6: 56 | H6: 53 | I6: 53 | J6: 53 | K6: =SUM(C6:J6) -> 439
A7: Brunswick Estates | B7: BRUN | C7: 54 | D7: 54 | E7: 52 | F7: 49 | G7: 48 | H7: 47 | I7: 47 | J7: 47 | K7: =SUM(C7:J7) -> 398
A8: Carley's Mobile Home Park | B8: CARL | C8: 75 | D8: 75 | E8: 75 | F8: 76 | G8: 76 | H8: 76 | I8: 76 | J8: 76 | K8: =SUM(C8:J8) -> 605
A9: Central Mobile Home Park | B9: CENT | C9: 59 | D9: 58 | E9: 58 | F9: 57 | G9: 57 | H9: 57 | I9: 57 | J9: 56 | K9: =SUM(C9:J9) -> 459
A10: Congress Mobile Home Park | B10: CONG | C10: 31 | D10: 31 | E10: 31 | F10: 31 | G10: 31 | H10: 31 | I10: 31 | J10: 31 | K10: =SUM(C10:J10) -> 248
A11: Crystal Acres | B11: CA | C11: 24 | D11: 24 | E11: 24 | F11: 24 | G11: 23 | H11: 23 | I11: 22 | J11: 23 | K11: =SUM(C11:J11) -> 187
A12: Druid Oaks MHC | B12: DO | C12: 100 | D12: 99 | E12: 99 | F12: 98 | G12: 98 | H12: 97 | I12: 96 | J12: 96 | K12: =SUM(C12:J12) -> 783
A13: Fox Creek | B13: FOX | C13: 106 | D13: 106 | E13: 102 | F13: 101 | G13: 99 | H13: 97 | I13: 101 | J13: 100 | K13: =SUM(C13:J13) -> 812
... A63: Wolf Bay MHC | B63: WOLFPO | C63: 43 | D63: 42 | E63: 41 | F63: 41 | G63: 40 | H63: 40 | I63: 40 | J63: 39 | K63: =SUM(C63:J63) -> 326
A64: PORTFOLIO TOTAL | C64: =SUM(C2:C63) -> 4680 | D64: =SUM(D2:D63) -> 4648 | E64: =SUM(E2:E63) -> 4992 | F64: =SUM(F2:F63) -> 5144 | G64: =SUM(G2:G63) -> 5112 | H64: =SUM(H2:H63) -> 5088 | I64: =SUM(I2:I63) -> 5073 | J64: =SUM(J2:J63) -> 4975 | K64: =SUM(K2:K63) -> 39712

Sheet Sewer Monthly
A1: Community | B1: RM Code | C1: Jan | D1: Feb | E1: Mar | F1: Apr | G1: May | H1: Jun | I1: Jul | J1: Aug | K1: YTD Total | L1: Per lot / mo
A2: American | B2: AMER | C2: 0 | D2: 0 | E2: 0 | F2: 0 | G2: 0 | H2: 0 | I2: 0 | J2: 0 | K2: =SUM(C2:J2) -> 0 | L2: =IFERROR(K2/'Occupied Lots'!K2,0) -> 0
A3: Applegate MHC | B3: APPLE | C3: 0 | D3: 0 | E3: 0 | F3: 0 | G3: 0 | H3: 0 | I3: 0 | J3: 0 | K3: =SUM(C3:J3) -> 0 | L3: =IFERROR(K3/'Occupied Lots'!K3,0) -> 0
A4: Auburn Ridge | B4: ARD | C4: 0 | D4: 0 | E4: 0 | F4: 0 | G4: 0 | H4: 0 | I4: 0 | J4: 0 | K4: =SUM(C4:J4) -> 0 | L4: =IFERROR(K4/'Occupied Lots'!K4,0) -> 0
A5: Bay Oaks Village II | B5: BOVIIPO | C5: 0 | D5: 0 | E5: 0 | F5: 0 | G5: 0 | H5: 0 | I5: 0 | J5: 0 | K5: =SUM(C5:J5) -> 0 | L5: =IFERROR(K5/'Occupied Lots'!K5,0) -> 0
A6: Belle Haven | B6: BELL | C6: 6602.6 | D6: 0 | E6: 4919.96 | F6: 0 | G6: 4179.91 | H6: 0 | I6: 6004.3 | J6: 0 | K6: =SUM(C6:J6) -> 21706.77 | L6: =IFERROR(K6/'Occupied Lots'!K6,0) -> 49.445945
A7: Brunswick Estates | B7: BRUN | C7: 314.14 | D7: 81.24 | E7: 229.41 | F7: 336.43 | G7: 277.62 | H7: 253.07 | I7: 319.6 | J7: 389.2 | K7: =SUM(C7:J7) -> 2200.71 | L7: =IFERROR(K7/'Occupied Lots'!K7,0) -> 5.5294221
A8: Carley's Mobile Home Park | B8: CARL | C8: 0 | D8: 1687.5 | E8: 0 | F8: 0 | G8: 0 | H8: 0 | I8: 1687.5 | J8: 0 | K8: =SUM(C8:J8) -> 3375 | L8: =IFERROR(K8/'Occupied Lots'!K8,0) -> 5.5785124
A9: Central Mobile Home Park | B9: CENT | C9: 0 | D9: 1908.85 | E9: 115.63 | F9: 231.26 | G9: 0 | H9: 115.63 | I9: 14885.1 | J9: 4118 | K9: =SUM(C9:J9) -> 21374.47 | L9: =IFERROR(K9/'Occupied Lots'!K9,0) -> 46.567473
A10: Congress Mobile Home Park | B10: CONG | C10: 1143.29 | D10: 1210.27 | E10: 1198.45 | F10: 1267.4 | G10: 1119.65 | H10: 0 | I10: 1206.33 | J10: 0 | K10: =SUM(C10:J10) -> 7145.39 | L10: =IFERROR(K10/'Occupied Lots'!K10,0) -> 28.812056
A11: Crystal Acres | B11: CA | C11: 0 | D11: 0 | E11: 0 | F11: 0 | G11: 0 | H11: 0 | I11: 0 | J11: 0 | K11: =SUM(C11:J11) -> 0 | L11: =IFERROR(K11/'Occupied Lots'!K11,0) -> 0
A12: Druid Oaks MHC | B12: DO | C12: 0 | D12: 0 | E12: 0 | F12: 0 | G12: 0 | H12: 0 | I12: 0 | J12: 0 | K12: =SUM(C12:J12) -> 0 | L12: =IFERROR(K12/'Occupied Lots'!K12,0) -> 0
A13: Fox Creek | B13: FOX | C13: 0 | D13: 0 | E13: 90.72 | F13: 312.5 | G13: 168.62 | H13: 381.28 | I13: 520.75 | J13: 754.54 | K13: =SUM(C13:J13) -> 2228.41 | L13: =IFERROR(K13/'Occupied Lots'!K13,0) -> 2.7443473
... A63: Wolf Bay MHC | B63: WOLFPO | C63: 1890 | D63: 1890 | E63: 1890 | F63: 3780 | G63: 0 | H63: 1890 | I63: 1899.45 | J63: 1890 | K63: =SUM(C63:J63) -> 15129.45 | L63: =IFERROR(K63/'Occupied Lots'!K63,0) -> 46.409356
A64: PORTFOLIO TOTAL | C64: =SUM(C2:C63) -> 57635.42 | D64: =SUM(D2:D63) -> 102779.94 | E64: =SUM(E2:E63) -> 48226.48 | F64: =SUM(F2:F63) -> 66967.04 | G64: =SUM(G2:G63) -> 56444.25 | H64: =SUM(H2:H63) -> 47530.44 | I64: =SUM(I2:I63) -> 90623.72 | J64: =SUM(J2:J63) -> 42098.86 | K64: =SUM(K2:K63) -> 512306.15 | L64: =IFERROR(K64/'Occupied Lots'!K64,0) -> 12.900538

Sheet Trash Monthly
A1: Community | B1: RM Code | C1: Jan | D1: Feb | E1: Mar | F1: Apr | G1: May | H1: Jun | I1: Jul | J1: Aug | K1: YTD Total | L1: Per lot / mo
A2: American | B2: AMER | C2: 580 | D2: 580 | E2: 680 | F2: 580 | G2: 580 | H2: 580 | I2: 580 | J2: 580 | K2: =SUM(C2:J2) -> 4740 | L2: =IFERROR(K2/'Occupied Lots'!K2,0) -> 15
A3: Applegate MHC | B3: APPLE | C3: 3701.99 | D3: 0 | E3: 1859.56 | F3: 4064.01 | G3: 928.55 | H3: 2040.72 | I3: 3956.7 | J3: 2014.65 | K3: =SUM(C3:J3) -> 18566.18 | L3: =IFERROR(K3/'Occupied Lots'!K3,0) -> 31.468102
A4: Auburn Ridge | B4: ARD | C4: 905 | D4: 30.75 | E4: 0 | F4: 1755.75 | G4: 91.34 | H4: 30.75 | I4: 30.75 | J4: 224.49 | K4: =SUM(C4:J4) -> 3068.83 | L4: =IFERROR(K4/'Occupied Lots'!K4,0) -> 2.6229316
A5: Bay Oaks Village II | B5: BOVIIPO | C5: 704.61 | D5: 704.61 | E5: 704.61 | F5: 723.48 | G5: 723.48 | H5: 723.48 | I5: 0 | J5: 1446.96 | K5: =SUM(C5:J5) -> 5731.23 | L5: =IFERROR(K5/'Occupied Lots'!K5,0) -> 37.955166
A6: Belle Haven | B6: BELL | C6: 1324.85 | D6: 0 | E6: 1248.3 | F6: 1248.3 | G6: 2496.6 | H6: 0 | I6: 2496.6 | J6: 0 | K6: =SUM(C6:J6) -> 8814.65 | L6: =IFERROR(K6/'Occupied Lots'!K6,0) -> 20.078929
A7: Brunswick Estates | B7: BRUN | C7: 719.24 | D7: 0 | E7: 198.81 | F7: 462.79 | G7: 462.67 | H7: 55.65 | I7: 594.31 | J7: 393.11 | K7: =SUM(C7:J7) -> 2886.58 | L7: =IFERROR(K7/'Occupied Lots'!K7,0) -> 7.2527136
A8: Carley's Mobile Home Park | B8: CARL | C8: 4688.94 | D8: 6963.94 | E8: 9237.88 | F8: 517.5 | G8: 6872.34 | H8: 5886.44 | I8: 10790.38 | J8: 5774.1 | K8: =SUM(C8:J8) -> 50731.52 | L8: =IFERROR(K8/'Occupied Lots'!K8,0) -> 83.853752
A9: Central Mobile Home Park | B9: CENT | C9: 0 | D9: 3742.75 | E9: 3455.71 | F9: 6911.42 | G9: 0 | H9: 3228.85 | I9: 15109.94 | J9: 6624.38 | K9: =SUM(C9:J9) -> 39073.05 | L9: =IFERROR(K9/'Occupied Lots'!K9,0) -> 85.126471
A10: Congress Mobile Home Park | B10: CONG | C10: 0 | D10: 0 | E10: 0 | F10: 0 | G10: 0 | H10: 0 | I10: 0 | J10: 0 | K10: =SUM(C10:J10) -> 0 | L10: =IFERROR(K10/'Occupied Lots'!K10,0) -> 0
A11: Crystal Acres | B11: CA | C11: 417.48 | D11: 33.7 | E11: 68.16 | F11: 1370.86 | G11: 1369.42 | H11: 1351.06 | I11: 1320.58 | J11: 1356.22 | K11: =SUM(C11:J11) -> 7287.48 | L11: =IFERROR(K11/'Occupied Lots'!K11,0) -> 38.970481
A12: Druid Oaks MHC | B12: DO | C12: 0 | D12: 0 | E12: 0 | F12: 0 | G12: 0 | H12: 0 | I12: 1121.34 | J12: 112.65 | K12: =SUM(C12:J12) -> 1233.99 | L12: =IFERROR(K12/'Occupied Lots'!K12,0) -> 1.575977
A13: Fox Creek | B13: FOX | C13: 2486.53 | D13: 4973.06 | E13: 0 | F13: 2486.53 | G13: 2981.53 | H13: 2486.53 | I13: 2486.53 | J13: 2486.53 | K13: =SUM(C13:J13) -> 20387.24 | L13: =IFERROR(K13/'Occupied Lots'!K13,0) -> 25.107438
... A63: Wolf Bay MHC | B63: WOLFPO | C63: 574.44 | D63: 570.02 | E63: 1342.04 | F63: 1032.33 | G63: 1901.01 | H63: 1632.99 | I63: 3296.92 | J63: 1452.13 | K63: =SUM(C63:J63) -> 11801.88 | L63: =IFERROR(K63/'Occupied Lots'!K63,0) -> 36.202086
A64: PORTFOLIO TOTAL | C64: =SUM(C2:C63) -> 104935.04 | D64: =SUM(D2:D63) -> 93460.8 | E64: =SUM(E2:E63) -> 122983.35 | F64: =SUM(F2:F63) -> 118784.69 | G64: =SUM(G2:G63) -> 114648.24 | H64: =SUM(H2:H63) -> 114510.56 | I64: =SUM(I2:I63) -> 175503.12 | J64: =SUM(J2:J63) -> 123012.59 | K64: =SUM(K2:K63) -> 967838.39 | L64: =IFERROR(K64/'Occupied Lots'!K64,0) -> 24.371434

Sheet WWTP Monthly
A1: Community | B1: RM Code | C1: Jan | D1: Feb | E1: Mar | F1: Apr | G1: May | H1: Jun | I1: Jul | J1: Aug | K1: YTD Total | L1: Per lot / mo
A2: American | B2: AMER | C2: 0 | D2: 0 | E2: 0 | F2: 0 | G2: 0 | H2: 0 | I2: 0 | J2: 0 | K2: =SUM(C2:J2) -> 0 | L2: =IFERROR(K2/'Occupied Lots'!K2,0) -> 0
A3: Applegate MHC | B3: APPLE | C3: 4105.92 | D3: 1840 | E3: 1380 | F3: 1097.1 | G3: 2212.6 | H3: 5642 | I3: 2155 | J3: 6530.78 | K3: =SUM(C3:J3) -> 24963.4 | L3: =IFERROR(K3/'Occupied Lots'!K3,0) -> 42.310847
A4: Auburn Ridge | B4: ARD | C4: 0 | D4: 0 | E4: 0 | F4: 0 | G4: 0 | H4: 0 | I4: 0 | J4: 0 | K4: =SUM(C4:J4) -> 0 | L4: =IFERROR(K4/'Occupied Lots'!K4,0) -> 0
A5: Bay Oaks Village II | B5: BOVIIPO | C5: 0 | D5: 0 | E5: 0 | F5: 0 | G5: 0 | H5: 0 | I5: 0 | J5: 0 | K5: =SUM(C5:J5) -> 0 | L5: =IFERROR(K5/'Occupied Lots'!K5,0) -> 0
A6: Belle Haven | B6: BELL | C6: 0 | D6: 0 | E6: 0 | F6: 0 | G6: 0 | H6: 0 | I6: 0 | J6: 0 | K6: =SUM(C6:J6) -> 0 | L6: =IFERROR(K6/'Occupied Lots'!K6,0) -> 0
A7: Brunswick Estates | B7: BRUN | C7: 0 | D7: 0 | E7: 0 | F7: 0 | G7: 0 | H7: 0 | I7: 0 | J7: 0 | K7: =SUM(C7:J7) -> 0 | L7: =IFERROR(K7/'Occupied Lots'!K7,0) -> 0
A8: Carley's Mobile Home Park | B8: CARL | C8: 0 | D8: 0 | E8: 73 | F8: 0 | G8: 0 | H8: 0 | I8: 0 | J8: 0 | K8: =SUM(C8:J8) -> 73 | L8: =IFERROR(K8/'Occupied Lots'!K8,0) -> 0.12066116
A9: Central Mobile Home Park | B9: CENT | C9: 0 | D9: 658.31 | E9: 0 | F9: 0 | G9: 0 | H9: 0 | I9: 0 | J9: 0 | K9: =SUM(C9:J9) -> 658.31 | L9: =IFERROR(K9/'Occupied Lots'!K9,0) -> 1.4342266
A10: Congress Mobile Home Park | B10: CONG | C10: 0 | D10: 0 | E10: 0 | F10: 275 | G10: 1124 | H10: 0 | I10: 0 | J10: 0 | K10: =SUM(C10:J10) -> 1399 | L10: =IFERROR(K10/'Occupied Lots'!K10,0) -> 5.641129
A11: Crystal Acres | B11: CA | C11: 0 | D11: 0 | E11: 0 | F11: 0 | G11: 0 | H11: 0 | I11: 0 | J11: 0 | K11: =SUM(C11:J11) -> 0 | L11: =IFERROR(K11/'Occupied Lots'!K11,0) -> 0
A12: Druid Oaks MHC | B12: DO | C12: 0 | D12: 0 | E12: 0 | F12: 0 | G12: 0 | H12: 0 | I12: 0 | J12: 0 | K12: =SUM(C12:J12) -> 0 | L12: =IFERROR(K12/'Occupied Lots'!K12,0) -> 0
A13: Fox Creek | B13: FOX | C13: 0 | D13: 0 | E13: 0 | F13: 0 | G13: 0 | H13: 0 | I13: 0 | J13: 0 | K13: =SUM(C13:J13) -> 0 | L13: =IFERROR(K13/'Occupied Lots'!K13,0) -> 0
... A63: Wolf Bay MHC | B63: WOLFPO | C63: 0 | D63: 0 | E63: 0 | F63: 491.93 | G63: 0 | H63: 450 | I63: 0 | J63: 0 | K63: =SUM(C63:J63) -> 941.93 | L63: =IFERROR(K63/'Occupied Lots'!K63,0) -> 2.8893558
A64: PORTFOLIO TOTAL | C64: =SUM(C2:C63) -> 62976.41 | D64: =SUM(D2:D63) -> 36085.62 | E64: =SUM(E2:E63) -> 36803.95 | F64: =SUM(F2:F63) -> 36868.57 | G64: =SUM(G2:G63) -> 59658.16 | H64: =SUM(H2:H63) -> 46347.92 | I64: =SUM(I2:I63) -> 39579.16 | J64: =SUM(J2:J63) -> 29659.33 | K64: =SUM(K2:K63) -> 347979.12 | L64: =IFERROR(K64/'Occupied Lots'!K64,0) -> 8.7625685

Sheet Exceptions
A1: A. Occupied lots in RM but ZERO sewer, WWTP or trash expense booked in 2026
A2: Community | B2: RM Code | C2: Avg occupied lots | D2: Months of occupancy data
A3: Cambridge MHC | B3: CAMMHC | C3: 90.4 | D3: 8
A4: BEDROCK MHC | B4: BMHC | C4: 1 | D4: 8
A5: Valley View MHC | B5: VV | C5: 57 | D5: 2
A6: Apple Creek | B6: ACMHC | C6: 166 | D6: 8
A7: Parktown MHC | B7: PTMHC | C7: 41 | D7: 8
A8: Countryside MHC | B8: CSMHC | C8: 29 | D8: 8
A9: Cedar Grove Manufactured Housing Community | B9: CG | C9: 124 | D9: 8
A10: Colonial Manufactured Housing Community | B10: C | C10: 104 | D10: 8
A11: Lambeth Manufactured Housing Community | B11: LB | C11: 63 | D11: 2
A12: xParkwood Manufactured Housing Community | B12: PW | C12: 97 | D12: 8
A13: Everglades Mobile Home Park | B13: EG | C13: 53 | D13: 8
A14: Royal Palm Trailer Park | B14: RP | C14: 50 | D14: 8
... A24: Shirleys Trailer Park II | B24: STPII | C24: 8 | D24: 2
A27: B. Sewer / trash expense booked but NO occupied lots in 2026 (no per-lot figure possible)
A28: Property | B28: RM Code | C28: Sewer YTD | D28: WWTP YTD | E28: Trash YTD
A29: Hunter Springs MHC | B29: HSRC | C29: 955.67 | D29: 0 | E29: 1399.64
A30: Geiger Key Fish Camp Opco | B30: GKFC | C30: 9700.11 | D30: 0 | E30: 48291.31
A33: C. Legacy entity records folded into their current entity (expense split across both in 2026)
A34: Legacy record | B34: Legacy code | C34: Folded into | D34: Current code
A35: xTown & Country MHC | B35: TCMHC | C35: Town & Country MHC | D35: TCMHCPO
A36: xOceanaire MHC | B36: OCEAN | C36: Oceanaire MHC | D36: OCEANPO
A37: xWolf Bay Manufactured Housing Community | B37: WOLF | C37: Wolf Bay MHC | D37: WOLFPO
A38: xPalm Spring Estates | B38: PSE | C38: Palm Spring Estates | D38: PSEPO
A39: xOrmond Beach Oasis | B39: OBO | C39: Ormond Beach Oasis | D39: OBOPO
A40: xBay Oaks Village I | B40: BOVI | C40: Bay Oaks Village I | D40: BOVIPO
A41: xBay Oaks Village II | B41: BOVII | C41: Bay Oaks Village II | D41: BOVIIPO
A42: xGulf Breeze MHP | B42: GULF | C42: Gulf Breeze MHC | D42: GULFPO
A43: xWestwood MHP | B43: WW | C43: Westwood MHC | D43: WWPO
A44: xLake Wales MHC | B44: LW | C44: Lake Wales MHC | D44: LWPO
A47: D. Sold communities - shown for completeness, exclude from current-period metrics
A48: Community | B48: RM Code | C48: Note
A49: Congress Mobile Home Park | B49: CONG | C49: sold Jul-2026
A50: Shell Pointe MHC | B50: SP | C50: sold Jul-2026
A53: E. Partial-year occupancy - per-lot figures cover only the months with occupancy
A54: Community | B54: RM Code | C54: Months with occupancy
A55: McGregor Downs | B55: MCG | C55: 5
A56: Regency I & II | B56: REG | C56: 6

Sheet Source
A1: Report | B1: RentViewer Data Warehouse (Rent Manager) via MCP - models VW_Budget_Comparison and VW_Rental_Unit_Listing
A2: Pulled | B2: 2026-09-04
A3: Period | B3: 2026-01-01 through 2026-08-31 (August is the last closed month; September is not closed)
A4: Sewer accounts | B4: 51804 Sewer + 51810 Sewer Base Rate
A5: WWTP accounts | B5: 51821 WWTP Dumping Fee + 51822 WWTP Maintenance + 51823 WWTP Service Call (self-operated plant - shown separately because it substitutes for municipal sewer)
A6: Trash accounts | B6: 51811 Garbage Base + 51812 Garbage Overage + 51813 Roll Offs
A7: Excluded accounts | B7: 51805 Water, 51801 Electric, 51808 Water Testing, 51817 Chlorine, 51819/51820 Private Water, 51816 Stormwater, 51815 Backflow, and all other 518xx
A8: Denominator | B8: Occupied units (unit-level, all unit types) from VW_Rental_Unit_Listing, occupiedUnits segment, by report month. Lot-months = sum of occupied lots across Jan-Aug.
A9: Per-lot basis | B9: Cost per OCCUPIED LOT per month. Rent Manager does not hold reliable occupant head-counts, so this is not cost per person.
A10: Entity merges | B10: Ten legacy "x" property records were folded into their current entity (see Exceptions tab C). Without this merge January 2026 expense is missing from the current record.
A11: Scope | B11: 62 property records with both expense and 2026 occupancy. 24 records with occupancy but no expense and 2 with expense but no occupancy are listed on the Exceptions tab, not in the table.
A12: Measure | B12: VW_Budget_Comparison.totalActual (actual, not budget).
