Workbook

Sheet Sheet1
B2: Community | C2: Short Name | D2: Portfolio | E2: Sign Package | F2: Higher End Sign Structure/Package | G2: Property Specific Notes
B3: American | C3: AMER | D3: BAKER | E3: Nothing | F3: --
B4: Monson | C4: MON | D4: BAKER | E4: Nothing | F4: --
B5: Whispering Pines MA | C5: WPMA | D5: BAKER | E5: Nothing | F5: --
B6: Lamberton Lake | C6: LLMHC | D6: BEDROCK FUND II | E6: Nothing | F6: --
B7: Everglades MHP | C7: EG | D7: GBH | E7: FULL NEW SIGN PACKAGE | F7: Low End
B8: Royal Palm | C8: RP | D8: GBH | E8: FULL NEW SIGN PACKAGE | F8: Low End
B9: Crystal Acres | C9: CA | D9: KIPPY | E9: Nothing | F9: --
B10: Hunter Springs | C10: HSRC | D10: KIPPY | E10: Nothing | F10: --
B11: Royal Oaks | C11: ROYAL | D11: KIPPY | E11: Nothing | F11: --
B12: Bay Oaks Village I | C12: BOVI | D12: ORIGINS | E12: FULL NEW SIGN PACKAGE | F12: High End
B13: Bay Oaks Village II | C13: BOVII | D13: ORIGINS | E13: FULL NEW SIGN PACKAGE | F13: High End
B14: Gulf Breeze | C14: GULF | D14: ORIGINS | E14: FULL NEW SIGN PACKAGE | F14: High End | G14: May have to go on fence b/c of easement or property line
B15: Lake Wales MHC | C15: LW | D15: ORIGINS | E15: FULL NEW SIGN PACKAGE | F15: Low End
B16: Oceanaire | C16: OCEAN | D16: ORIGINS | E16: FULL NEW SIGN PACKAGE | F16: High End
B17: Ormond Beach | C17: OBO | D17: ORIGINS | E17: FULL NEW SIGN PACKAGE | F17: High End
B18: Palm Spring | C18: PSE | D18: ORIGINS | E18: FULL NEW SIGN PACKAGE | F18: High End
B19: Town & Country | C19: TCMHC | D19: ORIGINS | E19: FULL NEW SIGN PACKAGE | F19: High End
B20: Westwood | C20: WW | D20: ORIGINS | E20: FULL NEW SIGN PACKAGE | F20: High End | G20: One at each entrance to the community on our land
B21: Wolf Bay | C21: WOLF | D21: ORIGINS | E21: FULL NEW SIGN PACKAGE | F21: High End
B22: Applegate | C22: APPLE | D22: PARAKEET I | E22: FULL NEW SIGN PACKAGE | F22: High End
B23: Belle Haven | C23: BELL | D23: PARAKEET I | E23: FULL NEW SIGN PACKAGE | F23: High End | G23: When fence goes in we will put signs in. Need 2-3 and confirm exact location.
B24: Carley's | C24: CARL | D24: PARAKEET I | E24: FULL NEW SIGN PACKAGE | F24: High End
B25: Central | C25: CENT | D25: PARAKEET I | E25: FULL NEW SIGN PACKAGE | F25: High End
B26: Congress | C26: CONG | D26: PARAKEET I | E26: Nothing | F26: --
B27: Geiger Key | C27: GEIGRV | D27: PARAKEET I | E27: Nothing | F27: --
B28: Harbour | C28: HARB | D28: PARAKEET I | E28: FULL NEW SIGN PACKAGE | F28: High End
B29: J Bar J Estates | C29: JBJ | D29: PARAKEET I | E29: FULL NEW SIGN PACKAGE | F29: High End | G29: Using existing sign structure
B30: Lake Saunders | C30: LS | D30: PARAKEET I | E30: Nothing | F30: --
B31: Lucky Clover | C31: LUCK | D31: PARAKEET I | E31: FULL NEW SIGN PACKAGE | F31: High End | G31: Using existing sign structure
B32: Palm Haven Estates | C32: PPH | D32: PARAKEET I | E32: FULL NEW SIGN PACKAGE | F32: High End
B33: Paradise Lakes | C33: PL | D33: PARAKEET I | E33: FULL NEW SIGN PACKAGE | F33: High End | G33: Using existing sign structure
B34: River Oaks | C34: RO | D34: PARAKEET I | E34: FULL NEW SIGN PACKAGE | F34: High End | G34: Using existing sign structure
B35: Riviera | C35: RIV | D35: PARAKEET I | E35: FULL NEW SIGN PACKAGE | F35: High End
B36: Sea Shells | C36: SS | D36: PARAKEET I | E36: FULL NEW SIGN PACKAGE | F36: High End
B37: Shady Oaks | C37: SO | D37: PARAKEET I | E37: FULL NEW SIGN PACKAGE | F37: High End
B38: Silver Breeze | C38: SILVER | D38: PARAKEET I | E38: FULL NEW SIGN PACKAGE | F38: High End
B39: Southgate | C39: SOUTH | D39: PARAKEET I | E39: FULL NEW SIGN PACKAGE | F39: High End
B40: Tradewinds | C40: TRADE | D40: PARAKEET I | E40: FULL NEW SIGN PACKAGE | F40: High End
B41: Triple S | C41: SSS | D41: PARAKEET I | E41: FULL NEW SIGN PACKAGE | F41: High End
...

Sheet Data
B2: Property Short Name | C2: Portfolio | D2: Project Category | E2: Project Description | F2: Cost | G2: Start Date | H2: End Date | I2: Monthly Amt | J2: Update | K2: High/Low Priority | L2: Responsibility | M2: Cost | N2: Start Date | O2: End Date | P2: Notes | R2: Project Category | U2: Property Short Name
B3: APPLE | C3: JREFI | D3: Utilities - Sewer | E3: Generator for Lift Station + Hookup | F3: 6000 | G3: 46053 | H3: 46112 | I3: 2000 | J3: Existing | K3: Low | L3: Construction | M3: 11000 | N3: 46113 | R3: Miscellaneous | U3: NGMH | X3: Complete
B4: APPLE | C4: JREFI | D4: Signage | E4: Sign Package | F4: 7500 | G4: 46053 | H4: 46112 | I4: 2500 | J4: Deleted | L4: Construction | M4: 7500 | N4: 46053 | O4: 46112 | R4: Utilities - Water | U4: SH | X4: Existing
B5: APPLE | C5: JREFI | D5: Landscaping | E5: Tree Trimming | F5: 30000 | G5: 46053 | H5: 46112 | I5: 10000 | J5: Existing | K5: Low | L5: Construction | M5: 30000 | N5: 46053 | O5: 46112 | R5: Fencing | U5: TO | X5: New
B6: APPLE | C6: JREFI | D6: Miscellaneous | E6: Upgrade Mailboxes & Enclosure | F6: 15000 | G6: 46142 | H6: 46203 | I6: 5000 | J6: Existing | K6: High | L6: Construction | M6: 15000 | N6: 46142 | O6: 46203 | R6: Amenities | U6: APPLE | X6: Deleted
B7: APPLE | C7: JREFI | D7: Amenities | E7: Playground | F7: 40000 | G7: 46326 | H7: 46387 | I7: 13333.333 | J7: Deleted | M7: 40000 | N7: 46326 | O7: 46387 | R7: Utilities - Sewer | U7: BELL
B8: BELL | C8: JREFI | D8: Landscaping | E8: Mower | F8: 5000 | G8: 46053 | H8: 46112 | I8: 1666.6667 | J8: Existing | L8: Operations | M8: 5000 | N8: 46053 | O8: 46112 | R8: Signage | U8: CARL
B9: BELL | C9: JREFI | D9: Signage | E9: Sign Package | F9: 7500 | G9: 46112 | H9: 46173 | I9: 2500 | J9: Deleted | M9: 7500 | N9: 46112 | O9: 46173 | R9: Landscaping | U9: CENT
B10: BELL | C10: JREFI | D10: Permanent Structures | E10: Dumpster Pad on Lot 2 | F10: 7500 | G10: 46112 | H10: 46173 | I10: 2500 | J10: Deleted | M10: 7500 | N10: 46112 | O10: 46173 | R10: Permanent Structures | U10: CONG
B11: BELL | C11: JREFI | D11: Amenities | E11: Bath House Upgrade | F11: 10000 | G11: 46112 | H11: 46173 | I11: 3333.3333 | J11: Existing | K11: High | L11: Construction | M11: 10000 | N11: 46112 | R11: Lighting | U11: JBJ
B12: BELL | C12: JREFI | D12: Amenities | E12: Clubhouse Upgrade | F12: 10000 | G12: 46203 | H12: 46265 | I12: 3333.3333 | J12: Existing | K12: High | L12: Construction | M12: 10000 | N12: 46112 | R12: Utilities - Electrical | U12: LS
B13: BELL | C13: JREFI | D13: Fencing | E13: Perimeter Fence | F13: 10000 | G13: 46203 | H13: 46265 | I13: 3333.3333 | J13: Existing | K13: High | L13: Construction | M13: 30000 | N13: 46112 | R13: Paving & Roads | U13: LUCK
B14: BELL | C14: JREFI | D14: Amenities | E14: Grill Area | F14: 5000 | G14: 46387 | H14: 46446 | I14: 1704.5455 | J14: Existing | K14: High | L14: Construction | M14: 20000 | N14: 46112 | R14: Lot Preparation | U14: PL
B15: CARL | C15: JREFI | D15: Landscaping | E15: One time tree trimming removal | F15: 30000 | G15: 46053 | H15: 46112 | I15: 10000 | J15: Complete | K15: Low | L15: Construction | M15: 30000 | N15: 46053 | O15: 46112 | R15: Drainage | U15: PPH
B16: CARL | C16: JREFI | D16: Permanent Structures | E16: Maintenance building removal/storage addition | F16: 10000 | G16: 46053 | H16: 46112 | I16: 3333.3333 | J16: Complete | K16: Low | L16: Construction | M16: 10000 | N16: 46053 | O16: 46112 | R16: Seawall | U16: RIV
B17: CARL | C17: JREFI | D17: Utilities - Sewer | E17: Sewer Tie-In/Septic | F17: 72000 | G17: 46053 | H17: 48213 | I17: 1000 | J17: Existing | K17: Low | L17: Construction | M17: 72000 | N17: 46053 | O17: 48213 | R17: POH | U17: RO
B18: CARL | C18: JREFI | D18: Signage | E18: New Sign | F18: 7500 | G18: 46053 | H18: 46112 | I18: 2500 | J18: Deleted | M18: 7500 | N18: 46053 | O18: 46112 | U18: SILVER
B19: CARL | C19: JREFI | D19: Amenities | E19: BBQ Area | J19: New | K19: High | L19: Construction | M19: 20000 | N19: 46142 | U19: SO
B20: CARL | C20: JREFI | D20: Amenities | E20: Parking | J20: New | K20: High | L20: Construction | M20: 15000 | N20: 46142 | U20: SO
B21: CARL | C21: JREFI | D21: Amenities | E21: Playground | F21: 35000 | G21: 46142 | H21: 46203 | I21: 11666.667 | J21: Deleted | M21: 35000 | N21: 46142 | O21: 46203 | U21: SO
B22: CENT | C22: JREFI | D22: Signage | E22: Sign Package | F22: 7500 | G22: 46053 | H22: 46112 | I22: 2500 | J22: Deleted | M22: 7500 | N22: 46053 | O22: 46112 | U22: SOUTH
B23: CENT | C23: JREFI | D23: Paving & Roads | E23: Seal Coat / Speedbump | F23: 20000 | G23: 46142 | H23: 46203 | I23: 6666.6667 | J23: Existing | K23: Low | L23: Construction | M23: 20000 | N23: 46326 | U23: SS
B24: CENT | C24: JREFI | D24: Miscellaneous | E24: Mailbox Enclosure | F24: 15000 | G24: 46234 | H24: 46295 | I24: 5000 | J24: Existing | K24: High | L24: Construction | M24: 15000 | N24: 46142 | U24: SSS
B25: CENT | C25: JREFI | D25: Lighting | E25: Lighting | F25: 15000 | G25: 46234 | H25: 46295 | I25: 5000 | J25: Existing | K25: High | L25: Construction | M25: 15000 | N25: 46142 | U25: TRADE
B26: CENT | C26: JREFI | D26: Fencing | E26: Fencing behind A & D St. | F26: 10000 | G26: 46234 | H26: 46295 | I26: 3333.3333 | J26: Existing | K26: High | L26: Construction | M26: 10000 | N26: 46142 | U26: VO
B27: CONG | C27: JREFI | D27: Lighting | E27: Solar Lights | F27: 5000 | G27: 46053 | H27: 46112 | I27: 1666.6667 | J27: Deleted | M27: 5000 | N27: 46053 | O27: 46112 | U27: WPMH
B28: CONG | C28: JREFI | D28: Signage | E28: New Sign | F28: 7500 | G28: 46142 | H28: 46203 | I28: 2500 | J28: Deleted | M28: 7500 | N28: 46142 | O28: 46203 | U28: PARK
B29: CONG | C29: JREFI | D29: Paving & Roads | E29: Seal coat roads & remove tree | F29: 25000 | G29: 46234 | H29: 46295 | I29: 8333.3333 | J29: Deleted | M29: 25000 | N29: 46234 | O29: 46295 | U29: FOX
B30: HARB | C30: JREFI | D30: Miscellaneous | E30: New Mailbox & Enclosure | F30: 15000 | G30: 46234 | H30: 46295 | I30: 5000 | J30: Existing | K30: High | L30: Construction | M30: 15000 | N30: 46142 | U30: ARD
B31: HARB | C31: JREFI | D31: Lighting | E31: Community Lighting | F31: 15000 | G31: 46234 | H31: 46295 | I31: 5000 | J31: Existing | K31: High | L31: Construction | M31: 15000 | N31: 46142 | U31: BRUN
B32: HARB | C32: JREFI | D32: Signage | E32: Sign Package | F32: 7500 | G32: 46326 | H32: 46387 | I32: 2500 | J32: Deleted | M32: 7500 | N32: 46326 | O32: 46387 | U32: DO
B33: HARB | C33: JREFI | D33: Fencing | E33: Fencing on A & D St. | F33: 10000 | G33: 46326 | H33: 46387 | I33: 3333.3333 | J33: Existing | K33: High | L33: Construction | M33: 10000 | N33: 46142 | U33: GO
B34: JBJ | C34: JREFI | D34: Utilities - Sewer | E34: Sewer Tie-in/Septic | F34: 360000 | G34: 46053 | H34: 48213 | I34: 5000 | J34: Existing | K34: Low | L34: Construction | M34: 360000 | N34: 46053 | O34: 48213 | U34: GPT
B35: JBJ | C35: JREFI | D35: Landscaping | E35: Tree Removal Project | F35: 15000 | G35: 46053 | H35: 46112 | I35: 5000 | J35: Existing | K35: Low | L35: Construction | M35: 15000 | N35: 46053 | O35: 46112 | U35: HP
B36: JBJ | C36: JREFI | D36: Paving & Roads | E36: Road Timbers | F36: 4000 | G36: 46142 | H36: 46203 | I36: 1333.3333 | J36: Existing | K36: Low | L36: Construction | M36: 4000 | N36: 46142 | O36: 46203 | U36: OAK
B37: JBJ | C37: JREFI | D37: Amenities | E37: Mailbox Replacement | F37: 15000 | G37: 46234 | H37: 46295 | I37: 5000 | J37: Existing | K37: High | L37: Construction | M37: 15000 | N37: 46234 | O37: 46295 | U37: RED
B38: LS | C38: JREFI | D38: Amenities | E38: Clubhouse furniture | F38: 4000 | G38: 46053 | H38: 46112 | I38: 1333.3333 | J38: Existing | K38: Low | L38: Operations | M38: 4000 | N38: 46053 | O38: 46112 | U38: RW
B39: LS | C39: JREFI | D39: Amenities | E39: Paint exterior clubhouse | F39: 4000 | G39: 46053 | H39: 46112 | I39: 1333.3333 | J39: Existing | K39: Low | L39: Construction | M39: 4000 | N39: 46053 | O39: 46112 | U39: SA
B40: LS | C40: JREFI | D40: Miscellaneous | E40: Enclosure Roofing on Mailbox Area | F40: 10000 | G40: 46234 | H40: 46295 | I40: 3333.3333 | J40: Existing | K40: Low | L40: Construction | M40: 10000 | N40: 46234 | O40: 46295 | U40: MON
B41: LS | C41: JREFI | D41: Miscellaneous | E41: Retention Walls | F41: 30000 | G41: 46326 | H41: 46387 | I41: 10000 | J41: Existing | K41: High | L41: Construction | M41: 30000 | N41: 46326 | O41: 46387 | U41: BOVI
...

Sheet Summary (PROP x PROJ)
B2: Prop | C2: Portfolio | D2: Miscellaneous | E2: Utilities - Water | F2: Fencing | G2: Amenities | H2: Utilities - Sewer | I2: Signage | J2: Landscaping | K2: Permanent Structures | L2: Lighting | M2: Utilities - Electrical | N2: Paving & Roads | O2: Lot Preparation | P2: Drainage | Q2: Seawall | R2: POH | S2: TOTAL
B3: APPLE | C3: =VLOOKUP(B3,Data!B:C,2,FALSE) -> JREFI | D3: =SUMIFS(Data!$F:$F,Data!$B:$B,$B3,Data!$D:$D,D$2) -> 15000 | E3: =SUMIFS(Data!$F:$F,Data!$B:$B,$B3,Data!$D:$D,E$2) -> 0 | F3: =SUMIFS(Data!$F:$F,Data!$B:$B,$B3,Data!$D:$D,F$2) -> 0 | G3: =SUMIFS(Data!$F:$F,Data!$B:$B,$B3,Data!$D:$D,G$2) -> 40000 | H3: =SUMIFS(Data!$F:$F,Data!$B:$B,$B3,Data!$D:$D,H$2) -> 6000 | I3: =SUMIFS(Data!$F:$F,Data!$B:$B,$B3,Data!$D:$D,I$2) -> 7500 | J3: =SUMIFS(Data!$F:$F,Data!$B:$B,$B3,Data!$D:$D,J$2) -> 30000 | K3: =SUMIFS(Data!$F:$F,Data!$B:$B,$B3,Data!$D:$D,K$2) -> 0 | ... R3: =SUMIFS(Data!$F:$F,Data!$B:$B,$B3,Data!$D:$D,R$2) -> 0 | S3: =SUM(D3:R3) -> 98500
B4: BELL | C4: =VLOOKUP(B4,Data!B:C,2,FALSE) -> JREFI | D4: =SUMIFS(Data!$F:$F,Data!$B:$B,$B4,Data!$D:$D,D$2) -> 0 | E4: =SUMIFS(Data!$F:$F,Data!$B:$B,$B4,Data!$D:$D,E$2) -> 0 | F4: =SUMIFS(Data!$F:$F,Data!$B:$B,$B4,Data!$D:$D,F$2) -> 10000 | G4: =SUMIFS(Data!$F:$F,Data!$B:$B,$B4,Data!$D:$D,G$2) -> 25000 | H4: =SUMIFS(Data!$F:$F,Data!$B:$B,$B4,Data!$D:$D,H$2) -> 0 | I4: =SUMIFS(Data!$F:$F,Data!$B:$B,$B4,Data!$D:$D,I$2) -> 7500 | J4: =SUMIFS(Data!$F:$F,Data!$B:$B,$B4,Data!$D:$D,J$2) -> 5000 | K4: =SUMIFS(Data!$F:$F,Data!$B:$B,$B4,Data!$D:$D,K$2) -> 7500 | ... R4: =SUMIFS(Data!$F:$F,Data!$B:$B,$B4,Data!$D:$D,R$2) -> 0 | S4: =SUM(D4:R4) -> 55000
B5: CARL | C5: =VLOOKUP(B5,Data!B:C,2,FALSE) -> JREFI | D5: =SUMIFS(Data!$F:$F,Data!$B:$B,$B5,Data!$D:$D,D$2) -> 0 | E5: =SUMIFS(Data!$F:$F,Data!$B:$B,$B5,Data!$D:$D,E$2) -> 0 | F5: =SUMIFS(Data!$F:$F,Data!$B:$B,$B5,Data!$D:$D,F$2) -> 0 | G5: =SUMIFS(Data!$F:$F,Data!$B:$B,$B5,Data!$D:$D,G$2) -> 35000 | H5: =SUMIFS(Data!$F:$F,Data!$B:$B,$B5,Data!$D:$D,H$2) -> 72000 | I5: =SUMIFS(Data!$F:$F,Data!$B:$B,$B5,Data!$D:$D,I$2) -> 7500 | J5: =SUMIFS(Data!$F:$F,Data!$B:$B,$B5,Data!$D:$D,J$2) -> 30000 | K5: =SUMIFS(Data!$F:$F,Data!$B:$B,$B5,Data!$D:$D,K$2) -> 10000 | ... R5: =SUMIFS(Data!$F:$F,Data!$B:$B,$B5,Data!$D:$D,R$2) -> 0 | S5: =SUM(D5:R5) -> 154500
B6: CENT | C6: =VLOOKUP(B6,Data!B:C,2,FALSE) -> JREFI | D6: =SUMIFS(Data!$F:$F,Data!$B:$B,$B6,Data!$D:$D,D$2) -> 15000 | E6: =SUMIFS(Data!$F:$F,Data!$B:$B,$B6,Data!$D:$D,E$2) -> 0 | F6: =SUMIFS(Data!$F:$F,Data!$B:$B,$B6,Data!$D:$D,F$2) -> 10000 | G6: =SUMIFS(Data!$F:$F,Data!$B:$B,$B6,Data!$D:$D,G$2) -> 0 | H6: =SUMIFS(Data!$F:$F,Data!$B:$B,$B6,Data!$D:$D,H$2) -> 0 | I6: =SUMIFS(Data!$F:$F,Data!$B:$B,$B6,Data!$D:$D,I$2) -> 7500 | J6: =SUMIFS(Data!$F:$F,Data!$B:$B,$B6,Data!$D:$D,J$2) -> 0 | K6: =SUMIFS(Data!$F:$F,Data!$B:$B,$B6,Data!$D:$D,K$2) -> 0 | ... R6: =SUMIFS(Data!$F:$F,Data!$B:$B,$B6,Data!$D:$D,R$2) -> 0 | S6: =SUM(D6:R6) -> 67500
B7: CONG | C7: =VLOOKUP(B7,Data!B:C,2,FALSE) -> JREFI | D7: =SUMIFS(Data!$F:$F,Data!$B:$B,$B7,Data!$D:$D,D$2) -> 0 | E7: =SUMIFS(Data!$F:$F,Data!$B:$B,$B7,Data!$D:$D,E$2) -> 0 | F7: =SUMIFS(Data!$F:$F,Data!$B:$B,$B7,Data!$D:$D,F$2) -> 0 | G7: =SUMIFS(Data!$F:$F,Data!$B:$B,$B7,Data!$D:$D,G$2) -> 0 | H7: =SUMIFS(Data!$F:$F,Data!$B:$B,$B7,Data!$D:$D,H$2) -> 0 | I7: =SUMIFS(Data!$F:$F,Data!$B:$B,$B7,Data!$D:$D,I$2) -> 7500 | J7: =SUMIFS(Data!$F:$F,Data!$B:$B,$B7,Data!$D:$D,J$2) -> 0 | K7: =SUMIFS(Data!$F:$F,Data!$B:$B,$B7,Data!$D:$D,K$2) -> 0 | ... R7: =SUMIFS(Data!$F:$F,Data!$B:$B,$B7,Data!$D:$D,R$2) -> 0 | S7: =SUM(D7:R7) -> 37500
B8: HARB | C8: =VLOOKUP(B8,Data!B:C,2,FALSE) -> JREFI | D8: =SUMIFS(Data!$F:$F,Data!$B:$B,$B8,Data!$D:$D,D$2) -> 15000 | E8: =SUMIFS(Data!$F:$F,Data!$B:$B,$B8,Data!$D:$D,E$2) -> 0 | F8: =SUMIFS(Data!$F:$F,Data!$B:$B,$B8,Data!$D:$D,F$2) -> 10000 | G8: =SUMIFS(Data!$F:$F,Data!$B:$B,$B8,Data!$D:$D,G$2) -> 0 | H8: =SUMIFS(Data!$F:$F,Data!$B:$B,$B8,Data!$D:$D,H$2) -> 0 | I8: =SUMIFS(Data!$F:$F,Data!$B:$B,$B8,Data!$D:$D,I$2) -> 7500 | J8: =SUMIFS(Data!$F:$F,Data!$B:$B,$B8,Data!$D:$D,J$2) -> 0 | K8: =SUMIFS(Data!$F:$F,Data!$B:$B,$B8,Data!$D:$D,K$2) -> 0 | ... R8: =SUMIFS(Data!$F:$F,Data!$B:$B,$B8,Data!$D:$D,R$2) -> 0 | S8: =SUM(D8:R8) -> 47500
B9: JBJ | C9: =VLOOKUP(B9,Data!B:C,2,FALSE) -> JREFI | D9: =SUMIFS(Data!$F:$F,Data!$B:$B,$B9,Data!$D:$D,D$2) -> 0 | E9: =SUMIFS(Data!$F:$F,Data!$B:$B,$B9,Data!$D:$D,E$2) -> 0 | F9: =SUMIFS(Data!$F:$F,Data!$B:$B,$B9,Data!$D:$D,F$2) -> 0 | G9: =SUMIFS(Data!$F:$F,Data!$B:$B,$B9,Data!$D:$D,G$2) -> 15000 | H9: =SUMIFS(Data!$F:$F,Data!$B:$B,$B9,Data!$D:$D,H$2) -> 360000 | I9: =SUMIFS(Data!$F:$F,Data!$B:$B,$B9,Data!$D:$D,I$2) -> 0 | J9: =SUMIFS(Data!$F:$F,Data!$B:$B,$B9,Data!$D:$D,J$2) -> 15000 | K9: =SUMIFS(Data!$F:$F,Data!$B:$B,$B9,Data!$D:$D,K$2) -> 0 | ... R9: =SUMIFS(Data!$F:$F,Data!$B:$B,$B9,Data!$D:$D,R$2) -> 0 | S9: =SUM(D9:R9) -> 394000
B10: LS | C10: =VLOOKUP(B10,Data!B:C,2,FALSE) -> JREFI | D10: =SUMIFS(Data!$F:$F,Data!$B:$B,$B10,Data!$D:$D,D$2) -> 40000 | E10: =SUMIFS(Data!$F:$F,Data!$B:$B,$B10,Data!$D:$D,E$2) -> 0 | F10: =SUMIFS(Data!$F:$F,Data!$B:$B,$B10,Data!$D:$D,F$2) -> 0 | G10: =SUMIFS(Data!$F:$F,Data!$B:$B,$B10,Data!$D:$D,G$2) -> 8000 | H10: =SUMIFS(Data!$F:$F,Data!$B:$B,$B10,Data!$D:$D,H$2) -> 0 | I10: =SUMIFS(Data!$F:$F,Data!$B:$B,$B10,Data!$D:$D,I$2) -> 0 | J10: =SUMIFS(Data!$F:$F,Data!$B:$B,$B10,Data!$D:$D,J$2) -> 0 | K10: =SUMIFS(Data!$F:$F,Data!$B:$B,$B10,Data!$D:$D,K$2) -> 0 | ... R10: =SUMIFS(Data!$F:$F,Data!$B:$B,$B10,Data!$D:$D,R$2) -> 0 | S10: =SUM(D10:R10) -> 48000
B11: LUCK | C11: =VLOOKUP(B11,Data!B:C,2,FALSE) -> JREFI | D11: =SUMIFS(Data!$F:$F,Data!$B:$B,$B11,Data!$D:$D,D$2) -> 0 | E11: =SUMIFS(Data!$F:$F,Data!$B:$B,$B11,Data!$D:$D,E$2) -> 0 | F11: =SUMIFS(Data!$F:$F,Data!$B:$B,$B11,Data!$D:$D,F$2) -> 0 | G11: =SUMIFS(Data!$F:$F,Data!$B:$B,$B11,Data!$D:$D,G$2) -> 14000 | H11: =SUMIFS(Data!$F:$F,Data!$B:$B,$B11,Data!$D:$D,H$2) -> 0 | I11: =SUMIFS(Data!$F:$F,Data!$B:$B,$B11,Data!$D:$D,I$2) -> 0 | J11: =SUMIFS(Data!$F:$F,Data!$B:$B,$B11,Data!$D:$D,J$2) -> 25000 | K11: =SUMIFS(Data!$F:$F,Data!$B:$B,$B11,Data!$D:$D,K$2) -> 15000 | ... R11: =SUMIFS(Data!$F:$F,Data!$B:$B,$B11,Data!$D:$D,R$2) -> 0 | S11: =SUM(D11:R11) -> 84000
B12: PL | C12: =VLOOKUP(B12,Data!B:C,2,FALSE) -> JREFI | D12: =SUMIFS(Data!$F:$F,Data!$B:$B,$B12,Data!$D:$D,D$2) -> 115000 | E12: =SUMIFS(Data!$F:$F,Data!$B:$B,$B12,Data!$D:$D,E$2) -> 0 | F12: =SUMIFS(Data!$F:$F,Data!$B:$B,$B12,Data!$D:$D,F$2) -> 500 | G12: =SUMIFS(Data!$F:$F,Data!$B:$B,$B12,Data!$D:$D,G$2) -> 102000 | H12: =SUMIFS(Data!$F:$F,Data!$B:$B,$B12,Data!$D:$D,H$2) -> 200000 | I12: =SUMIFS(Data!$F:$F,Data!$B:$B,$B12,Data!$D:$D,I$2) -> 7500 | J12: =SUMIFS(Data!$F:$F,Data!$B:$B,$B12,Data!$D:$D,J$2) -> 0 | K12: =SUMIFS(Data!$F:$F,Data!$B:$B,$B12,Data!$D:$D,K$2) -> 0 | ... R12: =SUMIFS(Data!$F:$F,Data!$B:$B,$B12,Data!$D:$D,R$2) -> 0 | S12: =SUM(D12:R12) -> 2825000
B13: PPH | C13: =VLOOKUP(B13,Data!B:C,2,FALSE) -> JREFI | D13: =SUMIFS(Data!$F:$F,Data!$B:$B,$B13,Data!$D:$D,D$2) -> 0 | E13: =SUMIFS(Data!$F:$F,Data!$B:$B,$B13,Data!$D:$D,E$2) -> 0 | F13: =SUMIFS(Data!$F:$F,Data!$B:$B,$B13,Data!$D:$D,F$2) -> 0 | G13: =SUMIFS(Data!$F:$F,Data!$B:$B,$B13,Data!$D:$D,G$2) -> 75000 | H13: =SUMIFS(Data!$F:$F,Data!$B:$B,$B13,Data!$D:$D,H$2) -> 0 | I13: =SUMIFS(Data!$F:$F,Data!$B:$B,$B13,Data!$D:$D,I$2) -> 0 | J13: =SUMIFS(Data!$F:$F,Data!$B:$B,$B13,Data!$D:$D,J$2) -> 20000 | K13: =SUMIFS(Data!$F:$F,Data!$B:$B,$B13,Data!$D:$D,K$2) -> 0 | ... R13: =SUMIFS(Data!$F:$F,Data!$B:$B,$B13,Data!$D:$D,R$2) -> 0 | S13: =SUM(D13:R13) -> 95000
B14: RIV | C14: =VLOOKUP(B14,Data!B:C,2,FALSE) -> JREFI | D14: =SUMIFS(Data!$F:$F,Data!$B:$B,$B14,Data!$D:$D,D$2) -> 17000 | E14: =SUMIFS(Data!$F:$F,Data!$B:$B,$B14,Data!$D:$D,E$2) -> 0 | F14: =SUMIFS(Data!$F:$F,Data!$B:$B,$B14,Data!$D:$D,F$2) -> 40000 | G14: =SUMIFS(Data!$F:$F,Data!$B:$B,$B14,Data!$D:$D,G$2) -> 20000 | H14: =SUMIFS(Data!$F:$F,Data!$B:$B,$B14,Data!$D:$D,H$2) -> 0 | I14: =SUMIFS(Data!$F:$F,Data!$B:$B,$B14,Data!$D:$D,I$2) -> 0 | J14: =SUMIFS(Data!$F:$F,Data!$B:$B,$B14,Data!$D:$D,J$2) -> 0 | K14: =SUMIFS(Data!$F:$F,Data!$B:$B,$B14,Data!$D:$D,K$2) -> 0 | ... R14: =SUMIFS(Data!$F:$F,Data!$B:$B,$B14,Data!$D:$D,R$2) -> 0 | S14: =SUM(D14:R14) -> 78600
... B23: WPMH | C23: =VLOOKUP(B23,Data!B:C,2,FALSE) -> JREFI | D23: =SUMIFS(Data!$F:$F,Data!$B:$B,$B23,Data!$D:$D,D$2) -> 0 | E23: =SUMIFS(Data!$F:$F,Data!$B:$B,$B23,Data!$D:$D,E$2) -> 0 | F23: =SUMIFS(Data!$F:$F,Data!$B:$B,$B23,Data!$D:$D,F$2) -> 0 | G23: =SUMIFS(Data!$F:$F,Data!$B:$B,$B23,Data!$D:$D,G$2) -> 0 | H23: =SUMIFS(Data!$F:$F,Data!$B:$B,$B23,Data!$D:$D,H$2) -> 0 | I23: =SUMIFS(Data!$F:$F,Data!$B:$B,$B23,Data!$D:$D,I$2) -> 0 | J23: =SUMIFS(Data!$F:$F,Data!$B:$B,$B23,Data!$D:$D,J$2) -> 50000 | K23: =SUMIFS(Data!$F:$F,Data!$B:$B,$B23,Data!$D:$D,K$2) -> 0 | ... R23: =SUMIFS(Data!$F:$F,Data!$B:$B,$B23,Data!$D:$D,R$2) -> 0 | S23: =SUM(D23:R23) -> 215000
B24: TOTAL | D24: =SUM(D3:D23) -> 289000 | E24: =SUM(E3:E23) -> 150000 | F24: =SUM(F3:F23) -> 95500 | G24: =SUM(G3:G23) -> 790000 | H24: =SUM(H3:H23) -> 1138000 | I24: =SUM(I3:I23) -> 90000 | J24: =SUM(J3:J23) -> 335000 | K24: =SUM(K3:K23) -> 32500 | ... R24: =SUM(R3:R23) -> 0 | S24: =SUM(D24:R24) -> 6747600
B26: Prop | C26: Portfolio | D26: Miscellaneous | E26: Utilities - Water | F26: Fencing | G26: Amenities | H26: Utilities - Sewer | I26: Signage | J26: Landscaping | K26: Permanent Structures | L26: Lighting | M26: Utilities - Electrical | N26: Paving & Roads | O26: Lot Preparation | P26: Drainage | Q26: Seawall | R26: POH | S26: TOTAL
B27: ARD | C27: =VLOOKUP(B27,Data!B:C,2,FALSE) -> JREFII | D27: =SUMIFS(Data!$F:$F,Data!$B:$B,$B27,Data!$D:$D,D$2) -> 3000 | E27: =SUMIFS(Data!$F:$F,Data!$B:$B,$B27,Data!$D:$D,E$2) -> 0 | F27: =SUMIFS(Data!$F:$F,Data!$B:$B,$B27,Data!$D:$D,F$2) -> 0 | G27: =SUMIFS(Data!$F:$F,Data!$B:$B,$B27,Data!$D:$D,G$2) -> 50000 | H27: =SUMIFS(Data!$F:$F,Data!$B:$B,$B27,Data!$D:$D,H$2) -> 0 | I27: =SUMIFS(Data!$F:$F,Data!$B:$B,$B27,Data!$D:$D,I$2) -> 15000 | J27: =SUMIFS(Data!$F:$F,Data!$B:$B,$B27,Data!$D:$D,J$2) -> 0 | K27: =SUMIFS(Data!$F:$F,Data!$B:$B,$B27,Data!$D:$D,K$2) -> 150000 | ... R27: =SUMIFS(Data!$F:$F,Data!$B:$B,$B27,Data!$D:$D,R$2) -> 260000 | S27: =SUM(D27:R27) -> 478000
B28: BRUN | C28: =VLOOKUP(B28,Data!B:C,2,FALSE) -> JREFII | D28: =SUMIFS(Data!$F:$F,Data!$B:$B,$B28,Data!$D:$D,D$2) -> 12000 | E28: =SUMIFS(Data!$F:$F,Data!$B:$B,$B28,Data!$D:$D,E$2) -> 0 | F28: =SUMIFS(Data!$F:$F,Data!$B:$B,$B28,Data!$D:$D,F$2) -> 0 | G28: =SUMIFS(Data!$F:$F,Data!$B:$B,$B28,Data!$D:$D,G$2) -> 0 | H28: =SUMIFS(Data!$F:$F,Data!$B:$B,$B28,Data!$D:$D,H$2) -> 0 | I28: =SUMIFS(Data!$F:$F,Data!$B:$B,$B28,Data!$D:$D,I$2) -> 0 | J28: =SUMIFS(Data!$F:$F,Data!$B:$B,$B28,Data!$D:$D,J$2) -> 0 | K28: =SUMIFS(Data!$F:$F,Data!$B:$B,$B28,Data!$D:$D,K$2) -> 0 | ... R28: =SUMIFS(Data!$F:$F,Data!$B:$B,$B28,Data!$D:$D,R$2) -> 0 | S28: =SUM(D28:R28) -> 12000
B29: DO | C29: =VLOOKUP(B29,Data!B:C,2,FALSE) -> JREFII | D29: =SUMIFS(Data!$F:$F,Data!$B:$B,$B29,Data!$D:$D,D$2) -> 10000 | E29: =SUMIFS(Data!$F:$F,Data!$B:$B,$B29,Data!$D:$D,E$2) -> 50000 | F29: =SUMIFS(Data!$F:$F,Data!$B:$B,$B29,Data!$D:$D,F$2) -> 0 | G29: =SUMIFS(Data!$F:$F,Data!$B:$B,$B29,Data!$D:$D,G$2) -> 0 | H29: =SUMIFS(Data!$F:$F,Data!$B:$B,$B29,Data!$D:$D,H$2) -> 1300000 | I29: =SUMIFS(Data!$F:$F,Data!$B:$B,$B29,Data!$D:$D,I$2) -> 0 | J29: =SUMIFS(Data!$F:$F,Data!$B:$B,$B29,Data!$D:$D,J$2) -> 0 | K29: =SUMIFS(Data!$F:$F,Data!$B:$B,$B29,Data!$D:$D,K$2) -> 0 | ... R29: =SUMIFS(Data!$F:$F,Data!$B:$B,$B29,Data!$D:$D,R$2) -> 0 | S29: =SUM(D29:R29) -> 1360000
B30: FOX | C30: =VLOOKUP(B30,Data!B:C,2,FALSE) -> JREFII | D30: =SUMIFS(Data!$F:$F,Data!$B:$B,$B30,Data!$D:$D,D$2) -> 0 | E30: =SUMIFS(Data!$F:$F,Data!$B:$B,$B30,Data!$D:$D,E$2) -> 0 | F30: =SUMIFS(Data!$F:$F,Data!$B:$B,$B30,Data!$D:$D,F$2) -> 0 | G30: =SUMIFS(Data!$F:$F,Data!$B:$B,$B30,Data!$D:$D,G$2) -> 0 | H30: =SUMIFS(Data!$F:$F,Data!$B:$B,$B30,Data!$D:$D,H$2) -> 0 | I30: =SUMIFS(Data!$F:$F,Data!$B:$B,$B30,Data!$D:$D,I$2) -> 0 | J30: =SUMIFS(Data!$F:$F,Data!$B:$B,$B30,Data!$D:$D,J$2) -> 75000 | K30: =SUMIFS(Data!$F:$F,Data!$B:$B,$B30,Data!$D:$D,K$2) -> 0 | ... R30: =SUMIFS(Data!$F:$F,Data!$B:$B,$B30,Data!$D:$D,R$2) -> 0 | S30: =SUM(D30:R30) -> 75000
B31: GO | C31: =VLOOKUP(B31,Data!B:C,2,FALSE) -> JREFII | D31: =SUMIFS(Data!$F:$F,Data!$B:$B,$B31,Data!$D:$D,D$2) -> 0 | E31: =SUMIFS(Data!$F:$F,Data!$B:$B,$B31,Data!$D:$D,E$2) -> 0 | F31: =SUMIFS(Data!$F:$F,Data!$B:$B,$B31,Data!$D:$D,F$2) -> 0 | G31: =SUMIFS(Data!$F:$F,Data!$B:$B,$B31,Data!$D:$D,G$2) -> 34000 | H31: =SUMIFS(Data!$F:$F,Data!$B:$B,$B31,Data!$D:$D,H$2) -> 9000 | I31: =SUMIFS(Data!$F:$F,Data!$B:$B,$B31,Data!$D:$D,I$2) -> 7500 | J31: =SUMIFS(Data!$F:$F,Data!$B:$B,$B31,Data!$D:$D,J$2) -> 25000 | K31: =SUMIFS(Data!$F:$F,Data!$B:$B,$B31,Data!$D:$D,K$2) -> 0 | ... R31: =SUMIFS(Data!$F:$F,Data!$B:$B,$B31,Data!$D:$D,R$2) -> 0 | S31: =SUM(D31:R31) -> 90500
B32: GPT | C32: =VLOOKUP(B32,Data!B:C,2,FALSE) -> JREFII | D32: =SUMIFS(Data!$F:$F,Data!$B:$B,$B32,Data!$D:$D,D$2) -> 10000 | E32: =SUMIFS(Data!$F:$F,Data!$B:$B,$B32,Data!$D:$D,E$2) -> 0 | F32: =SUMIFS(Data!$F:$F,Data!$B:$B,$B32,Data!$D:$D,F$2) -> 0 | G32: =SUMIFS(Data!$F:$F,Data!$B:$B,$B32,Data!$D:$D,G$2) -> 40000 | H32: =SUMIFS(Data!$F:$F,Data!$B:$B,$B32,Data!$D:$D,H$2) -> 0 | I32: =SUMIFS(Data!$F:$F,Data!$B:$B,$B32,Data!$D:$D,I$2) -> 0 | J32: =SUMIFS(Data!$F:$F,Data!$B:$B,$B32,Data!$D:$D,J$2) -> 20000 | K32: =SUMIFS(Data!$F:$F,Data!$B:$B,$B32,Data!$D:$D,K$2) -> 0 | ... R32: =SUMIFS(Data!$F:$F,Data!$B:$B,$B32,Data!$D:$D,R$2) -> 0 | S32: =SUM(D32:R32) -> 70000
B33: HP | C33: =VLOOKUP(B33,Data!B:C,2,FALSE) -> JREFII | D33: =SUMIFS(Data!$F:$F,Data!$B:$B,$B33,Data!$D:$D,D$2) -> 20000 | E33: =SUMIFS(Data!$F:$F,Data!$B:$B,$B33,Data!$D:$D,E$2) -> 0 | F33: =SUMIFS(Data!$F:$F,Data!$B:$B,$B33,Data!$D:$D,F$2) -> 0 | G33: =SUMIFS(Data!$F:$F,Data!$B:$B,$B33,Data!$D:$D,G$2) -> 0 | H33: =SUMIFS(Data!$F:$F,Data!$B:$B,$B33,Data!$D:$D,H$2) -> 0 | I33: =SUMIFS(Data!$F:$F,Data!$B:$B,$B33,Data!$D:$D,I$2) -> 7500 | J33: =SUMIFS(Data!$F:$F,Data!$B:$B,$B33,Data!$D:$D,J$2) -> 30000 | K33: =SUMIFS(Data!$F:$F,Data!$B:$B,$B33,Data!$D:$D,K$2) -> 0 | ... R33: =SUMIFS(Data!$F:$F,Data!$B:$B,$B33,Data!$D:$D,R$2) -> 0 | S33: =SUM(D33:R33) -> 57500
B34: NGMH | C34: =VLOOKUP(B34,Data!B:C,2,FALSE) -> JREFII | D34: =SUMIFS(Data!$F:$F,Data!$B:$B,$B34,Data!$D:$D,D$2) -> 30000 | E34: =SUMIFS(Data!$F:$F,Data!$B:$B,$B34,Data!$D:$D,E$2) -> 60000 | F34: =SUMIFS(Data!$F:$F,Data!$B:$B,$B34,Data!$D:$D,F$2) -> 0 | G34: =SUMIFS(Data!$F:$F,Data!$B:$B,$B34,Data!$D:$D,G$2) -> 8000 | H34: =SUMIFS(Data!$F:$F,Data!$B:$B,$B34,Data!$D:$D,H$2) -> 477000 | I34: =SUMIFS(Data!$F:$F,Data!$B:$B,$B34,Data!$D:$D,I$2) -> 0 | J34: =SUMIFS(Data!$F:$F,Data!$B:$B,$B34,Data!$D:$D,J$2) -> 20000 | K34: =SUMIFS(Data!$F:$F,Data!$B:$B,$B34,Data!$D:$D,K$2) -> 0 | ... R34: =SUMIFS(Data!$F:$F,Data!$B:$B,$B34,Data!$D:$D,R$2) -> 0 | S34: =SUM(D34:R34) -> 595000
B35: OAK | C35: =VLOOKUP(B35,Data!B:C,2,FALSE) -> JREFII | D35: =SUMIFS(Data!$F:$F,Data!$B:$B,$B35,Data!$D:$D,D$2) -> 0 | E35: =SUMIFS(Data!$F:$F,Data!$B:$B,$B35,Data!$D:$D,E$2) -> 0 | F35: =SUMIFS(Data!$F:$F,Data!$B:$B,$B35,Data!$D:$D,F$2) -> 0 | G35: =SUMIFS(Data!$F:$F,Data!$B:$B,$B35,Data!$D:$D,G$2) -> 8000 | H35: =SUMIFS(Data!$F:$F,Data!$B:$B,$B35,Data!$D:$D,H$2) -> 0 | I35: =SUMIFS(Data!$F:$F,Data!$B:$B,$B35,Data!$D:$D,I$2) -> 8000 | J35: =SUMIFS(Data!$F:$F,Data!$B:$B,$B35,Data!$D:$D,J$2) -> 10000 | K35: =SUMIFS(Data!$F:$F,Data!$B:$B,$B35,Data!$D:$D,K$2) -> 0 | ... R35: =SUMIFS(Data!$F:$F,Data!$B:$B,$B35,Data!$D:$D,R$2) -> 0 | S35: =SUM(D35:R35) -> 26000
B36: PARK | C36: =VLOOKUP(B36,Data!B:C,2,FALSE) -> JREFII | D36: =SUMIFS(Data!$F:$F,Data!$B:$B,$B36,Data!$D:$D,D$2) -> 50000 | E36: =SUMIFS(Data!$F:$F,Data!$B:$B,$B36,Data!$D:$D,E$2) -> 0 | F36: =SUMIFS(Data!$F:$F,Data!$B:$B,$B36,Data!$D:$D,F$2) -> 0 | G36: =SUMIFS(Data!$F:$F,Data!$B:$B,$B36,Data!$D:$D,G$2) -> 0 | H36: =SUMIFS(Data!$F:$F,Data!$B:$B,$B36,Data!$D:$D,H$2) -> 0 | I36: =SUMIFS(Data!$F:$F,Data!$B:$B,$B36,Data!$D:$D,I$2) -> 8000 | J36: =SUMIFS(Data!$F:$F,Data!$B:$B,$B36,Data!$D:$D,J$2) -> 25000 | K36: =SUMIFS(Data!$F:$F,Data!$B:$B,$B36,Data!$D:$D,K$2) -> 0 | ... R36: =SUMIFS(Data!$F:$F,Data!$B:$B,$B36,Data!$D:$D,R$2) -> 0 | S36: =SUM(D36:R36) -> 83000
B37: PP | C37: =VLOOKUP(B37,Data!B:C,2,FALSE) -> JREFII | D37: =SUMIFS(Data!$F:$F,Data!$B:$B,$B37,Data!$D:$D,D$2) -> 10000 | E37: =SUMIFS(Data!$F:$F,Data!$B:$B,$B37,Data!$D:$D,E$2) -> 0 | F37: =SUMIFS(Data!$F:$F,Data!$B:$B,$B37,Data!$D:$D,F$2) -> 5000 | G37: =SUMIFS(Data!$F:$F,Data!$B:$B,$B37,Data!$D:$D,G$2) -> 15000 | H37: =SUMIFS(Data!$F:$F,Data!$B:$B,$B37,Data!$D:$D,H$2) -> 30000 | I37: =SUMIFS(Data!$F:$F,Data!$B:$B,$B37,Data!$D:$D,I$2) -> 15000 | J37: =SUMIFS(Data!$F:$F,Data!$B:$B,$B37,Data!$D:$D,J$2) -> 0 | K37: =SUMIFS(Data!$F:$F,Data!$B:$B,$B37,Data!$D:$D,K$2) -> 0 | ... R37: =SUMIFS(Data!$F:$F,Data!$B:$B,$B37,Data!$D:$D,R$2) -> 0 | S37: =SUM(D37:R37) -> 200000
B38: RED | C38: =VLOOKUP(B38,Data!B:C,2,FALSE) -> JREFII | D38: =SUMIFS(Data!$F:$F,Data!$B:$B,$B38,Data!$D:$D,D$2) -> 0 | E38: =SUMIFS(Data!$F:$F,Data!$B:$B,$B38,Data!$D:$D,E$2) -> 0 | F38: =SUMIFS(Data!$F:$F,Data!$B:$B,$B38,Data!$D:$D,F$2) -> 7000 | G38: =SUMIFS(Data!$F:$F,Data!$B:$B,$B38,Data!$D:$D,G$2) -> 26000 | H38: =SUMIFS(Data!$F:$F,Data!$B:$B,$B38,Data!$D:$D,H$2) -> 0 | I38: =SUMIFS(Data!$F:$F,Data!$B:$B,$B38,Data!$D:$D,I$2) -> 0 | J38: =SUMIFS(Data!$F:$F,Data!$B:$B,$B38,Data!$D:$D,J$2) -> 20000 | K38: =SUMIFS(Data!$F:$F,Data!$B:$B,$B38,Data!$D:$D,K$2) -> 0 | ... R38: =SUMIFS(Data!$F:$F,Data!$B:$B,$B38,Data!$D:$D,R$2) -> 0 | S38: =SUM(D38:R38) -> 53000
... B45: WIND | C45: =VLOOKUP(B45,Data!B:C,2,FALSE) -> JREFII | D45: =SUMIFS(Data!$F:$F,Data!$B:$B,$B45,Data!$D:$D,D$2) -> 0 | E45: =SUMIFS(Data!$F:$F,Data!$B:$B,$B45,Data!$D:$D,E$2) -> 0 | F45: =SUMIFS(Data!$F:$F,Data!$B:$B,$B45,Data!$D:$D,F$2) -> 0 | G45: =SUMIFS(Data!$F:$F,Data!$B:$B,$B45,Data!$D:$D,G$2) -> 8000 | H45: =SUMIFS(Data!$F:$F,Data!$B:$B,$B45,Data!$D:$D,H$2) -> 0 | I45: =SUMIFS(Data!$F:$F,Data!$B:$B,$B45,Data!$D:$D,I$2) -> 0 | J45: =SUMIFS(Data!$F:$F,Data!$B:$B,$B45,Data!$D:$D,J$2) -> 0 | K45: =SUMIFS(Data!$F:$F,Data!$B:$B,$B45,Data!$D:$D,K$2) -> 0 | ... R45: =SUMIFS(Data!$F:$F,Data!$B:$B,$B45,Data!$D:$D,R$2) -> 0 | S45: =SUM(D45:R45) -> 208000
B46: TOTAL | D46: =SUM(D27:D45) -> 182000 | E46: =SUM(E27:E45) -> 138000 | F46: =SUM(F27:F45) -> 107000 | G46: =SUM(G27:G45) -> 242000 | H46: =SUM(H27:H45) -> 1822500 | I46: =SUM(I27:I45) -> 94000 | J46: =SUM(J27:J45) -> 285000 | K46: =SUM(K27:K45) -> 150000 | ... S46: =SUM(S27:S45) -> 4072000
B48: Prop | C48: Portfolio | D48: Miscellaneous | E48: Utilities - Water | F48: Fencing | G48: Amenities | H48: Utilities - Sewer | I48: Signage | J48: Landscaping | K48: Permanent Structures | L48: Lighting | M48: Utilities - Electrical | N48: Paving & Roads | O48: Lot Preparation | P48: Drainage | Q48: Seawall | R48: POH | S48: TOTAL
B49: AMER | C49: =VLOOKUP(B49,Data!B:C,2,FALSE) -> Legacy | D49: =SUMIFS(Data!$F:$F,Data!$B:$B,$B49,Data!$D:$D,D$2) -> 200000 | E49: =SUMIFS(Data!$F:$F,Data!$B:$B,$B49,Data!$D:$D,E$2) -> 0 | F49: =SUMIFS(Data!$F:$F,Data!$B:$B,$B49,Data!$D:$D,F$2) -> 0 | G49: =SUMIFS(Data!$F:$F,Data!$B:$B,$B49,Data!$D:$D,G$2) -> 0 | H49: =SUMIFS(Data!$F:$F,Data!$B:$B,$B49,Data!$D:$D,H$2) -> 0 | I49: =SUMIFS(Data!$F:$F,Data!$B:$B,$B49,Data!$D:$D,I$2) -> 0 | J49: =SUMIFS(Data!$F:$F,Data!$B:$B,$B49,Data!$D:$D,J$2) -> 0 | K49: =SUMIFS(Data!$F:$F,Data!$B:$B,$B49,Data!$D:$D,K$2) -> 0 | ... R49: =SUMIFS(Data!$F:$F,Data!$B:$B,$B49,Data!$D:$D,R$2) -> 0 | S49: =SUM(D49:R49) -> 200000
B50: BOVI | C50: =VLOOKUP(B50,Data!B:C,2,FALSE) -> Legacy | D50: =SUMIFS(Data!$F:$F,Data!$B:$B,$B50,Data!$D:$D,D$2) -> 22000 | E50: =SUMIFS(Data!$F:$F,Data!$B:$B,$B50,Data!$D:$D,E$2) -> 0 | F50: =SUMIFS(Data!$F:$F,Data!$B:$B,$B50,Data!$D:$D,F$2) -> 10000 | G50: =SUMIFS(Data!$F:$F,Data!$B:$B,$B50,Data!$D:$D,G$2) -> 50000 | H50: =SUMIFS(Data!$F:$F,Data!$B:$B,$B50,Data!$D:$D,H$2) -> 0 | I50: =SUMIFS(Data!$F:$F,Data!$B:$B,$B50,Data!$D:$D,I$2) -> 7500 | J50: =SUMIFS(Data!$F:$F,Data!$B:$B,$B50,Data!$D:$D,J$2) -> 10000 | K50: =SUMIFS(Data!$F:$F,Data!$B:$B,$B50,Data!$D:$D,K$2) -> 0 | ... R50: =SUMIFS(Data!$F:$F,Data!$B:$B,$B50,Data!$D:$D,R$2) -> 0 | S50: =SUM(D50:R50) -> 99500
B51: BOVII | C51: =VLOOKUP(B51,Data!B:C,2,FALSE) -> Legacy | D51: =SUMIFS(Data!$F:$F,Data!$B:$B,$B51,Data!$D:$D,D$2) -> 0 | E51: =SUMIFS(Data!$F:$F,Data!$B:$B,$B51,Data!$D:$D,E$2) -> 0 | F51: =SUMIFS(Data!$F:$F,Data!$B:$B,$B51,Data!$D:$D,F$2) -> 10000 | G51: =SUMIFS(Data!$F:$F,Data!$B:$B,$B51,Data!$D:$D,G$2) -> 10000 | H51: =SUMIFS(Data!$F:$F,Data!$B:$B,$B51,Data!$D:$D,H$2) -> 0 | I51: =SUMIFS(Data!$F:$F,Data!$B:$B,$B51,Data!$D:$D,I$2) -> 7500 | J51: =SUMIFS(Data!$F:$F,Data!$B:$B,$B51,Data!$D:$D,J$2) -> 0 | K51: =SUMIFS(Data!$F:$F,Data!$B:$B,$B51,Data!$D:$D,K$2) -> 0 | ... R51: =SUMIFS(Data!$F:$F,Data!$B:$B,$B51,Data!$D:$D,R$2) -> 0 | S51: =SUM(D51:R51) -> 27500
B52: EG | C52: =VLOOKUP(B52,Data!B:C,2,FALSE) -> Legacy | D52: =SUMIFS(Data!$F:$F,Data!$B:$B,$B52,Data!$D:$D,D$2) -> 15000 | E52: =SUMIFS(Data!$F:$F,Data!$B:$B,$B52,Data!$D:$D,E$2) -> 0 | F52: =SUMIFS(Data!$F:$F,Data!$B:$B,$B52,Data!$D:$D,F$2) -> 0 | G52: =SUMIFS(Data!$F:$F,Data!$B:$B,$B52,Data!$D:$D,G$2) -> 0 | H52: =SUMIFS(Data!$F:$F,Data!$B:$B,$B52,Data!$D:$D,H$2) -> 0 | I52: =SUMIFS(Data!$F:$F,Data!$B:$B,$B52,Data!$D:$D,I$2) -> 7500 | J52: =SUMIFS(Data!$F:$F,Data!$B:$B,$B52,Data!$D:$D,J$2) -> 0 | K52: =SUMIFS(Data!$F:$F,Data!$B:$B,$B52,Data!$D:$D,K$2) -> 0 | ... R52: =SUMIFS(Data!$F:$F,Data!$B:$B,$B52,Data!$D:$D,R$2) -> 0 | S52: =SUM(D52:R52) -> 22500
B53: GULF | C53: =VLOOKUP(B53,Data!B:C,2,FALSE) -> Legacy | D53: =SUMIFS(Data!$F:$F,Data!$B:$B,$B53,Data!$D:$D,D$2) -> 0 | E53: =SUMIFS(Data!$F:$F,Data!$B:$B,$B53,Data!$D:$D,E$2) -> 0 | F53: =SUMIFS(Data!$F:$F,Data!$B:$B,$B53,Data!$D:$D,F$2) -> 0 | G53: =SUMIFS(Data!$F:$F,Data!$B:$B,$B53,Data!$D:$D,G$2) -> 0 | H53: =SUMIFS(Data!$F:$F,Data!$B:$B,$B53,Data!$D:$D,H$2) -> 0 | I53: =SUMIFS(Data!$F:$F,Data!$B:$B,$B53,Data!$D:$D,I$2) -> 0 | J53: =SUMIFS(Data!$F:$F,Data!$B:$B,$B53,Data!$D:$D,J$2) -> 20000 | K53: =SUMIFS(Data!$F:$F,Data!$B:$B,$B53,Data!$D:$D,K$2) -> 0 | ... R53: =SUMIFS(Data!$F:$F,Data!$B:$B,$B53,Data!$D:$D,R$2) -> 0 | S53: =SUM(D53:R53) -> 20000
B54: LW | C54: =VLOOKUP(B54,Data!B:C,2,FALSE) -> Legacy | D54: =SUMIFS(Data!$F:$F,Data!$B:$B,$B54,Data!$D:$D,D$2) -> 8000 | E54: =SUMIFS(Data!$F:$F,Data!$B:$B,$B54,Data!$D:$D,E$2) -> 0 | F54: =SUMIFS(Data!$F:$F,Data!$B:$B,$B54,Data!$D:$D,F$2) -> 0 | G54: =SUMIFS(Data!$F:$F,Data!$B:$B,$B54,Data!$D:$D,G$2) -> 10000 | H54: =SUMIFS(Data!$F:$F,Data!$B:$B,$B54,Data!$D:$D,H$2) -> 50000 | I54: =SUMIFS(Data!$F:$F,Data!$B:$B,$B54,Data!$D:$D,I$2) -> 7500 | J54: =SUMIFS(Data!$F:$F,Data!$B:$B,$B54,Data!$D:$D,J$2) -> 0 | K54: =SUMIFS(Data!$F:$F,Data!$B:$B,$B54,Data!$D:$D,K$2) -> 0 | ... R54: =SUMIFS(Data!$F:$F,Data!$B:$B,$B54,Data!$D:$D,R$2) -> 0 | S54: =SUM(D54:R54) -> 80500
B55: MON | C55: =VLOOKUP(B55,Data!B:C,2,FALSE) -> Legacy | D55: =SUMIFS(Data!$F:$F,Data!$B:$B,$B55,Data!$D:$D,D$2) -> 0 | E55: =SUMIFS(Data!$F:$F,Data!$B:$B,$B55,Data!$D:$D,E$2) -> 0 | F55: =SUMIFS(Data!$F:$F,Data!$B:$B,$B55,Data!$D:$D,F$2) -> 0 | G55: =SUMIFS(Data!$F:$F,Data!$B:$B,$B55,Data!$D:$D,G$2) -> 0 | H55: =SUMIFS(Data!$F:$F,Data!$B:$B,$B55,Data!$D:$D,H$2) -> 0 | I55: =SUMIFS(Data!$F:$F,Data!$B:$B,$B55,Data!$D:$D,I$2) -> 0 | J55: =SUMIFS(Data!$F:$F,Data!$B:$B,$B55,Data!$D:$D,J$2) -> 0 | K55: =SUMIFS(Data!$F:$F,Data!$B:$B,$B55,Data!$D:$D,K$2) -> 0 | ... R55: =SUMIFS(Data!$F:$F,Data!$B:$B,$B55,Data!$D:$D,R$2) -> 0 | S55: =SUM(D55:R55) -> 30000
B56: OBO | C56: =VLOOKUP(B56,Data!B:C,2,FALSE) -> Legacy | D56: =SUMIFS(Data!$F:$F,Data!$B:$B,$B56,Data!$D:$D,D$2) -> 30000 | E56: =SUMIFS(Data!$F:$F,Data!$B:$B,$B56,Data!$D:$D,E$2) -> 0 | F56: =SUMIFS(Data!$F:$F,Data!$B:$B,$B56,Data!$D:$D,F$2) -> 0 | G56: =SUMIFS(Data!$F:$F,Data!$B:$B,$B56,Data!$D:$D,G$2) -> 6000 | H56: =SUMIFS(Data!$F:$F,Data!$B:$B,$B56,Data!$D:$D,H$2) -> 0 | I56: =SUMIFS(Data!$F:$F,Data!$B:$B,$B56,Data!$D:$D,I$2) -> 1500 | J56: =SUMIFS(Data!$F:$F,Data!$B:$B,$B56,Data!$D:$D,J$2) -> 0 | K56: =SUMIFS(Data!$F:$F,Data!$B:$B,$B56,Data!$D:$D,K$2) -> 120000 | ... R56: =SUMIFS(Data!$F:$F,Data!$B:$B,$B56,Data!$D:$D,R$2) -> 0 | S56: =SUM(D56:R56) -> 172500
B57: OCEAN | C57: =VLOOKUP(B57,Data!B:C,2,FALSE) -> Legacy | D57: =SUMIFS(Data!$F:$F,Data!$B:$B,$B57,Data!$D:$D,D$2) -> 10000 | E57: =SUMIFS(Data!$F:$F,Data!$B:$B,$B57,Data!$D:$D,E$2) -> 0 | F57: =SUMIFS(Data!$F:$F,Data!$B:$B,$B57,Data!$D:$D,F$2) -> 0 | G57: =SUMIFS(Data!$F:$F,Data!$B:$B,$B57,Data!$D:$D,G$2) -> 0 | H57: =SUMIFS(Data!$F:$F,Data!$B:$B,$B57,Data!$D:$D,H$2) -> 0 | I57: =SUMIFS(Data!$F:$F,Data!$B:$B,$B57,Data!$D:$D,I$2) -> 0 | J57: =SUMIFS(Data!$F:$F,Data!$B:$B,$B57,Data!$D:$D,J$2) -> 0 | K57: =SUMIFS(Data!$F:$F,Data!$B:$B,$B57,Data!$D:$D,K$2) -> 0 | ... R57: =SUMIFS(Data!$F:$F,Data!$B:$B,$B57,Data!$D:$D,R$2) -> 0 | S57: =SUM(D57:R57) -> 25000
...

Sheet Summary (PROP x DATE)
B2: Prop | C2: Portfolio | D2: 45961 | E2: =EOMONTH(D2,1) -> 45991 | F2: =EOMONTH(E2,1) -> 46022 | G2: =EOMONTH(F2,1) -> 46053 | H2: =EOMONTH(G2,1) -> 46081 | I2: =EOMONTH(H2,1) -> 46112 | J2: =EOMONTH(I2,1) -> 46142 | K2: =EOMONTH(J2,1) -> 46173 | L2: =EOMONTH(K2,1) -> 46203 | ... BZ2: =EOMONTH(BY2,1) -> 48213 | CA2: TOTAL
B3: APPLE | C3: =VLOOKUP(B3,Data!B:C,2,FALSE) -> JREFI | D3: =SUMIFS(Data!$I:$I,Data!$B:$B,$B3,Data!$G:$G,"<="&D$2,Data!$H:$H,">="&D$2) -> 0 | E3: =SUMIFS(Data!$I:$I,Data!$B:$B,$B3,Data!$G:$G,"<="&E$2,Data!$H:$H,">="&E$2) -> 0 | F3: =SUMIFS(Data!$I:$I,Data!$B:$B,$B3,Data!$G:$G,"<="&F$2,Data!$H:$H,">="&F$2) -> 0 | G3: =SUMIFS(Data!$I:$I,Data!$B:$B,$B3,Data!$G:$G,"<="&G$2,Data!$H:$H,">="&G$2) -> 14500 | H3: =SUMIFS(Data!$I:$I,Data!$B:$B,$B3,Data!$G:$G,"<="&H$2,Data!$H:$H,">="&H$2) -> 14500 | I3: =SUMIFS(Data!$I:$I,Data!$B:$B,$B3,Data!$G:$G,"<="&I$2,Data!$H:$H,">="&I$2) -> 14500 | J3: =SUMIFS(Data!$I:$I,Data!$B:$B,$B3,Data!$G:$G,"<="&J$2,Data!$H:$H,">="&J$2) -> 5000 | K3: =SUMIFS(Data!$I:$I,Data!$B:$B,$B3,Data!$G:$G,"<="&K$2,Data!$H:$H,">="&K$2) -> 5000 | ... BZ3: =SUMIFS(Data!$I:$I,Data!$B:$B,$B3,Data!$G:$G,"<="&BZ$2,Data!$H:$H,">="&BZ$2) -> 0 | CA3: =SUM(D3:BZ3) -> 98500
B4: BELL | C4: =VLOOKUP(B4,Data!B:C,2,FALSE) -> JREFI | D4: =SUMIFS(Data!$I:$I,Data!$B:$B,$B4,Data!$G:$G,"<="&D$2,Data!$H:$H,">="&D$2) -> 0 | E4: =SUMIFS(Data!$I:$I,Data!$B:$B,$B4,Data!$G:$G,"<="&E$2,Data!$H:$H,">="&E$2) -> 0 | F4: =SUMIFS(Data!$I:$I,Data!$B:$B,$B4,Data!$G:$G,"<="&F$2,Data!$H:$H,">="&F$2) -> 0 | G4: =SUMIFS(Data!$I:$I,Data!$B:$B,$B4,Data!$G:$G,"<="&G$2,Data!$H:$H,">="&G$2) -> 1666.6667 | H4: =SUMIFS(Data!$I:$I,Data!$B:$B,$B4,Data!$G:$G,"<="&H$2,Data!$H:$H,">="&H$2) -> 1666.6667 | I4: =SUMIFS(Data!$I:$I,Data!$B:$B,$B4,Data!$G:$G,"<="&I$2,Data!$H:$H,">="&I$2) -> 10000 | J4: =SUMIFS(Data!$I:$I,Data!$B:$B,$B4,Data!$G:$G,"<="&J$2,Data!$H:$H,">="&J$2) -> 8333.3333 | K4: =SUMIFS(Data!$I:$I,Data!$B:$B,$B4,Data!$G:$G,"<="&K$2,Data!$H:$H,">="&K$2) -> 8333.3333 | ... BZ4: =SUMIFS(Data!$I:$I,Data!$B:$B,$B4,Data!$G:$G,"<="&BZ$2,Data!$H:$H,">="&BZ$2) -> 0 | CA4: =SUM(D4:BZ4) -> 55113.636
B5: CARL | C5: =VLOOKUP(B5,Data!B:C,2,FALSE) -> JREFI | D5: =SUMIFS(Data!$I:$I,Data!$B:$B,$B5,Data!$G:$G,"<="&D$2,Data!$H:$H,">="&D$2) -> 0 | E5: =SUMIFS(Data!$I:$I,Data!$B:$B,$B5,Data!$G:$G,"<="&E$2,Data!$H:$H,">="&E$2) -> 0 | F5: =SUMIFS(Data!$I:$I,Data!$B:$B,$B5,Data!$G:$G,"<="&F$2,Data!$H:$H,">="&F$2) -> 0 | G5: =SUMIFS(Data!$I:$I,Data!$B:$B,$B5,Data!$G:$G,"<="&G$2,Data!$H:$H,">="&G$2) -> 16833.333 | H5: =SUMIFS(Data!$I:$I,Data!$B:$B,$B5,Data!$G:$G,"<="&H$2,Data!$H:$H,">="&H$2) -> 16833.333 | I5: =SUMIFS(Data!$I:$I,Data!$B:$B,$B5,Data!$G:$G,"<="&I$2,Data!$H:$H,">="&I$2) -> 16833.333 | J5: =SUMIFS(Data!$I:$I,Data!$B:$B,$B5,Data!$G:$G,"<="&J$2,Data!$H:$H,">="&J$2) -> 12666.667 | K5: =SUMIFS(Data!$I:$I,Data!$B:$B,$B5,Data!$G:$G,"<="&K$2,Data!$H:$H,">="&K$2) -> 12666.667 | ... BZ5: =SUMIFS(Data!$I:$I,Data!$B:$B,$B5,Data!$G:$G,"<="&BZ$2,Data!$H:$H,">="&BZ$2) -> 1000 | CA5: =SUM(D5:BZ5) -> 154500
B6: CENT | C6: =VLOOKUP(B6,Data!B:C,2,FALSE) -> JREFI | D6: =SUMIFS(Data!$I:$I,Data!$B:$B,$B6,Data!$G:$G,"<="&D$2,Data!$H:$H,">="&D$2) -> 0 | E6: =SUMIFS(Data!$I:$I,Data!$B:$B,$B6,Data!$G:$G,"<="&E$2,Data!$H:$H,">="&E$2) -> 0 | F6: =SUMIFS(Data!$I:$I,Data!$B:$B,$B6,Data!$G:$G,"<="&F$2,Data!$H:$H,">="&F$2) -> 0 | G6: =SUMIFS(Data!$I:$I,Data!$B:$B,$B6,Data!$G:$G,"<="&G$2,Data!$H:$H,">="&G$2) -> 2500 | H6: =SUMIFS(Data!$I:$I,Data!$B:$B,$B6,Data!$G:$G,"<="&H$2,Data!$H:$H,">="&H$2) -> 2500 | I6: =SUMIFS(Data!$I:$I,Data!$B:$B,$B6,Data!$G:$G,"<="&I$2,Data!$H:$H,">="&I$2) -> 2500 | J6: =SUMIFS(Data!$I:$I,Data!$B:$B,$B6,Data!$G:$G,"<="&J$2,Data!$H:$H,">="&J$2) -> 6666.6667 | K6: =SUMIFS(Data!$I:$I,Data!$B:$B,$B6,Data!$G:$G,"<="&K$2,Data!$H:$H,">="&K$2) -> 6666.6667 | ... BZ6: =SUMIFS(Data!$I:$I,Data!$B:$B,$B6,Data!$G:$G,"<="&BZ$2,Data!$H:$H,">="&BZ$2) -> 0 | CA6: =SUM(D6:BZ6) -> 67500
B7: CONG | C7: =VLOOKUP(B7,Data!B:C,2,FALSE) -> JREFI | D7: =SUMIFS(Data!$I:$I,Data!$B:$B,$B7,Data!$G:$G,"<="&D$2,Data!$H:$H,">="&D$2) -> 0 | E7: =SUMIFS(Data!$I:$I,Data!$B:$B,$B7,Data!$G:$G,"<="&E$2,Data!$H:$H,">="&E$2) -> 0 | F7: =SUMIFS(Data!$I:$I,Data!$B:$B,$B7,Data!$G:$G,"<="&F$2,Data!$H:$H,">="&F$2) -> 0 | G7: =SUMIFS(Data!$I:$I,Data!$B:$B,$B7,Data!$G:$G,"<="&G$2,Data!$H:$H,">="&G$2) -> 1666.6667 | H7: =SUMIFS(Data!$I:$I,Data!$B:$B,$B7,Data!$G:$G,"<="&H$2,Data!$H:$H,">="&H$2) -> 1666.6667 | I7: =SUMIFS(Data!$I:$I,Data!$B:$B,$B7,Data!$G:$G,"<="&I$2,Data!$H:$H,">="&I$2) -> 1666.6667 | J7: =SUMIFS(Data!$I:$I,Data!$B:$B,$B7,Data!$G:$G,"<="&J$2,Data!$H:$H,">="&J$2) -> 2500 | K7: =SUMIFS(Data!$I:$I,Data!$B:$B,$B7,Data!$G:$G,"<="&K$2,Data!$H:$H,">="&K$2) -> 2500 | ... BZ7: =SUMIFS(Data!$I:$I,Data!$B:$B,$B7,Data!$G:$G,"<="&BZ$2,Data!$H:$H,">="&BZ$2) -> 0 | CA7: =SUM(D7:BZ7) -> 37500
B8: HARB | C8: =VLOOKUP(B8,Data!B:C,2,FALSE) -> JREFI | D8: =SUMIFS(Data!$I:$I,Data!$B:$B,$B8,Data!$G:$G,"<="&D$2,Data!$H:$H,">="&D$2) -> 0 | E8: =SUMIFS(Data!$I:$I,Data!$B:$B,$B8,Data!$G:$G,"<="&E$2,Data!$H:$H,">="&E$2) -> 0 | F8: =SUMIFS(Data!$I:$I,Data!$B:$B,$B8,Data!$G:$G,"<="&F$2,Data!$H:$H,">="&F$2) -> 0 | G8: =SUMIFS(Data!$I:$I,Data!$B:$B,$B8,Data!$G:$G,"<="&G$2,Data!$H:$H,">="&G$2) -> 0 | H8: =SUMIFS(Data!$I:$I,Data!$B:$B,$B8,Data!$G:$G,"<="&H$2,Data!$H:$H,">="&H$2) -> 0 | I8: =SUMIFS(Data!$I:$I,Data!$B:$B,$B8,Data!$G:$G,"<="&I$2,Data!$H:$H,">="&I$2) -> 0 | J8: =SUMIFS(Data!$I:$I,Data!$B:$B,$B8,Data!$G:$G,"<="&J$2,Data!$H:$H,">="&J$2) -> 0 | K8: =SUMIFS(Data!$I:$I,Data!$B:$B,$B8,Data!$G:$G,"<="&K$2,Data!$H:$H,">="&K$2) -> 0 | ... BZ8: =SUMIFS(Data!$I:$I,Data!$B:$B,$B8,Data!$G:$G,"<="&BZ$2,Data!$H:$H,">="&BZ$2) -> 0 | CA8: =SUM(D8:BZ8) -> 47500
B9: JBJ | C9: =VLOOKUP(B9,Data!B:C,2,FALSE) -> JREFI | D9: =SUMIFS(Data!$I:$I,Data!$B:$B,$B9,Data!$G:$G,"<="&D$2,Data!$H:$H,">="&D$2) -> 0 | E9: =SUMIFS(Data!$I:$I,Data!$B:$B,$B9,Data!$G:$G,"<="&E$2,Data!$H:$H,">="&E$2) -> 0 | F9: =SUMIFS(Data!$I:$I,Data!$B:$B,$B9,Data!$G:$G,"<="&F$2,Data!$H:$H,">="&F$2) -> 0 | G9: =SUMIFS(Data!$I:$I,Data!$B:$B,$B9,Data!$G:$G,"<="&G$2,Data!$H:$H,">="&G$2) -> 10000 | H9: =SUMIFS(Data!$I:$I,Data!$B:$B,$B9,Data!$G:$G,"<="&H$2,Data!$H:$H,">="&H$2) -> 10000 | I9: =SUMIFS(Data!$I:$I,Data!$B:$B,$B9,Data!$G:$G,"<="&I$2,Data!$H:$H,">="&I$2) -> 10000 | J9: =SUMIFS(Data!$I:$I,Data!$B:$B,$B9,Data!$G:$G,"<="&J$2,Data!$H:$H,">="&J$2) -> 6333.3333 | K9: =SUMIFS(Data!$I:$I,Data!$B:$B,$B9,Data!$G:$G,"<="&K$2,Data!$H:$H,">="&K$2) -> 6333.3333 | ... BZ9: =SUMIFS(Data!$I:$I,Data!$B:$B,$B9,Data!$G:$G,"<="&BZ$2,Data!$H:$H,">="&BZ$2) -> 5000 | CA9: =SUM(D9:BZ9) -> 394000
B10: LS | C10: =VLOOKUP(B10,Data!B:C,2,FALSE) -> JREFI | D10: =SUMIFS(Data!$I:$I,Data!$B:$B,$B10,Data!$G:$G,"<="&D$2,Data!$H:$H,">="&D$2) -> 0 | E10: =SUMIFS(Data!$I:$I,Data!$B:$B,$B10,Data!$G:$G,"<="&E$2,Data!$H:$H,">="&E$2) -> 0 | F10: =SUMIFS(Data!$I:$I,Data!$B:$B,$B10,Data!$G:$G,"<="&F$2,Data!$H:$H,">="&F$2) -> 0 | G10: =SUMIFS(Data!$I:$I,Data!$B:$B,$B10,Data!$G:$G,"<="&G$2,Data!$H:$H,">="&G$2) -> 2666.6667 | H10: =SUMIFS(Data!$I:$I,Data!$B:$B,$B10,Data!$G:$G,"<="&H$2,Data!$H:$H,">="&H$2) -> 2666.6667 | I10: =SUMIFS(Data!$I:$I,Data!$B:$B,$B10,Data!$G:$G,"<="&I$2,Data!$H:$H,">="&I$2) -> 2666.6667 | J10: =SUMIFS(Data!$I:$I,Data!$B:$B,$B10,Data!$G:$G,"<="&J$2,Data!$H:$H,">="&J$2) -> 0 | K10: =SUMIFS(Data!$I:$I,Data!$B:$B,$B10,Data!$G:$G,"<="&K$2,Data!$H:$H,">="&K$2) -> 0 | ... BZ10: =SUMIFS(Data!$I:$I,Data!$B:$B,$B10,Data!$G:$G,"<="&BZ$2,Data!$H:$H,">="&BZ$2) -> 0 | CA10: =SUM(D10:BZ10) -> 48000
B11: LUCK | C11: =VLOOKUP(B11,Data!B:C,2,FALSE) -> JREFI | D11: =SUMIFS(Data!$I:$I,Data!$B:$B,$B11,Data!$G:$G,"<="&D$2,Data!$H:$H,">="&D$2) -> 0 | E11: =SUMIFS(Data!$I:$I,Data!$B:$B,$B11,Data!$G:$G,"<="&E$2,Data!$H:$H,">="&E$2) -> 0 | F11: =SUMIFS(Data!$I:$I,Data!$B:$B,$B11,Data!$G:$G,"<="&F$2,Data!$H:$H,">="&F$2) -> 0 | G11: =SUMIFS(Data!$I:$I,Data!$B:$B,$B11,Data!$G:$G,"<="&G$2,Data!$H:$H,">="&G$2) -> 13333.333 | H11: =SUMIFS(Data!$I:$I,Data!$B:$B,$B11,Data!$G:$G,"<="&H$2,Data!$H:$H,">="&H$2) -> 13333.333 | I11: =SUMIFS(Data!$I:$I,Data!$B:$B,$B11,Data!$G:$G,"<="&I$2,Data!$H:$H,">="&I$2) -> 13333.333 | J11: =SUMIFS(Data!$I:$I,Data!$B:$B,$B11,Data!$G:$G,"<="&J$2,Data!$H:$H,">="&J$2) -> 10000 | K11: =SUMIFS(Data!$I:$I,Data!$B:$B,$B11,Data!$G:$G,"<="&K$2,Data!$H:$H,">="&K$2) -> 10000 | ... BZ11: =SUMIFS(Data!$I:$I,Data!$B:$B,$B11,Data!$G:$G,"<="&BZ$2,Data!$H:$H,">="&BZ$2) -> 0 | CA11: =SUM(D11:BZ11) -> 84000
B12: PL | C12: =VLOOKUP(B12,Data!B:C,2,FALSE) -> JREFI | D12: =SUMIFS(Data!$I:$I,Data!$B:$B,$B12,Data!$G:$G,"<="&D$2,Data!$H:$H,">="&D$2) -> 0 | E12: =SUMIFS(Data!$I:$I,Data!$B:$B,$B12,Data!$G:$G,"<="&E$2,Data!$H:$H,">="&E$2) -> 0 | F12: =SUMIFS(Data!$I:$I,Data!$B:$B,$B12,Data!$G:$G,"<="&F$2,Data!$H:$H,">="&F$2) -> 0 | G12: =SUMIFS(Data!$I:$I,Data!$B:$B,$B12,Data!$G:$G,"<="&G$2,Data!$H:$H,">="&G$2) -> 246000 | H12: =SUMIFS(Data!$I:$I,Data!$B:$B,$B12,Data!$G:$G,"<="&H$2,Data!$H:$H,">="&H$2) -> 246000 | I12: =SUMIFS(Data!$I:$I,Data!$B:$B,$B12,Data!$G:$G,"<="&I$2,Data!$H:$H,">="&I$2) -> 246000 | J12: =SUMIFS(Data!$I:$I,Data!$B:$B,$B12,Data!$G:$G,"<="&J$2,Data!$H:$H,">="&J$2) -> 205000 | K12: =SUMIFS(Data!$I:$I,Data!$B:$B,$B12,Data!$G:$G,"<="&K$2,Data!$H:$H,">="&K$2) -> 205000 | ... BZ12: =SUMIFS(Data!$I:$I,Data!$B:$B,$B12,Data!$G:$G,"<="&BZ$2,Data!$H:$H,">="&BZ$2) -> 0 | CA12: =SUM(D12:BZ12) -> 2825000
B13: PPH | C13: =VLOOKUP(B13,Data!B:C,2,FALSE) -> JREFI | D13: =SUMIFS(Data!$I:$I,Data!$B:$B,$B13,Data!$G:$G,"<="&D$2,Data!$H:$H,">="&D$2) -> 0 | E13: =SUMIFS(Data!$I:$I,Data!$B:$B,$B13,Data!$G:$G,"<="&E$2,Data!$H:$H,">="&E$2) -> 0 | F13: =SUMIFS(Data!$I:$I,Data!$B:$B,$B13,Data!$G:$G,"<="&F$2,Data!$H:$H,">="&F$2) -> 0 | G13: =SUMIFS(Data!$I:$I,Data!$B:$B,$B13,Data!$G:$G,"<="&G$2,Data!$H:$H,">="&G$2) -> 6666.6667 | H13: =SUMIFS(Data!$I:$I,Data!$B:$B,$B13,Data!$G:$G,"<="&H$2,Data!$H:$H,">="&H$2) -> 6666.6667 | I13: =SUMIFS(Data!$I:$I,Data!$B:$B,$B13,Data!$G:$G,"<="&I$2,Data!$H:$H,">="&I$2) -> 6666.6667 | J13: =SUMIFS(Data!$I:$I,Data!$B:$B,$B13,Data!$G:$G,"<="&J$2,Data!$H:$H,">="&J$2) -> 3333.3333 | K13: =SUMIFS(Data!$I:$I,Data!$B:$B,$B13,Data!$G:$G,"<="&K$2,Data!$H:$H,">="&K$2) -> 3333.3333 | ... BZ13: =SUMIFS(Data!$I:$I,Data!$B:$B,$B13,Data!$G:$G,"<="&BZ$2,Data!$H:$H,">="&BZ$2) -> 0 | CA13: =SUM(D13:BZ13) -> 95000
B14: RIV | C14: =VLOOKUP(B14,Data!B:C,2,FALSE) -> JREFI | D14: =SUMIFS(Data!$I:$I,Data!$B:$B,$B14,Data!$G:$G,"<="&D$2,Data!$H:$H,">="&D$2) -> 0 | E14: =SUMIFS(Data!$I:$I,Data!$B:$B,$B14,Data!$G:$G,"<="&E$2,Data!$H:$H,">="&E$2) -> 0 | F14: =SUMIFS(Data!$I:$I,Data!$B:$B,$B14,Data!$G:$G,"<="&F$2,Data!$H:$H,">="&F$2) -> 0 | G14: =SUMIFS(Data!$I:$I,Data!$B:$B,$B14,Data!$G:$G,"<="&G$2,Data!$H:$H,">="&G$2) -> 1366.6667 | H14: =SUMIFS(Data!$I:$I,Data!$B:$B,$B14,Data!$G:$G,"<="&H$2,Data!$H:$H,">="&H$2) -> 1366.6667 | I14: =SUMIFS(Data!$I:$I,Data!$B:$B,$B14,Data!$G:$G,"<="&I$2,Data!$H:$H,">="&I$2) -> 1366.6667 | J14: =SUMIFS(Data!$I:$I,Data!$B:$B,$B14,Data!$G:$G,"<="&J$2,Data!$H:$H,">="&J$2) -> 6666.6667 | K14: =SUMIFS(Data!$I:$I,Data!$B:$B,$B14,Data!$G:$G,"<="&K$2,Data!$H:$H,">="&K$2) -> 6666.6667 | ... BZ14: =SUMIFS(Data!$I:$I,Data!$B:$B,$B14,Data!$G:$G,"<="&BZ$2,Data!$H:$H,">="&BZ$2) -> 0 | CA14: =SUM(D14:BZ14) -> 76100
... B23: WPMH | C23: =VLOOKUP(B23,Data!B:C,2,FALSE) -> JREFI | D23: =SUMIFS(Data!$I:$I,Data!$B:$B,$B23,Data!$G:$G,"<="&D$2,Data!$H:$H,">="&D$2) -> 0 | E23: =SUMIFS(Data!$I:$I,Data!$B:$B,$B23,Data!$G:$G,"<="&E$2,Data!$H:$H,">="&E$2) -> 0 | F23: =SUMIFS(Data!$I:$I,Data!$B:$B,$B23,Data!$G:$G,"<="&F$2,Data!$H:$H,">="&F$2) -> 0 | G23: =SUMIFS(Data!$I:$I,Data!$B:$B,$B23,Data!$G:$G,"<="&G$2,Data!$H:$H,">="&G$2) -> 21666.667 | H23: =SUMIFS(Data!$I:$I,Data!$B:$B,$B23,Data!$G:$G,"<="&H$2,Data!$H:$H,">="&H$2) -> 21666.667 | I23: =SUMIFS(Data!$I:$I,Data!$B:$B,$B23,Data!$G:$G,"<="&I$2,Data!$H:$H,">="&I$2) -> 21666.667 | J23: =SUMIFS(Data!$I:$I,Data!$B:$B,$B23,Data!$G:$G,"<="&J$2,Data!$H:$H,">="&J$2) -> 0 | K23: =SUMIFS(Data!$I:$I,Data!$B:$B,$B23,Data!$G:$G,"<="&K$2,Data!$H:$H,">="&K$2) -> 0 | ... BZ23: =SUMIFS(Data!$I:$I,Data!$B:$B,$B23,Data!$G:$G,"<="&BZ$2,Data!$H:$H,">="&BZ$2) -> 0 | CA23: =SUM(D23:BZ23) -> 215000
B24: TOTAL | D24: =SUM(D3:D23) -> 0 | E24: =SUM(E3:E23) -> 0 | F24: =SUM(F3:F23) -> 0 | G24: =SUM(G3:G23) -> 645200 | H24: =SUM(H3:H23) -> 645200 | I24: =SUM(I3:I23) -> 653533.33 | J24: =SUM(J3:J23) -> 515333.33 | K24: =SUM(K3:K23) -> 502833.33 | ... BZ24: =SUM(BZ3:BZ23) -> 6000 | CA24: =SUM(D24:BZ24) -> 6745213.6
B26: Prop | C26: Portfolio | D26: 45961 | E26: =EOMONTH(D26,1) -> 45991 | F26: =EOMONTH(E26,1) -> 46022 | G26: =EOMONTH(F26,1) -> 46053 | H26: =EOMONTH(G26,1) -> 46081 | I26: =EOMONTH(H26,1) -> 46112 | J26: =EOMONTH(I26,1) -> 46142 | K26: =EOMONTH(J26,1) -> 46173 | L26: =EOMONTH(K26,1) -> 46203 | ... BZ26: =EOMONTH(BY26,1) -> 48213 | CA26: TOTAL
B27: ARD | C27: =VLOOKUP(B27,Data!B:C,2,FALSE) -> JREFII | D27: =SUMIFS(Data!$I:$I,Data!$B:$B,$B27,Data!$G:$G,"<="&D$2,Data!$H:$H,">="&D$2) -> 0 | E27: =SUMIFS(Data!$I:$I,Data!$B:$B,$B27,Data!$G:$G,"<="&E$2,Data!$H:$H,">="&E$2) -> 0 | F27: =SUMIFS(Data!$I:$I,Data!$B:$B,$B27,Data!$G:$G,"<="&F$2,Data!$H:$H,">="&F$2) -> 0 | G27: =SUMIFS(Data!$I:$I,Data!$B:$B,$B27,Data!$G:$G,"<="&G$2,Data!$H:$H,">="&G$2) -> 22666.667 | H27: =SUMIFS(Data!$I:$I,Data!$B:$B,$B27,Data!$G:$G,"<="&H$2,Data!$H:$H,">="&H$2) -> 22666.667 | I27: =SUMIFS(Data!$I:$I,Data!$B:$B,$B27,Data!$G:$G,"<="&I$2,Data!$H:$H,">="&I$2) -> 22666.667 | J27: =SUMIFS(Data!$I:$I,Data!$B:$B,$B27,Data!$G:$G,"<="&J$2,Data!$H:$H,">="&J$2) -> 43333.333 | K27: =SUMIFS(Data!$I:$I,Data!$B:$B,$B27,Data!$G:$G,"<="&K$2,Data!$H:$H,">="&K$2) -> 56666.667 | ... BZ27: =SUMIFS(Data!$I:$I,Data!$B:$B,$B27,Data!$G:$G,"<="&BZ$2,Data!$H:$H,">="&BZ$2) -> 0 | CA27: =SUM(D27:BZ27) -> 478000
B28: BRUN | C28: =VLOOKUP(B28,Data!B:C,2,FALSE) -> JREFII | D28: =SUMIFS(Data!$I:$I,Data!$B:$B,$B28,Data!$G:$G,"<="&D$2,Data!$H:$H,">="&D$2) -> 0 | E28: =SUMIFS(Data!$I:$I,Data!$B:$B,$B28,Data!$G:$G,"<="&E$2,Data!$H:$H,">="&E$2) -> 0 | F28: =SUMIFS(Data!$I:$I,Data!$B:$B,$B28,Data!$G:$G,"<="&F$2,Data!$H:$H,">="&F$2) -> 0 | G28: =SUMIFS(Data!$I:$I,Data!$B:$B,$B28,Data!$G:$G,"<="&G$2,Data!$H:$H,">="&G$2) -> 4000 | H28: =SUMIFS(Data!$I:$I,Data!$B:$B,$B28,Data!$G:$G,"<="&H$2,Data!$H:$H,">="&H$2) -> 4000 | I28: =SUMIFS(Data!$I:$I,Data!$B:$B,$B28,Data!$G:$G,"<="&I$2,Data!$H:$H,">="&I$2) -> 4000 | J28: =SUMIFS(Data!$I:$I,Data!$B:$B,$B28,Data!$G:$G,"<="&J$2,Data!$H:$H,">="&J$2) -> 0 | K28: =SUMIFS(Data!$I:$I,Data!$B:$B,$B28,Data!$G:$G,"<="&K$2,Data!$H:$H,">="&K$2) -> 0 | ... BZ28: =SUMIFS(Data!$I:$I,Data!$B:$B,$B28,Data!$G:$G,"<="&BZ$2,Data!$H:$H,">="&BZ$2) -> 0 | CA28: =SUM(D28:BZ28) -> 12000
B29: DO | C29: =VLOOKUP(B29,Data!B:C,2,FALSE) -> JREFII | D29: =SUMIFS(Data!$I:$I,Data!$B:$B,$B29,Data!$G:$G,"<="&D$2,Data!$H:$H,">="&D$2) -> 0 | E29: =SUMIFS(Data!$I:$I,Data!$B:$B,$B29,Data!$G:$G,"<="&E$2,Data!$H:$H,">="&E$2) -> 0 | F29: =SUMIFS(Data!$I:$I,Data!$B:$B,$B29,Data!$G:$G,"<="&F$2,Data!$H:$H,">="&F$2) -> 0 | G29: =SUMIFS(Data!$I:$I,Data!$B:$B,$B29,Data!$G:$G,"<="&G$2,Data!$H:$H,">="&G$2) -> 3333.3333 | H29: =SUMIFS(Data!$I:$I,Data!$B:$B,$B29,Data!$G:$G,"<="&H$2,Data!$H:$H,">="&H$2) -> 3333.3333 | I29: =SUMIFS(Data!$I:$I,Data!$B:$B,$B29,Data!$G:$G,"<="&I$2,Data!$H:$H,">="&I$2) -> 3333.3333 | J29: =SUMIFS(Data!$I:$I,Data!$B:$B,$B29,Data!$G:$G,"<="&J$2,Data!$H:$H,">="&J$2) -> 0 | K29: =SUMIFS(Data!$I:$I,Data!$B:$B,$B29,Data!$G:$G,"<="&K$2,Data!$H:$H,">="&K$2) -> 0 | ... BZ29: =SUMIFS(Data!$I:$I,Data!$B:$B,$B29,Data!$G:$G,"<="&BZ$2,Data!$H:$H,">="&BZ$2) -> 0 | CA29: =SUM(D29:BZ29) -> 1360000
B30: FOX | C30: =VLOOKUP(B30,Data!B:C,2,FALSE) -> JREFII | D30: =SUMIFS(Data!$I:$I,Data!$B:$B,$B30,Data!$G:$G,"<="&D$2,Data!$H:$H,">="&D$2) -> 0 | E30: =SUMIFS(Data!$I:$I,Data!$B:$B,$B30,Data!$G:$G,"<="&E$2,Data!$H:$H,">="&E$2) -> 0 | F30: =SUMIFS(Data!$I:$I,Data!$B:$B,$B30,Data!$G:$G,"<="&F$2,Data!$H:$H,">="&F$2) -> 0 | G30: =SUMIFS(Data!$I:$I,Data!$B:$B,$B30,Data!$G:$G,"<="&G$2,Data!$H:$H,">="&G$2) -> 25000 | H30: =SUMIFS(Data!$I:$I,Data!$B:$B,$B30,Data!$G:$G,"<="&H$2,Data!$H:$H,">="&H$2) -> 25000 | I30: =SUMIFS(Data!$I:$I,Data!$B:$B,$B30,Data!$G:$G,"<="&I$2,Data!$H:$H,">="&I$2) -> 25000 | J30: =SUMIFS(Data!$I:$I,Data!$B:$B,$B30,Data!$G:$G,"<="&J$2,Data!$H:$H,">="&J$2) -> 0 | K30: =SUMIFS(Data!$I:$I,Data!$B:$B,$B30,Data!$G:$G,"<="&K$2,Data!$H:$H,">="&K$2) -> 0 | ... BZ30: =SUMIFS(Data!$I:$I,Data!$B:$B,$B30,Data!$G:$G,"<="&BZ$2,Data!$H:$H,">="&BZ$2) -> 0 | CA30: =SUM(D30:BZ30) -> 75000
B31: GO | C31: =VLOOKUP(B31,Data!B:C,2,FALSE) -> JREFII | D31: =SUMIFS(Data!$I:$I,Data!$B:$B,$B31,Data!$G:$G,"<="&D$2,Data!$H:$H,">="&D$2) -> 0 | E31: =SUMIFS(Data!$I:$I,Data!$B:$B,$B31,Data!$G:$G,"<="&E$2,Data!$H:$H,">="&E$2) -> 0 | F31: =SUMIFS(Data!$I:$I,Data!$B:$B,$B31,Data!$G:$G,"<="&F$2,Data!$H:$H,">="&F$2) -> 0 | G31: =SUMIFS(Data!$I:$I,Data!$B:$B,$B31,Data!$G:$G,"<="&G$2,Data!$H:$H,">="&G$2) -> 10166.667 | H31: =SUMIFS(Data!$I:$I,Data!$B:$B,$B31,Data!$G:$G,"<="&H$2,Data!$H:$H,">="&H$2) -> 10166.667 | I31: =SUMIFS(Data!$I:$I,Data!$B:$B,$B31,Data!$G:$G,"<="&I$2,Data!$H:$H,">="&I$2) -> 10166.667 | J31: =SUMIFS(Data!$I:$I,Data!$B:$B,$B31,Data!$G:$G,"<="&J$2,Data!$H:$H,">="&J$2) -> 20000 | K31: =SUMIFS(Data!$I:$I,Data!$B:$B,$B31,Data!$G:$G,"<="&K$2,Data!$H:$H,">="&K$2) -> 20000 | ... BZ31: =SUMIFS(Data!$I:$I,Data!$B:$B,$B31,Data!$G:$G,"<="&BZ$2,Data!$H:$H,">="&BZ$2) -> 0 | CA31: =SUM(D31:BZ31) -> 90500
B32: GPT | C32: =VLOOKUP(B32,Data!B:C,2,FALSE) -> JREFII | D32: =SUMIFS(Data!$I:$I,Data!$B:$B,$B32,Data!$G:$G,"<="&D$2,Data!$H:$H,">="&D$2) -> 0 | E32: =SUMIFS(Data!$I:$I,Data!$B:$B,$B32,Data!$G:$G,"<="&E$2,Data!$H:$H,">="&E$2) -> 0 | F32: =SUMIFS(Data!$I:$I,Data!$B:$B,$B32,Data!$G:$G,"<="&F$2,Data!$H:$H,">="&F$2) -> 0 | G32: =SUMIFS(Data!$I:$I,Data!$B:$B,$B32,Data!$G:$G,"<="&G$2,Data!$H:$H,">="&G$2) -> 6666.6667 | H32: =SUMIFS(Data!$I:$I,Data!$B:$B,$B32,Data!$G:$G,"<="&H$2,Data!$H:$H,">="&H$2) -> 6666.6667 | I32: =SUMIFS(Data!$I:$I,Data!$B:$B,$B32,Data!$G:$G,"<="&I$2,Data!$H:$H,">="&I$2) -> 6666.6667 | J32: =SUMIFS(Data!$I:$I,Data!$B:$B,$B32,Data!$G:$G,"<="&J$2,Data!$H:$H,">="&J$2) -> 3333.3333 | K32: =SUMIFS(Data!$I:$I,Data!$B:$B,$B32,Data!$G:$G,"<="&K$2,Data!$H:$H,">="&K$2) -> 3333.3333 | ... BZ32: =SUMIFS(Data!$I:$I,Data!$B:$B,$B32,Data!$G:$G,"<="&BZ$2,Data!$H:$H,">="&BZ$2) -> 0 | CA32: =SUM(D32:BZ32) -> 70000
B33: HP | C33: =VLOOKUP(B33,Data!B:C,2,FALSE) -> JREFII | D33: =SUMIFS(Data!$I:$I,Data!$B:$B,$B33,Data!$G:$G,"<="&D$2,Data!$H:$H,">="&D$2) -> 0 | E33: =SUMIFS(Data!$I:$I,Data!$B:$B,$B33,Data!$G:$G,"<="&E$2,Data!$H:$H,">="&E$2) -> 0 | F33: =SUMIFS(Data!$I:$I,Data!$B:$B,$B33,Data!$G:$G,"<="&F$2,Data!$H:$H,">="&F$2) -> 0 | G33: =SUMIFS(Data!$I:$I,Data!$B:$B,$B33,Data!$G:$G,"<="&G$2,Data!$H:$H,">="&G$2) -> 16666.667 | H33: =SUMIFS(Data!$I:$I,Data!$B:$B,$B33,Data!$G:$G,"<="&H$2,Data!$H:$H,">="&H$2) -> 16666.667 | I33: =SUMIFS(Data!$I:$I,Data!$B:$B,$B33,Data!$G:$G,"<="&I$2,Data!$H:$H,">="&I$2) -> 16666.667 | J33: =SUMIFS(Data!$I:$I,Data!$B:$B,$B33,Data!$G:$G,"<="&J$2,Data!$H:$H,">="&J$2) -> 2500 | K33: =SUMIFS(Data!$I:$I,Data!$B:$B,$B33,Data!$G:$G,"<="&K$2,Data!$H:$H,">="&K$2) -> 2500 | ... BZ33: =SUMIFS(Data!$I:$I,Data!$B:$B,$B33,Data!$G:$G,"<="&BZ$2,Data!$H:$H,">="&BZ$2) -> 0 | CA33: =SUM(D33:BZ33) -> 57500
B34: NGMH | C34: =VLOOKUP(B34,Data!B:C,2,FALSE) -> JREFII | D34: =SUMIFS(Data!$I:$I,Data!$B:$B,$B34,Data!$G:$G,"<="&D$2,Data!$H:$H,">="&D$2) -> 3333.3333 | E34: =SUMIFS(Data!$I:$I,Data!$B:$B,$B34,Data!$G:$G,"<="&E$2,Data!$H:$H,">="&E$2) -> 3333.3333 | F34: =SUMIFS(Data!$I:$I,Data!$B:$B,$B34,Data!$G:$G,"<="&F$2,Data!$H:$H,">="&F$2) -> 3333.3333 | G34: =SUMIFS(Data!$I:$I,Data!$B:$B,$B34,Data!$G:$G,"<="&G$2,Data!$H:$H,">="&G$2) -> 9333.3333 | H34: =SUMIFS(Data!$I:$I,Data!$B:$B,$B34,Data!$G:$G,"<="&H$2,Data!$H:$H,">="&H$2) -> 9333.3333 | I34: =SUMIFS(Data!$I:$I,Data!$B:$B,$B34,Data!$G:$G,"<="&I$2,Data!$H:$H,">="&I$2) -> 9333.3333 | J34: =SUMIFS(Data!$I:$I,Data!$B:$B,$B34,Data!$G:$G,"<="&J$2,Data!$H:$H,">="&J$2) -> 94809.524 | K34: =SUMIFS(Data!$I:$I,Data!$B:$B,$B34,Data!$G:$G,"<="&K$2,Data!$H:$H,">="&K$2) -> 94809.524 | ... BZ34: =SUMIFS(Data!$I:$I,Data!$B:$B,$B34,Data!$G:$G,"<="&BZ$2,Data!$H:$H,">="&BZ$2) -> 0 | CA34: =SUM(D34:BZ34) -> 595000
B35: OAK | C35: =VLOOKUP(B35,Data!B:C,2,FALSE) -> JREFII | D35: =SUMIFS(Data!$I:$I,Data!$B:$B,$B35,Data!$G:$G,"<="&D$2,Data!$H:$H,">="&D$2) -> 0 | E35: =SUMIFS(Data!$I:$I,Data!$B:$B,$B35,Data!$G:$G,"<="&E$2,Data!$H:$H,">="&E$2) -> 0 | F35: =SUMIFS(Data!$I:$I,Data!$B:$B,$B35,Data!$G:$G,"<="&F$2,Data!$H:$H,">="&F$2) -> 0 | G35: =SUMIFS(Data!$I:$I,Data!$B:$B,$B35,Data!$G:$G,"<="&G$2,Data!$H:$H,">="&G$2) -> 6000 | H35: =SUMIFS(Data!$I:$I,Data!$B:$B,$B35,Data!$G:$G,"<="&H$2,Data!$H:$H,">="&H$2) -> 6000 | I35: =SUMIFS(Data!$I:$I,Data!$B:$B,$B35,Data!$G:$G,"<="&I$2,Data!$H:$H,">="&I$2) -> 6000 | J35: =SUMIFS(Data!$I:$I,Data!$B:$B,$B35,Data!$G:$G,"<="&J$2,Data!$H:$H,">="&J$2) -> 0 | K35: =SUMIFS(Data!$I:$I,Data!$B:$B,$B35,Data!$G:$G,"<="&K$2,Data!$H:$H,">="&K$2) -> 0 | ... BZ35: =SUMIFS(Data!$I:$I,Data!$B:$B,$B35,Data!$G:$G,"<="&BZ$2,Data!$H:$H,">="&BZ$2) -> 0 | CA35: =SUM(D35:BZ35) -> 26000
B36: PARK | C36: =VLOOKUP(B36,Data!B:C,2,FALSE) -> JREFII | D36: =SUMIFS(Data!$I:$I,Data!$B:$B,$B36,Data!$G:$G,"<="&D$2,Data!$H:$H,">="&D$2) -> 0 | E36: =SUMIFS(Data!$I:$I,Data!$B:$B,$B36,Data!$G:$G,"<="&E$2,Data!$H:$H,">="&E$2) -> 0 | F36: =SUMIFS(Data!$I:$I,Data!$B:$B,$B36,Data!$G:$G,"<="&F$2,Data!$H:$H,">="&F$2) -> 0 | G36: =SUMIFS(Data!$I:$I,Data!$B:$B,$B36,Data!$G:$G,"<="&G$2,Data!$H:$H,">="&G$2) -> 11000 | H36: =SUMIFS(Data!$I:$I,Data!$B:$B,$B36,Data!$G:$G,"<="&H$2,Data!$H:$H,">="&H$2) -> 11000 | I36: =SUMIFS(Data!$I:$I,Data!$B:$B,$B36,Data!$G:$G,"<="&I$2,Data!$H:$H,">="&I$2) -> 11000 | J36: =SUMIFS(Data!$I:$I,Data!$B:$B,$B36,Data!$G:$G,"<="&J$2,Data!$H:$H,">="&J$2) -> 0 | K36: =SUMIFS(Data!$I:$I,Data!$B:$B,$B36,Data!$G:$G,"<="&K$2,Data!$H:$H,">="&K$2) -> 0 | ... BZ36: =SUMIFS(Data!$I:$I,Data!$B:$B,$B36,Data!$G:$G,"<="&BZ$2,Data!$H:$H,">="&BZ$2) -> 0 | CA36: =SUM(D36:BZ36) -> 83000
B37: PP | C37: =VLOOKUP(B37,Data!B:C,2,FALSE) -> JREFII | D37: =SUMIFS(Data!$I:$I,Data!$B:$B,$B37,Data!$G:$G,"<="&D$2,Data!$H:$H,">="&D$2) -> 0 | E37: =SUMIFS(Data!$I:$I,Data!$B:$B,$B37,Data!$G:$G,"<="&E$2,Data!$H:$H,">="&E$2) -> 0 | F37: =SUMIFS(Data!$I:$I,Data!$B:$B,$B37,Data!$G:$G,"<="&F$2,Data!$H:$H,">="&F$2) -> 0 | G37: =SUMIFS(Data!$I:$I,Data!$B:$B,$B37,Data!$G:$G,"<="&G$2,Data!$H:$H,">="&G$2) -> 0 | H37: =SUMIFS(Data!$I:$I,Data!$B:$B,$B37,Data!$G:$G,"<="&H$2,Data!$H:$H,">="&H$2) -> 0 | I37: =SUMIFS(Data!$I:$I,Data!$B:$B,$B37,Data!$G:$G,"<="&I$2,Data!$H:$H,">="&I$2) -> 0 | J37: =SUMIFS(Data!$I:$I,Data!$B:$B,$B37,Data!$G:$G,"<="&J$2,Data!$H:$H,">="&J$2) -> 5000 | K37: =SUMIFS(Data!$I:$I,Data!$B:$B,$B37,Data!$G:$G,"<="&K$2,Data!$H:$H,">="&K$2) -> 5000 | ... BZ37: =SUMIFS(Data!$I:$I,Data!$B:$B,$B37,Data!$G:$G,"<="&BZ$2,Data!$H:$H,">="&BZ$2) -> 0 | CA37: =SUM(D37:BZ37) -> 200000
