Workbook

Sheet ESG DDQ Appendix A
A2: Asset Characteristics | J2: Data | K2: Energy Usage | P2: Water Consumption | R2: Social | Z2: Governance
A3: Investment Vehicle | B3: Investment Name | C3: Country | D3: City | E3: Street Address | F3: Asset Class | G3: Sector / Property Type | H3: Building Status | I3: (Gross) Square Footage / Asset Size (1) | J3: Reporting Year | K3: Total Energy Consumption (kWh) | L3: % Floor Area Covered | M3: % Natural Gas and other fuels | N3: % Renewable Energy Used | O3: % Other (pls specify) | P3: Total Consumption (kGal) | Q3: Onsite water reuse (kGal) | R3: Diversity (% Women on Board) | S3: Diversity (% Women in C-suite) | T3: Work-related Accidents: Injuries | U3: Work-related Accidents: Days Lost | V3: New Hires: Total % | W3: New Hires: Turnover % | X3: Total: Turnover % | Y3: Employee Training (Type/Date) | Z3: Community Engagement (yes/no) | AA3: Community Engagement ($ spent) | AB3: Cyber Security Breaches (#) | AC3: HIPAA Violations (#) (specify if N/A)
A5: Fund 1 | B5: Parakeet | C5: United States | D5: Various | E5: Various | F5: Real Estate | G5: Manufactured Housing | H5: Standing Investment | I5: =SUM(I6:I29) -> 0 | R5: 0.4 | T5: N/A | U5: N/A | V5: 0.1463 | W5: 0 | X5: 0.242 | Y5: Fair Housing / Harassment Training
A6: APPLE | B6: Parakeet | C6: United States | D6: Deland | E6: 399 Circle Dr. | F6: Real Estate | G6: Manufactured Housing | H6: Standing Investment | J6: 1/1/2025 - 6/30/2025 | K6: =SUMIFS(Sheet1!$K:$K,Sheet1!$B:$B,'ESG DDQ Appendix A'!$A6,Sheet1!$A:$A,"Electric") -> 57015 | P6: =SUMIFS(Sheet1!$K:$K,Sheet1!$B:$B,'ESG DDQ Appendix A'!$A6,Sheet1!$A:$A,"Water")/1000 -> 0 | Z6: YES | AB6: NO | AC6: NO
A7: BELL | B7: Parakeet | C7: United States | D7: Clearwater | E7: 27554 US Hwy 19 N | F7: Real Estate | G7: Manufactured Housing | H7: Standing Investment | J7: 1/1/2025 - 6/30/2025 | K7: =SUMIFS(Sheet1!$K:$K,Sheet1!$B:$B,'ESG DDQ Appendix A'!$A7,Sheet1!$A:$A,"Electric") -> 46392 | P7: =SUMIFS(Sheet1!$K:$K,Sheet1!$B:$B,'ESG DDQ Appendix A'!$A7,Sheet1!$A:$A,"Water")/1000 -> 494 | Z7: YES | AB7: NO | AC7: NO
A8: CARL | B8: Parakeet | C8: United States | D8: Miami | E8: 4111 NW 37th Ave | F8: Real Estate | G8: Manufactured Housing | H8: Standing Investment | J8: 1/1/2025 - 6/30/2025 | K8: =SUMIFS(Sheet1!$K:$K,Sheet1!$B:$B,'ESG DDQ Appendix A'!$A8,Sheet1!$A:$A,"Electric") -> 4336 | P8: =SUMIFS(Sheet1!$K:$K,Sheet1!$B:$B,'ESG DDQ Appendix A'!$A8,Sheet1!$A:$A,"Water")/1000 -> 1478.2 | Z8: YES | AB8: NO | AC8: NO
A9: CENT | B9: Parakeet | C9: United States | D9: Cocoa | E9: 810 Peachtree Street | F9: Real Estate | G9: Manufactured Housing | H9: Standing Investment | J9: 1/1/2025 - 6/30/2025 | K9: =SUMIFS(Sheet1!$K:$K,Sheet1!$B:$B,'ESG DDQ Appendix A'!$A9,Sheet1!$A:$A,"Electric") -> 0 | P9: =SUMIFS(Sheet1!$K:$K,Sheet1!$B:$B,'ESG DDQ Appendix A'!$A9,Sheet1!$A:$A,"Water")/1000 -> 0 | Z9: YES | AB9: NO | AC9: NO
A10: CONG | B10: Parakeet | C10: United States | D10: West Palm Beach | E10: 1960 Congress Avenue | F10: Real Estate | G10: Manufactured Housing | H10: Standing Investment | J10: 1/1/2025 - 6/30/2025 | K10: =SUMIFS(Sheet1!$K:$K,Sheet1!$B:$B,'ESG DDQ Appendix A'!$A10,Sheet1!$A:$A,"Electric") -> 0 | P10: =SUMIFS(Sheet1!$K:$K,Sheet1!$B:$B,'ESG DDQ Appendix A'!$A10,Sheet1!$A:$A,"Water")/1000 -> 1225 | Z10: YES | AB10: NO | AC10: NO
A11: GEIGRV | B11: Parakeet | C11: United States | D11: Key West | E11: 5 Geiger Rd | F11: Real Estate | G11: Manufactured Housing | H11: Standing Investment | J11: 1/1/2025 - 6/30/2025 | K11: =SUMIFS(Sheet1!$K:$K,Sheet1!$B:$B,'ESG DDQ Appendix A'!$A11,Sheet1!$A:$A,"Electric") -> 0 | P11: =SUMIFS(Sheet1!$K:$K,Sheet1!$B:$B,'ESG DDQ Appendix A'!$A11,Sheet1!$A:$A,"Water")/1000 -> 0 | Z11: YES | AB11: NO | AC11: NO
A12: GKFC | B12: Parakeet | C12: United States | D12: Key West | E12: 5 Geiger Rd | F12: Real Estate | G12: Manufactured Housing | H12: Standing Investment | J12: 1/1/2025 - 6/30/2025 | K12: =SUMIFS(Sheet1!$K:$K,Sheet1!$B:$B,'ESG DDQ Appendix A'!$A12,Sheet1!$A:$A,"Electric") -> 0 | P12: =SUMIFS(Sheet1!$K:$K,Sheet1!$B:$B,'ESG DDQ Appendix A'!$A12,Sheet1!$A:$A,"Water")/1000 -> 0 | Z12: YES | AB12: NO | AC12: NO
A13: HARB | B13: Parakeet | C13: United States | D13: Cocoa | E13: 821 Peachtree Street | F13: Real Estate | G13: Manufactured Housing | H13: Standing Investment | J13: 1/1/2025 - 6/30/2025 | K13: =SUMIFS(Sheet1!$K:$K,Sheet1!$B:$B,'ESG DDQ Appendix A'!$A13,Sheet1!$A:$A,"Electric") -> 80 | P13: =SUMIFS(Sheet1!$K:$K,Sheet1!$B:$B,'ESG DDQ Appendix A'!$A13,Sheet1!$A:$A,"Water")/1000 -> 848 | Z13: YES | AB13: NO | AC13: NO
A14: HSRC | B14: Parakeet | C14: United States | D14: Crystal River | E14: 316 NE 2nd Street | F14: Real Estate | G14: Manufactured Housing | H14: Standing Investment | J14: 1/1/2025 - 6/30/2025 | K14: =SUMIFS(Sheet1!$K:$K,Sheet1!$B:$B,'ESG DDQ Appendix A'!$A14,Sheet1!$A:$A,"Electric") -> 129 | P14: =SUMIFS(Sheet1!$K:$K,Sheet1!$B:$B,'ESG DDQ Appendix A'!$A14,Sheet1!$A:$A,"Water")/1000 -> 0 | Z14: YES | AB14: NO | AC14: NO
A15: JBJ | B15: Parakeet | C15: United States | D15: Miami | E15: 2980 NW 79th St | F15: Real Estate | G15: Manufactured Housing | H15: Standing Investment | J15: 1/1/2025 - 6/30/2025 | K15: =SUMIFS(Sheet1!$K:$K,Sheet1!$B:$B,'ESG DDQ Appendix A'!$A15,Sheet1!$A:$A,"Electric") -> 29806 | P15: =SUMIFS(Sheet1!$K:$K,Sheet1!$B:$B,'ESG DDQ Appendix A'!$A15,Sheet1!$A:$A,"Water")/1000 -> 2213.332 | Z15: YES | AB15: NO | AC15: NO
A16: LS | B16: Parakeet | C16: United States | D16: Mt Dora | E16: 4301 County Road 19A | F16: Real Estate | G16: Manufactured Housing | H16: Standing Investment | J16: 1/1/2025 - 6/30/2025 | K16: =SUMIFS(Sheet1!$K:$K,Sheet1!$B:$B,'ESG DDQ Appendix A'!$A16,Sheet1!$A:$A,"Electric") -> 10434 | P16: =SUMIFS(Sheet1!$K:$K,Sheet1!$B:$B,'ESG DDQ Appendix A'!$A16,Sheet1!$A:$A,"Water")/1000 -> 530 | Z16: YES | AB16: NO | AC16: NO
A17: LUCK | B17: Parakeet | C17: United States | D17: Melbourne | E17: 635 E Eau Gallie Blvd. | F17: Real Estate | G17: Manufactured Housing | H17: Standing Investment | J17: 1/1/2025 - 6/30/2025 | K17: =SUMIFS(Sheet1!$K:$K,Sheet1!$B:$B,'ESG DDQ Appendix A'!$A17,Sheet1!$A:$A,"Electric") -> 305031 | P17: =SUMIFS(Sheet1!$K:$K,Sheet1!$B:$B,'ESG DDQ Appendix A'!$A17,Sheet1!$A:$A,"Water")/1000 -> 1149.1 | Z17: YES | AB17: NO | AC17: NO
... A29: WPMH | B29: Parakeet | C29: United States | D29: Titusville | E29: 359 Cheney Hwy | F29: Real Estate | G29: Manufactured Housing | H29: Standing Investment | J29: 1/1/2025 - 6/30/2025 | K29: =SUMIFS(Sheet1!$K:$K,Sheet1!$B:$B,'ESG DDQ Appendix A'!$A29,Sheet1!$A:$A,"Electric") -> 247968 | P29: =SUMIFS(Sheet1!$K:$K,Sheet1!$B:$B,'ESG DDQ Appendix A'!$A29,Sheet1!$A:$A,"Water")/1000 -> 158 | Z29: YES | AB29: NO | AC29: NO
A33: Fund 1 | B33: Parakeet | C33: United States | D33: Various | E33: Various | F33: Real Estate | G33: Manufactured Housing | H33: Standing Investment | I33: =SUM(I34:I57) -> 0 | R33: 0.4 | T33: N/A | U33: N/A | V33: 0.1463 | W33: 0 | X33: 0.242 | Y33: Fair Housing / Harassment Training
A34: ARD | B34: Parakeet | C34: United States | D34: Auburn | E34: 328 Carter Rd | F34: Real Estate | G34: Manufactured Housing | H34: Standing Investment
A35: BRUN | B35: Parakeet | C35: United States | D35: Brunswick | E35: 21 Gressel Circle | F35: Real Estate | G35: Manufactured Housing | H35: Standing Investment
A36: DO | B36: Parakeet | C36: United States | D36: Brunswick | E36: 4240 US Hwy 17N | F36: Real Estate | G36: Manufactured Housing | H36: Standing Investment
A37: FOX | B37: Parakeet | C37: United States | D37: Fountain Inn | E37: 491 Chapman Rd | F37: Real Estate | G37: Manufactured Housing | H37: Standing Investment
A38: GO | B38: Parakeet | C38: United States | D38: Kissimmee | E38: 4440 Yowell Road | F38: Real Estate | G38: Manufactured Housing | H38: Standing Investment
A39: GPT | B39: Parakeet | C39: United States | D39: Summerville | E39: 143 Greenpoint Dr | F39: Real Estate | G39: Manufactured Housing | H39: Standing Investment
A40: HP | B40: Parakeet | C40: United States | D40: Summerville | E40: 90 Hershey Circle | F40: Real Estate | G40: Manufactured Housing | H40: Standing Investment
A41: NGMH | B41: Parakeet | C41: United States | D41: Mims | E41: 3277 1st Ave | F41: Real Estate | G41: Manufactured Housing | H41: Standing Investment
A42: NGRV | B42: Parakeet | C42: United States | D42: Mims | E42: 3277 1st Ave | F42: Real Estate | G42: Manufactured Housing | H42: Standing Investment
A43: NGU | B43: Parakeet | C43: United States | D43: Mims | E43: 3277 1st Ave | F43: Real Estate | G43: Manufactured Housing | H43: Standing Investment
A44: OAK | B44: Parakeet | C44: United States | D44: Goose Creek | E44: 134 Oakside Dr. | F44: Real Estate | G44: Manufactured Housing | H44: Standing Investment
A45: PARK | B45: Parakeet | C45: United States | D45: West Columbia | E45: 3118 Dudley Rd | F45: Real Estate | G45: Manufactured Housing | H45: Standing Investment
... A55: WIND | B55: Parakeet | C55: United States | D55: Thonotosassa | E55: 12415 Thonotosassa Rd | F55: Real Estate | G55: Manufactured Housing | H55: Standing Investment

Sheet Bill Analysis
A1: Service Type: | B1: Site # | C1: Site Name | D1: Vendor Name | E1: Account # | F1: Service Period | G1: Days | H1: Year | I1: Month | J1: Cost | K1: Qty | L1: UOM | M1: Demand | N1: Demand UOM | O1: Rate | P1: Service Start Date | Q1: Service End Date | R1: Service Start Month | S1: Service Start Year | T1: Service End Month | U1: Service End Year
A2: Electricity | B2: AMER | C2: AMERICAN MHP | D2: NATIONAL GRID | E2: 0324600026 | F2: 06/24/2024 - 07/25/2024 | G2: 31 | H2: 2024 | I2: Jul | J2: 84.74 | K2: 141 | L2: KWH | M2: 0 | O2: Street & Security Lighting-Company Owned S-1 | P2: 45467 | Q2: 07/25/2024 | R2: 6 | S2: 2024 | T2: 7 | U2: 2024
A3: Electricity | B3: AMER | C3: AMERICAN MHP | D3: NATIONAL GRID | E3: 0324600026 | F3: 05/23/2024 - 06/24/2024 | G3: 32 | H3: 2024 | I3: Jun | J3: 87.31 | K3: 145 | L3: KWH | M3: 0 | O3: Street & Security Lighting-Company Owned S-1 | P3: 45435 | Q3: 06/24/2024 | R3: 5 | S3: 2024 | T3: 6 | U3: 2024
A4: Electricity | B4: AMER | C4: AMERICAN MHP | D4: NATIONAL GRID | E4: 0324600026 | F4: 04/24/2024 - 05/23/2024 | G4: 29 | H4: 2024 | I4: May | J4: 82.42 | K4: 143 | L4: KWH | M4: 0 | O4: Street & Security Lighting-Company Owned S-1 | P4: 45406 | Q4: 05/23/2024 | R4: 4 | S4: 2024 | T4: 5 | U4: 2024
A5: Electricity | B5: AMER | C5: AMERICAN MHP | D5: NATIONAL GRID | E5: 0324600026 | F5: 03/22/2024 - 04/24/2024 | G5: 33 | H5: 2024 | I5: Apr | J5: 101.04 | K5: 187 | L5: KWH | M5: 0 | O5: Street & Security Lighting-Company Owned S-1 | P5: 45373 | Q5: 04/24/2024 | R5: 3 | S5: 2024 | T5: 4 | U5: 2024
A6: Electricity | B6: AMER | C6: AMERICAN MHP | D6: NATIONAL GRID | E6: 0324600026 | F6: 02/22/2024 - 03/22/2024 | G6: 29 | H6: 2024 | I6: Mar | J6: 93.6 | K6: 184 | L6: KWH | M6: 0 | O6: Street & Security Lighting-Company Owned S-1 | P6: 45344 | Q6: 03/22/2024 | R6: 2 | S6: 2024 | T6: 3 | U6: 2024
A7: Electricity | B7: AMER | C7: AMERICAN MHP | D7: NATIONAL GRID | E7: 0324600026 | F7: 01/24/2024 - 02/22/2024 | G7: 29 | H7: 2024 | I7: Feb | J7: 95.42 | K7: 200 | L7: KWH | M7: 0 | O7: Street & Security Lighting-Company Owned S-1 | P7: 45315 | Q7: 02/22/2024 | R7: 1 | S7: 2024 | T7: 2 | U7: 2024
A8: Electricity | B8: AMER | C8: AMERICAN MHP | D8: NATIONAL GRID | E8: 5292896028 | F8: 06/24/2024 - 07/25/2024 | G8: 31 | H8: 2024 | I8: Jul | J8: 44.09 | K8: 62 | L8: KWH | M8: 0 | O8: Street & Security Lighting-Company Owned S-1 | P8: 45467 | Q8: 07/25/2024 | R8: 6 | S8: 2024 | T8: 7 | U8: 2024
A9: Electricity | B9: AMER | C9: AMERICAN MHP | D9: NATIONAL GRID | E9: 5292896028 | F9: 05/23/2024 - 06/24/2024 | G9: 32 | H9: 2024 | I9: Jun | J9: 45.49 | K9: 64 | L9: KWH | M9: 0 | O9: Street & Security Lighting-Company Owned S-1 | P9: 45435 | Q9: 06/24/2024 | R9: 5 | S9: 2024 | T9: 6 | U9: 2024
A10: Electricity | B10: AMER | C10: AMERICAN MHP | D10: NATIONAL GRID | E10: 5292896028 | F10: 04/24/2024 - 05/23/2024 | G10: 29 | H10: 2024 | I10: May | J10: 42.67 | K10: 63 | L10: KWH | M10: 0 | O10: Street & Security Lighting-Company Owned S-1 | P10: 45406 | Q10: 05/23/2024 | R10: 4 | S10: 2024 | T10: 5 | U10: 2024
A11: Electricity | B11: AMER | C11: AMERICAN MHP | D11: NATIONAL GRID | E11: 5292896028 | F11: 03/22/2024 - 04/24/2024 | G11: 33 | H11: 2024 | I11: Apr | J11: 51.96 | K11: 83 | L11: KWH | M11: 0 | O11: Street & Security Lighting-Company Owned S-1 | P11: 45373 | Q11: 04/24/2024 | R11: 3 | S11: 2024 | T11: 4 | U11: 2024
A12: Electricity | B12: AMER | C12: AMERICAN MHP | D12: NATIONAL GRID | E12: 5292896028 | F12: 02/22/2024 - 03/22/2024 | G12: 29 | H12: 2024 | I12: Mar | J12: 47.56 | K12: 81 | L12: KWH | M12: 0 | O12: Street & Security Lighting-Company Owned S-1 | P12: 45344 | Q12: 03/22/2024 | R12: 2 | S12: 2024 | T12: 3 | U12: 2024
A13: Electricity | B13: AMER | C13: AMERICAN MHP | D13: NATIONAL GRID | E13: 5292896028 | F13: 01/24/2024 - 02/22/2024 | G13: 29 | H13: 2024 | I13: Feb | J13: 48.63 | K13: 89 | L13: KWH | M13: 0 | O13: Street & Security Lighting-Company Owned S-1 | P13: 45315 | Q13: 02/22/2024 | R13: 1 | S13: 2024 | T13: 2 | U13: 2024
A14: Water | B14: AMER | C14: AMERICAN MHP | D14: AUBURN WATER DISTRICT | E14: 29220 | F14: 03/21/2024 - 06/20/2024 | G14: 91 | H14: 2024 | I14: Jul | J14: 17081.93 | K14: 1144470 | L14: GAL | O14: None | P14: 45372 | Q14: 45463 | R14: 3 | S14: 2024 | T14: 6 | U14: 2024
A15: Electricity | B15: APPLE | C15: APPLEGATE MHC | D15: DUKE ENERGY PAYMENT PROCESSING | E15: 910087354836 | F15: 06/12/2024 - 07/11/2024 | G15: 29 | H15: 2024 | I15: Jul | J15: 747.87 | K15: 5786 | L15: KWH | M15: 14.82 | N15: KW | O15: GENERAL SERVICE DEMAND SEC (GSD-1) | P15: 45455 | Q15: 07/11/2024 | R15: 6 | S15: 2024 | T15: 7 | U15: 2024
A16: Electricity | B16: APPLE | C16: APPLEGATE MHC | D16: DUKE ENERGY PAYMENT PROCESSING | E16: 910087354836 | F16: 05/11/2024 - 06/11/2024 | G16: 31 | H16: 2024 | I16: Jun | J16: 776.26 | K16: 5853 | L16: KWH | M16: 13.74 | N16: KW | O16: GENERAL SERVICE DEMAND SEC (GSD-1) | P16: 45423 | Q16: 06/11/2024 | R16: 5 | S16: 2024 | T16: 6 | U16: 2024
A17: Electricity | B17: APPLE | C17: APPLEGATE MHC | D17: DUKE ENERGY PAYMENT PROCESSING | E17: 910087354836 | F17: 04/11/2024 - 05/10/2024 | G17: 29 | H17: 2024 | I17: May | J17: 716.64 | K17: 4791 | L17: KWH | M17: 14.55 | N17: KW | O17: GENERAL SERVICE DEMAND SEC (GSD-1) | P17: 45393 | Q17: 05/10/2024 | R17: 4 | S17: 2024 | T17: 5 | U17: 2024
A18: Electricity | B18: APPLE | C18: APPLEGATE MHC | D18: DUKE ENERGY PAYMENT PROCESSING | E18: 910087354836 | F18: 03/13/2024 - 04/10/2024 | G18: 28 | H18: 2024 | I18: Apr | J18: 614.31 | K18: 4108 | L18: KWH | M18: 12.26 | N18: KW | O18: GENERAL SERVICE DEMAND SEC (GSD-1) | P18: 45364 | Q18: 04/10/2024 | R18: 3 | S18: 2024 | T18: 4 | U18: 2024
A19: Electricity | B19: APPLE | C19: APPLEGATE MHC | D19: DUKE ENERGY PAYMENT PROCESSING | E19: 910087354836 | F19: 02/13/2024 - 03/12/2024 | G19: 28 | H19: 2024 | I19: Mar | J19: 679.47 | K19: 4462 | L19: KWH | M19: 13.39 | N19: KW | O19: GENERAL SERVICE DEMAND SEC (GSD-1) | P19: 45335 | Q19: 03/12/2024 | R19: 2 | S19: 2024 | T19: 3 | U19: 2024
A20: Electricity | B20: APPLE | C20: APPLEGATE MHC | D20: DUKE ENERGY PAYMENT PROCESSING | E20: 910087354836 | F20: 01/12/2024 - 02/12/2024 | G20: 31 | H20: 2024 | I20: Feb | J20: 868.85 | K20: 5888 | L20: KWH | M20: 17.35 | N20: KW | O20: GENERAL SERVICE DEMAND SEC (GSD-1) | P20: 45303 | Q20: 02/12/2024 | R20: 1 | S20: 2024 | T20: 2 | U20: 2024
A21: Electricity | B21: APPLE | C21: APPLEGATE MHC | D21: DUKE ENERGY PAYMENT PROCESSING | E21: 910087354836 | F21: 01/11/2024 - 02/13/2024 | G21: 33 | H21: 2024 | I21: Feb | J21: 877.35 | K21: 0 | L21: KWH | M21: 0 | O21: GENERAL SERVICE DEMAND SEC (GSD-1) | P21: 45302 | Q21: 02/13/2024 | R21: 1 | S21: 2024 | T21: 2 | U21: 2024
A22: Electricity | B22: APPLE | C22: APPLEGATE MHC | D22: DUKE ENERGY PAYMENT PROCESSING | E22: 910087354836 | F22: 01/11/2024 - 02/13/2024 | G22: 33 | H22: 2024 | I22: Feb | J22: 877.35 | K22: 0 | L22: KWH | M22: 0 | O22: GENERAL SERVICE DEMAND SEC (GSD-1) | P22: 45302 | Q22: 02/13/2024 | R22: 1 | S22: 2024 | T22: 2 | U22: 2024
A23: Electricity | B23: APPLE | C23: APPLEGATE MHC | D23: DUKE ENERGY PAYMENT PROCESSING | E23: 910087354977 | F23: 06/11/2024 - 07/10/2024 | G23: 29 | H23: 2024 | I23: Jul | J23: 157.75 | K23: 487 | L23: KWH | M23: 0 | O23: LIGHTING SERVICE COMPANY OWNED/MAINTAINED (LS-1) | P23: 45454 | Q23: 07/10/2024 | R23: 6 | S23: 2024 | T23: 7 | U23: 2024
A24: Electricity | B24: APPLE | C24: APPLEGATE MHC | D24: DUKE ENERGY PAYMENT PROCESSING | E24: 910087354977 | F24: 05/10/2024 - 06/10/2024 | G24: 31 | H24: 2024 | I24: Jun | J24: 164.65 | K24: 487 | L24: KWH | M24: 0 | O24: LIGHTING SERVICE COMPANY OWNED/MAINTAINED (LS-1) | P24: 45422 | Q24: 06/10/2024 | R24: 5 | S24: 2024 | T24: 6 | U24: 2024
A25: Electricity | B25: APPLE | C25: APPLEGATE MHC | D25: DUKE ENERGY PAYMENT PROCESSING | E25: 910087354977 | F25: 04/10/2024 - 05/09/2024 | G25: 29 | H25: 2024 | I25: May | J25: 167.56 | K25: 487 | L25: KWH | M25: 0 | O25: LIGHTING SERVICE COMPANY OWNED/MAINTAINED (LS-1) | P25: 45392 | Q25: 05/09/2024 | R25: 4 | S25: 2024 | T25: 5 | U25: 2024
A26: Electricity | B26: APPLE | C26: APPLEGATE MHC | D26: DUKE ENERGY PAYMENT PROCESSING | E26: 910087354977 | F26: 03/12/2024 - 04/09/2024 | G26: 28 | H26: 2024 | I26: Apr | J26: 167.56 | K26: 487 | L26: KWH | M26: 0 | O26: LIGHTING SERVICE COMPANY OWNED/MAINTAINED (LS-1) | P26: 45363 | Q26: 04/09/2024 | R26: 3 | S26: 2024 | T26: 4 | U26: 2024
A27: Electricity | B27: APPLE | C27: APPLEGATE MHC | D27: DUKE ENERGY PAYMENT PROCESSING | E27: 910087354977 | F27: 02/10/2024 - 03/11/2024 | G27: 30 | H27: 2024 | I27: Mar | J27: 167.53 | K27: 487 | L27: KWH | M27: 0 | O27: LIGHTING SERVICE COMPANY OWNED/MAINTAINED (LS-1) | P27: 45332 | Q27: 03/11/2024 | R27: 2 | S27: 2024 | T27: 3 | U27: 2024
A28: Electricity | B28: CARL | C28: CARLEY S MOBILE HOME PARK | D28: FPL | E28: 6338187369 | F28: 05/14/2024 - 06/13/2024 | G28: 30 | H28: 2024 | I28: Jun | J28: 208.74 | K28: 574 | L28: KWH | M28: 0 | O28: SL-1 STREET LIGHTING SERVICE | P28: 45426 | Q28: 06/13/2024 | R28: 5 | S28: 2024 | T28: 6 | U28: 2024
A29: Electricity | B29: CARL | C29: CARLEY S MOBILE HOME PARK | D29: FPL | E29: 6338187369 | F29: 04/12/2024 - 07/15/2024 | G29: 94 | H29: 2024 | I29: Jul | J29: 192.72 | K29: 840 | L29: KWH | M29: 0 | O29: SL-1 STREET LIGHTING SERVICE | P29: 45394 | Q29: 07/15/2024 | R29: 4 | S29: 2024 | T29: 7 | U29: 2024
A30: Electricity | B30: CARL | C30: CARLEY S MOBILE HOME PARK | D30: FPL | E30: 6338187369 | F30: 04/12/2024 - 05/14/2024 | G30: 32 | H30: 2024 | I30: May | J30: 219.78 | K30: 574 | L30: KWH | M30: 0 | O30: SL-1 STREET LIGHTING SERVICE | P30: 45394 | Q30: 05/14/2024 | R30: 4 | S30: 2024 | T30: 5 | U30: 2024
A31: Electricity | B31: CARL | C31: CARLEY S MOBILE HOME PARK | D31: FPL | E31: 6338187369 | F31: 03/13/2024 - 04/12/2024 | G31: 30 | H31: 2024 | I31: Apr | J31: 224.7 | K31: 574 | L31: KWH | M31: 0 | O31: SL-1 STREET LIGHTING SERVICE | P31: 45364 | Q31: 04/12/2024 | R31: 3 | S31: 2024 | T31: 4 | U31: 2024
A32: Electricity | B32: CARL | C32: CARLEY S MOBILE HOME PARK | D32: FPL | E32: 6338187369 | F32: 02/13/2024 - 03/13/2024 | G32: 29 | H32: 2024 | I32: Mar | J32: 233.47 | K32: 574 | L32: KWH | M32: 0 | O32: SL-1 STREET LIGHTING SERVICE | P32: 45335 | Q32: 03/13/2024 | R32: 2 | S32: 2024 | T32: 3 | U32: 2024
... A45: Electricity | B45: CARL | C45: CARLEY S MOBILE HOME PARK | D45: FPL | E45: 9657990025 | F45: 01/24/2024 - 02/23/2024 | G45: 30 | H45: 2024 | I45: Feb | J45: 114.35 | K45: 763 | L45: KWH | M45: 0 | O45: RS-1 RESIDENTIAL SERVICE | P45: 45315 | Q45: 02/23/2024 | R45: 1 | S45: 2024 | T45: 2 | U45: 2024
A46: Sewer | B46: CARL | C46: CARLEY S MOBILE HOME PARK | D46: CITY OF HIALEAH | E46: 235032000 | F46: 01/26/2024 - 03/26/2024 | G46: 60 | H46: 2024 | I46: Apr | J46: 202.57 | K46: 3528 | L46: GAL | P46: 45317 | Q46: 03/26/2024 | R46: 1 | S46: 2024 | T46: 3 | U46: 2024
A47: Water | B47: CARL | C47: CARLEY S MOBILE HOME PARK | D47: CITY OF HIALEAH | E47: 235032000 | F47: 03/26/2024 - 05/28/2024 | G47: 63 | H47: 2024 | I47: Jun | J47: 2478.91 | K47: 375700 | L47: GAL | P47: 45377 | Q47: 05/28/2024 | R47: 3 | S47: 2024 | T47: 5 | U47: 2024
A48: Water | B48: CARL | C48: CARLEY S MOBILE HOME PARK | D48: CITY OF HIALEAH | E48: 235032000 | F48: 01/26/2024 - 03/26/2024 | G48: 60 | H48: 2024 | I48: Apr | J48: 2146.69 | K48: 3528 | L48: GAL | P48: 45317 | Q48: 03/26/2024 | R48: 1 | S48: 2024 | T48: 3 | U48: 2024
A49: Water | B49: CARL | C49: CARLEY S MOBILE HOME PARK | D49: CITY OF HIALEAH | E49: 235033000 | F49: 03/26/2024 - 05/28/2024 | G49: 63 | H49: 2024 | I49: Jun | J49: 18897.77 | K49: 999800 | L49: GAL | P49: 45377 | Q49: 05/28/2024 | R49: 3 | S49: 2024 | T49: 5 | U49: 2024
A50: Water | B50: CARL | C50: CARLEY S MOBILE HOME PARK | D50: CITY OF HIALEAH | E50: 235033000 | F50: 01/26/2024 - 03/26/2024 | G50: 60 | H50: 2024 | I50: Apr | J50: 5746.14 | K50: 867900 | L50: GAL | P50: 45317 | Q50: 03/26/2024 | R50: 1 | S50: 2024 | T50: 3 | U50: 2024
A51: Electricity | B51: CENTHARB | C51: CENTRAL MOBILE HOME PARK | D51: FPL | E51: 4251646057 | F51: 05/07/2024 - 06/06/2024 | G51: 30 | H51: 2024 | I51: Jun | J51: 41.69 | K51: 105 | L51: KWH | M51: 0 | O51: GS-1 GENERAL SVC NON-DEMAND / BUSINESS | P51: 45419 | Q51: 06/06/2024 | R51: 5 | S51: 2024 | T51: 6 | U51: 2024
A52: Electricity | B52: CENTHARB | C52: CENTRAL MOBILE HOME PARK | D52: FPL | E52: 4251646057 | F52: 04/05/2024 - 05/07/2024 | G52: 32 | H52: 2024 | I52: May | J52: 37.63 | K52: 115 | L52: KWH | M52: 0 | O52: GS-1 GENERAL SVC NON-DEMAND/BUSINESS | P52: 45387 | Q52: 05/07/2024 | R52: 4 | S52: 2024 | T52: 5 | U52: 2024
...

Sheet Sheet1
A1: Service Type: | B1: Site # | C1: Site Name | D1: Vendor Name | E1: Account # | F1: Service Period | G1: Days | H1: Year | I1: Month | J1: Cost | K1: Qty | L1: UOM | M1: Demand | N1: Demand UOM | O1: Rate | P1: Service Start Date | Q1: Service End Date | R1: Service Start Month | S1: Service Start Year | T1: Service End Month | U1: Service End Year
A2: Electric | B2: CA | C2: CRYSTAL ACRES | D2: WITHLACOOCHEE RIVER ELEC COOP | E2: 122850NCREDE | F2: 12/13/2024 - 01/16/2025 | G2: 34 | H2: 2025 | I2: Jan | J2: 64.67 | K2: 169 | L2: KWH | P2: 45639 | Q2: 45673 | R2: 12 | S2: 2024 | T2: 1
A3: Electric | B3: RO | C3: RIVER OAKS RV RESORT | D3: TECO | E3: 212WHITESQUIRREL | F3: 04/05/2025 - 05/05/2025 | G3: 30 | H3: 2025 | I3: May | J3: 0 | K3: 0 | L3: KWH | P3: 45752 | Q3: 45782 | R3: 4 | S3: 2025 | T3: 5
A4: Electric | B4: RO | C4: RIVER OAKS RV RESORT | D4: TECO | E4: 216WHITESQUIRREL | F4: 12/27/2024 - 01/27/2025 | G4: 31 | H4: 2025 | I4: Jan | J4: 14.11 | K4: 0 | L4: KWH | O4: RESIDENTIAL SERVICE | P4: 45653 | Q4: 45684 | R4: 12 | S4: 2024 | T4: 1
A5: Electric | B5: RO | C5: RIVER OAKS RV RESORT | D5: TECO | E5: 216WHITESQUIRREL | F5: 11/23/2024 - 12/26/2024 | G5: 33 | H5: 2025 | I5: Jan | J5: 24.76 | K5: 0 | L5: KWH | O5: RESIDENTIAL SERVICE | P5: 45619 | Q5: 45652 | R5: 11 | S5: 2024 | T5: 12
A6: Electric | B6: RO | C6: RIVER OAKS RV RESORT | D6: TECO | E6: 2716DANCINGMULLET | F6: 12/27/2024 - 01/27/2025 | G6: 31 | H6: 2025 | I6: Jan | J6: 14.11 | K6: 0 | L6: KWH | O6: RESIDENTIAL SERVICE | P6: 45653 | Q6: 45684 | R6: 12 | S6: 2024 | T6: 1
A7: Electric | B7: RO | C7: RIVER OAKS RV RESORT | D7: TECO | E7: 2716DANCINGMULLET | F7: 11/23/2024 - 12/26/2024 | G7: 33 | H7: 2025 | I7: Jan | J7: 24.76 | K7: 0 | L7: KWH | O7: RESIDENTIAL SERVICE | P7: 45619 | Q7: 45652 | R7: 11 | S7: 2024 | T7: 12
A8: Electric | B8: RO | C8: RIVER OAKS RV RESORT | D8: TECO | E8: 2718DANCINGMULLET | F8: 12/27/2024 - 01/27/2025 | G8: 31 | H8: 2025 | I8: Jan | J8: 19.11 | K8: 0 | L8: KWH | O8: RESIDENTIAL SERVICE | P8: 45653 | Q8: 45684 | R8: 12 | S8: 2024 | T8: 1
A9: Electric | B9: RO | C9: RIVER OAKS RV RESORT | D9: TECO | E9: 2718DANCINGMULLET | F9: 11/26/2024 - 12/26/2024 | G9: 30 | H9: 2025 | I9: Jan | J9: 22.57 | K9: 0 | L9: KWH | O9: RESIDENTIAL SERVICE | P9: 45622 | Q9: 45652 | R9: 11 | S9: 2024 | T9: 12
A10: Electric | B10: RO | C10: RIVER OAKS RV RESORT | D10: TECO | E10: 2732DANCINGMULLET | F10: 12/27/2024 - 01/27/2025 | G10: 31 | H10: 2025 | I10: Jan | J10: 14.11 | K10: 0 | L10: KWH | P10: 45653 | Q10: 45684 | R10: 12 | S10: 2024 | T10: 1
A11: Electric | B11: RO | C11: RIVER OAKS RV RESORT | D11: TECO | E11: 2732DANCINGMULLET | F11: 11/23/2024 - 12/26/2024 | G11: 33 | H11: 2025 | I11: Jan | J11: 24.76 | K11: 0 | L11: KWH | O11: RESIDENTIAL SERVICE | P11: 45619 | Q11: 45652 | R11: 11 | S11: 2024 | T11: 12
A12: Electric | B12: SOUTH | C12: SOUTHGATE MOBILE HOMES | D12: FPL | E12: 318817NATLANTIC | F12: 01/15/2025 - 02/17/2025 | G12: 33 | H12: 2025 | I12: Feb | J12: 34.9 | K12: 0 | L12: KWH | O12: RS-1 RESIDENTIAL SERVICE | P12: 45672 | Q12: 45705 | R12: 1 | S12: 2025 | T12: 2
A13: Electric | B13: SOUTH | C13: SOUTHGATE MOBILE HOMES | D13: FPL | E13: 318817NATLANTIC | F13: 01/15/2025 - 02/17/2025 | G13: 33 | H13: 2025 | I13: Feb | J13: 34.9 | K13: 0 | L13: KWH | O13: RS-1 RESIDENTIAL SERVICE | P13: 45672 | Q13: 45705 | R13: 1 | S13: 2025 | T13: 2
A14: Electric | B14: WPMH | C14: WHISPERING PINES MH | D14: FPL | E14: 354LILY | F14: 02/17/2025 - 03/19/2025 | G14: 30 | H14: 2025 | I14: Mar | J14: 0 | K14: 0 | L14: KWH | P14: 45705 | Q14: 45735 | R14: 2 | S14: 2025 | T14: 3
A15: Electric | B15: WPMH | C15: WHISPERING PINES MH | D15: FPL | E15: 359CHENEY | F15: 12/30/2024 - 01/06/2025 | G15: 7 | H15: 2025 | I15: Jan | J15: 123.6 | K15: 785 | L15: KWH | O15: RS-1 RESIDENTIAL SERVICE | P15: 45656 | Q15: 45663 | R15: 12 | S15: 2024 | T15: 1
A16: Electric | B16: WPMH | C16: WHISPERING PINES MH | D16: FPL | E16: 359CHENEY | F16: 12/30/2024 - 01/06/2025 | G16: 7 | H16: 2025 | I16: Jan | J16: 123.6 | K16: 785 | L16: KWH | O16: RS-1 RESIDENTIAL SERVICE | P16: 45656 | Q16: 45663 | R16: 12 | S16: 2024 | T16: 1
A17: Water | B17: HSRC | C17: HUNTER SPRINGS MHC | D17: CITY OF CRYSTAL RIVER | E17: 1316NE2ND | F17: 03/19/2025 - 04/21/2025 | G17: 33 | H17: 2025 | I17: Apr | J17: 10.13 | K17: 0 | L17: GAL | O17: 1PH35 | P17: 45735 | Q17: 45768 | R17: 3 | S17: 2025 | T17: 4
A18: Water | B18: HSRC | C18: HUNTER SPRINGS MHC | D18: CITY OF CRYSTAL RIVER | E18: 1316NE2ND | F18: 02/19/2025 - 03/19/2025 | G18: 28 | H18: 2025 | I18: Mar | J18: 11.14 | K18: 0 | L18: GAL | P18: 45707 | Q18: 45735 | R18: 2 | S18: 2025 | T18: 3
A19: Water | B19: HSRC | C19: HUNTER SPRINGS MHC | D19: CITY OF CRYSTAL RIVER | E19: 1316NE2ND | F19: 12/19/2024 - 01/21/2025 | G19: 33 | H19: 2025 | I19: Jan | J19: 21.27 | K19: 0 | L19: GAL | P19: 45645 | Q19: 45678 | R19: 12 | S19: 2024 | T19: 1
A20: Water | B20: WPMH | C20: WHISPERING PINES MH | D20: CITY OF TITUSVILLE | E20: 350LILY | F20: 04/08/2025 - 05/14/2025 | G20: 36 | H20: 2025 | I20: May | J20: 12.28 | K20: 0 | L20: GAL | P20: 45755 | Q20: 45791 | R20: 4 | S20: 2025 | T20: 5
A21: Water | B21: WPMH | C21: WHISPERING PINES MH | D21: CITY OF TITUSVILLE | E21: 350LILY | F21: 03/28/2025 - 04/08/2025 | G21: 11 | H21: 2025 | I21: Apr | J21: 16.2 | K21: 1000 | L21: GAL | P21: 45744 | Q21: 45755 | R21: 3 | S21: 2025 | T21: 4
A22: Water | B22: WPMH | C22: WHISPERING PINES MH | D22: CITY OF TITUSVILLE | E22: 350LILY | F22: 12/10/2024 - 01/21/2025 | G22: 42 | H22: 2025 | I22: Jan | J22: 16.52 | K22: 0 | L22: GAL | P22: 45636 | Q22: 45678 | R22: 12 | S22: 2024 | T22: 1
A23: Water | B23: WPMH | C23: WHISPERING PINES MH | D23: CITY OF TITUSVILLE | E23: 350LILY | F23: 11/06/2024 - 12/10/2024 | G23: 34 | H23: 2025 | I23: Jan | J23: 24.49 | K23: 0 | L23: GAL | P23: 45602 | Q23: 45636 | R23: 11 | S23: 2024 | T23: 12
A24: Water | B24: WPMH | C24: WHISPERING PINES MH | D24: CITY OF TITUSVILLE | E24: 359DAISY | F24: 04/08/2025 - 05/14/2025 | G24: 36 | H24: 2025 | I24: May | J24: 12.28 | K24: 0 | L24: GAL | P24: 45755 | Q24: 45791 | R24: 4 | S24: 2025 | T24: 5
A25: Water | B25: WPMH | C25: WHISPERING PINES MH | D25: CITY OF TITUSVILLE | E25: 359DAISY | F25: 03/12/2025 - 04/08/2025 | G25: 27 | H25: 2025 | I25: Apr | J25: 12.28 | K25: 0 | L25: GAL | P25: 45728 | Q25: 45755 | R25: 3 | S25: 2025 | T25: 4
A26: Water | B26: WPMH | C26: WHISPERING PINES MH | D26: CITY OF TITUSVILLE | E26: 359DAISY | F26: 02/12/2025 - 03/12/2025 | G26: 28 | H26: 2025 | I26: Apr | J26: 12.28 | K26: 0 | L26: GAL | P26: 45700 | Q26: 45728 | R26: 2 | S26: 2025 | T26: 3
A27: Water | B27: WPMH | C27: WHISPERING PINES MH | D27: CITY OF TITUSVILLE | E27: 359DAISY | F27: 01/08/2025 - 02/12/2025 | G27: 35 | H27: 2025 | I27: Feb | J27: 12.28 | K27: 0 | L27: GAL | P27: 45665 | Q27: 45700 | R27: 1 | S27: 2025 | T27: 2
A28: Water | B28: WPMH | C28: WHISPERING PINES MH | D28: CITY OF TITUSVILLE | E28: 359DAISY | F28: 12/10/2024 - 01/08/2025 | G28: 29 | H28: 2025 | I28: Jan | J28: 14.31 | K28: 0 | L28: GAL | P28: 45636 | Q28: 45665 | R28: 12 | S28: 2024 | T28: 1
A29: Water | B29: WPMH | C29: WHISPERING PINES MH | D29: CITY OF TITUSVILLE | E29: 359DAISY | F29: 11/06/2024 - 12/10/2024 | G29: 34 | H29: 2025 | I29: Jan | J29: 44.83 | K29: 0 | L29: GAL | P29: 45602 | Q29: 45636 | R29: 11 | S29: 2024 | T29: 12
... A55: Water | B55: AMER | C55: AMERICAN MHP | D55: AUBURN WATER DISTRICT | E55: 29220 | F55: 12/19/2024 - 03/21/2025 | G55: 92 | H55: 2025 | I55: Apr | J55: 13359.84 | K55: 7599411 | L55: GAL | P55: 45645 | Q55: 45737 | R55: 12 | S55: 2024 | T55: 3
A56: Water | B56: AMER | C56: AMERICAN MHP | D56: AUBURN WATER DISTRICT | E56: 29220 | F56: 09/23/2024 - 12/19/2024 | G56: 87 | H56: 2025 | I56: Jan | J56: 11716.96 | K56: 788392 | L56: GAL | O56: None | P56: 45558 | Q56: 45645 | R56: 9 | S56: 2024 | T56: 12
A57: Water | B57: BELL | C57: BELLE HAVEN | D57: PINELLAS COUNTY UTILITIES | E57: 100200051882 | F57: 03/06/2025 - 05/05/2025 | G57: 60 | H57: 2025 | I57: May | J57: 2101.89 | K57: 494000 | L57: GAL | P57: 45722 | Q57: 45782 | R57: 3 | S57: 2025 | T57: 5
A58: Water | B58: BELL | C58: BELLE HAVEN | D58: PINELLAS COUNTY UTILITIES | E58: 100200051882 | F58: 02/03/2025 - 03/03/2025 | G58: 28 | H58: 2025 | I58: Mar | J58: 4002.5 | K58: 0 | L58: GAL | P58: 45691 | Q58: 45719 | R58: 2 | S58: 2025 | T58: 3
A59: Water | B59: BELL | C59: BELLE HAVEN | D59: PINELLAS COUNTY UTILITIES | E59: 100200051882 | F59: 12/03/2024 - 01/02/2025 | G59: 30 | H59: 2025 | I59: Jan | J59: 4085.31 | K59: 0 | L59: GAL | P59: 45629 | Q59: 45659 | R59: 12 | S59: 2024 | T59: 1
A60: Water | B60: CARL | C60: CARLEY S MOBILE HOME PARK | D60: CITY OF HIALEAH | E60: 235032000 | F60: 02/06/2025 - 04/08/2025 | G60: 61 | H60: 2025 | I60: Apr | J60: 6324.51 | K60: 0 | L60: GAL | P60: 45694 | Q60: 45755 | R60: 2 | S60: 2025 | T60: 4
A61: Water | B61: CARL | C61: CARLEY S MOBILE HOME PARK | D61: CITY OF HIALEAH | E61: 235032000 | F61: 11/25/2024 - 01/28/2025 | G61: 64 | H61: 2025 | I61: Feb | J61: 3490.09 | K61: 518000 | L61: GAL | P61: 45621 | Q61: 45685 | R61: 11 | S61: 2024 | T61: 1
A62: Water | B62: CARL | C62: CARLEY S MOBILE HOME PARK | D62: CITY OF HIALEAH | E62: 235033000 | F62: 02/06/2025 - 04/08/2025 | G62: 61 | H62: 2025 | I62: Apr | J62: 6059.29 | K62: 0 | L62: GAL | P62: 45694 | Q62: 45755 | R62: 2 | S62: 2025 | T62: 4
A63: Water | B63: CARL | C63: CARLEY S MOBILE HOME PARK | D63: CITY OF HIALEAH | E63: 235033000 | F63: 11/25/2024 - 01/28/2025 | G63: 64 | H63: 2025 | I63: Feb | J63: 5902.69 | K63: 960200 | L63: GAL | P63: 45621 | Q63: 45685 | R63: 11 | S63: 2024 | T63: 1
A64: Water | B64: CENTHARB | C64: CENTRAL MOBILE HOME PARK | D64: CITY OF COCOA | E64: 48972111978 | F64: 04/16/2025 - 05/21/2025 | G64: 35 | H64: 2025 | I64: May | J64: 0 | K64: 0 | L64: GAL | P64: 45763 | Q64: 45798 | R64: 4 | S64: 2025 | T64: 5
A65: Water | B65: CENTHARB | C65: CENTRAL MOBILE HOME PARK | D65: CITY OF COCOA | E65: 48972111978 | F65: 03/18/2025 - 04/16/2025 | G65: 29 | H65: 2025 | I65: Apr | J65: 3932.48 | K65: 288000 | L65: GAL | P65: 45734 | Q65: 45763 | R65: 3 | S65: 2025 | T65: 4
...

Sheet Site-Level RFI
I1: Asset Management | M1: Occupancy | Q1: Utility Type and Data | AD1: Green Initiatives
